S28873092A3K27G6000079S000100DDM   0000802500Y
S28873092X3K27G600005S000100
S28873092X9K27G60000NI002000
S28873092X9K27G60000F6003200
S28873092A9K27G60000F6S003200QQQQ  0000495900Y
S28873093X9K27G60000NK001000
S28873093A9K27G60000PBB005000QQQQ  0000495400Y
S28873094X9K27G60000OP001000
S28873095A9K27G60000PCB001000QQQQ  0000495400Y
S28873096A9K27G60000PDB001000QLD   0000889200Y
S28873095X6K27GA00005F000500
S28873095A6K27GA00005FB000500IWM   0000736500Y
S28873097X9K27G60000PC001000
S28873097XBK27GA0000ER000100
S28873097XBK27GA0000PH000100
S28873096X6K27GA00005F000500
S28873096A6K27GA00005FB000500IWM   0000736100Y
S28873098ABK27GA0000PTB000100UWM   0000542400Y
S28873098XAK27GA0000ZW001000
S28873098AAK27GA000101B001000SPY   0001425100Y
S28873097A6K27GA00008GB000100IWM   0000736000Y
S28873097X6K27GA00008G000100
S28873099ABK27GA0000PUS000100TWM   0000702400Y
S28873100XBK27GA0000PT000100
S28873100XBK27GA0000PU000100
S28873101A9K27G60000PEB002000QQQQ  0000495600Y
S28873100AAK27GA000102B001000SPY   0001425100Y
S28873101X9K27G60000N8001000
S28873101A9K27G60000PFB001000QQQQ  0000495200Y
S28873101X9K27G60000PD001000
S28873101A9K27G60000PGB001000QLD   0000888800Y
S28873102ABK27GA0000PVS000100TWM   0000702600Y
S28873103A9K27G60000PHB001000QLD   0000888900Y
S28873103X9K27G60000ND000100
S28873103X9K27G60000LN000100
S28873103A9K27G60000PIB001000QQQQ  0000495400Y
S28873103X9K27G60000PI001000
S28873105A8K27G6000037B000500MZZ   0000491600Y
S28873105A8K27G6000038S000100MVV   0000809300Y
S28873106ABK27GA0000PWB000100UWM   0000542400Y
S28873107ABK27GA0000PXS000100TWM   0000702400Y
S28873107XBK27GA0000PV000100
S28873107XBK27GA0000PW000100
S28873107XBK27GA0000PX000100
S28873109ABK27GA0000PYS000100TWM   0000702600Y
S28873111X9K27G60000P8002000
S28873123X8K27G600002P000500
S28873123X8K27G600002Q000100
S28873125A8K27G6000039S000500MZZ   0000494000Y
S28873125A8K27G600003AB000100MVV   0000806100Y
S28873127XAK27GA0000O2000500
S28873127AAK27GA0000O2S000500SPY   0001425500Y
S28873135X4K27GA0000DT000047
S28873136A3K27G600007AS000100DDM   0000802400Y
S28873136X3K27G6000063000100
S28873135A4K27GA0000DZS000200DIA   0001298700Y
S28873135A4K27GA0000E0B000100DOG   0000597100Y
S28873158X9K27G60000N5002000
S28873157X6K27GA00006H002000
S28873159A6K27GA00008HB002000IWM   0000736200Y
S28873163XAK27GA0000UD000100
S28873163XBK27GA0000PP001000
S28873165AAK27GA000103B000100SPY   0001424400Y
S28873171X6K27GA00006U010000
S28873196X9K27G60000G1002000
S28873196A9K27G60000G1S002000QQQQ  0000495800Y
S28873202X8K27G600003A000100
S28873204A8K27G600003BB000100MVV   0000806000Y
S28873258AAK27GA000104S000500SPY   0001425700Y
S28873349X3K27G600006Z002000
S28873389A7K27GA000044B002000LMT   0000213100Y
S28873404X8K27G6000039000500
S28873404X8K27G600003B000100
S28873406A8K27G600003CS000500MZZ   0000494100Y
S28873406A8K27G600003DB000100MVV   0000805900Y
S28873406XBK27GA0000OD002000
S28873408XCK27GA00003A002000
S28873414XBK27GA0000OE002000
S28873416X1K27GA000063002000
S28873434X2K27G6000053002000
S28873433AAK27GA000105B005000SPY   0001424900Y
S28873434XAK27GA0000WY005000
S28873439X2K27G600005C002000
S28873443ACK27GA00003BB002000WMT   0000538700Y
S28873449X3K27G6000075002000
S28873452AAK27GA000106B002500SPY   0001425200Y
S28873463X4K27GA0000DU002000
S28873471ACK27GA00003CB002000WYE   0000080500Y
S28873488X7K27GA000042002000
S28873496X1K27GA000064002000
S28873497X9K27G60000NT000500
S28873497A9K27G60000PJS000100QID   0000382300Y
S28873497X9K27G60000PF001000
S28873501A7K27GA000045B002000LMT   0000212300Y
S28873514A1K27GA000065B002000AFL   0000128500Y
S28873529X2K27G6000055002000
S28873533ACK27GA00003DB002000WMT   0000537900Y
S28873543A2K27G600005GB002000BBT   0000061300Y
S28873550A1K27GA000066B002000AFL   0000127700Y
S28873558X2K27G600005D002000
S28873564A3K27G600007BB002000CVS   0000077700Y
S28873579A3K27G600007CB002000COH   0000064600Y
S28873586X3K27G6000077002000
S28873592A4K27GA0000E1B002000EIX   0000092100Y
S28873603A5K27GA00004XB002000HNZ   0000083600Y
S28873609A4K27GA0000E2B002000ELN   0000228100Y
S28873612A5K27GA00004YB002000HOT   0000086300Y
S28873622A6K27GA00008IB002000JCI   0000061400Y
S28873630X6K27GA000089002000
S28873636A5K27GA00004ZB002000HNZ   0000084400Y
S28873640A7K27GA000046B002000MRK   0000072000Y
S28873656A8K27G600003EB002000MU    0000074400Y
S28873660XAK27GA0000R0001000
S28873660ABK27GA0000PZB001000SSO   0000763900Y
S28873660XBK27GA0000PO001000
S28873661X4K27GA00007C000200
S28873661A4K27GA00007CB000200DIA   0001298200Y
S28873662X4K27GA000094000100
S28873662ABK27GA0000Q0B001000SSO   0000764100Y
S28873662X4K27GA000095000100
S28873663X3K27G6000078000100
S28873664A4K27GA0000E3S000100DXD   0000500500Y
S28873665A3K27G600007DB000100DDM   0000800800Y
S28873666A7K27GA000047B002000MRO   0000520600Y
S28873879AAK27GA000107S005000SPY   0001425700Y
S28874352XAK27GA0000Z9002000
S28874391X7K27GA000045002000
S28874392X2K27G600005E002000
S28874402X5K27GA00003Y002000
S28874406A3K27G600007EB002000CTSH  0000054900Y
S28874412X1K27GA000066002000
S28874416X7K27GA000044002000
S28874425X1K27GA000026002000
S28874433X2K27G600005F002000
S28874450XCK27GA00003C002000
S28874452X3K27G600007B002000
S28874457X4K27GA0000AJ002000
S28874468X4K27GA0000AP002000
S28874478X5K27GA00004X002000
S28874478X5K27GA00004Y002000
S28874481X4K27GA0000DQ000100
S28874481X4K27GA0000DR000100
S28874483X1K27GA000065002000
S28874486A4K27GA0000E4B000100DRYS  0001070600Y
S28874486A4K27GA0000E5B000100DRYS  0001070600Y
S28874495X1K27GA000023002000
S28874496X7K27GA000046002000
S28874500X4K27GA0000E1002000
S28874503X5K27GA00004Z002000
S28874510ABK27GA0000Q1B002000UTX   0000141100Y
S28874518ABK27GA0000Q2B002000UTX   0000140300Y
S28874523A1K27GA000067B002000ABT   0000105800Y
S28874526ACK27GA00003EB002000WYE   0000080900Y
S28874546A2K27G600005HB002000AXP   0000407400Y
S28874553A1K27GA000068B002000ABT   0000105000Y
S28874565A2K27G600005IB002000CAG   0000039800Y
S28874576A2K27G600005JB002000AXP   0000406600Y
S28874583A2K27G600005KB002000BBT   0000061400Y
S28874596A3K27G600007FB002000CVS   0000079600Y
S28874597A3K27G600007GB002000COH   0000064800Y
S28874620A4K27GA0000E6B002000EIX   0000092700Y
S28874637A5K27GA000050B002000HOT   0000088400Y
S28874664A6K27GA00008JB002000JCI   0000063200Y
S28874691XAK27GA0000QB000500
S28874691AAK27GA0000QBS000500SPY   0001425400Y
S28874691XAK27GA0000XP001000
S28874691XAK27GA0000FI000500
S28874691AAK27GA0000FIB000500SPY   0001424800Y
S28874691AAK27GA000108S001000SPY   0001425400Y
S28874691XAK27GA0000E7001000
S28874691AAK27GA0000E7B001000SPY   0001424900Y
S28874692XAK27GA0000YF001000
S28874692XAK27GA0000F5000500
S28874692AAK27GA0000F5B000500SPY   0001424800Y
S28874692X4K27GA0000CB000200
S28874693AAK27GA000109B001000SDS   0000547800Y
S28874693AAK27GA00010AB000100SH    0000618400Y
S28874693X3K27G600006W000100
S28874693A3K27G600007HS000100DDM   0000802200Y
S28874693ABK27GA0000Q3S001000SSO   0000765000Y
S28874693X4K27GA00009I000100
S28874693A4K27GA0000E7B000100DXD   0000499600Y
S28874693XBK27GA0000PM001000
S28874693AAK27GA00010BS005000SPY   0001425600Y
S28874693XAK27GA0000NY000500
S28874693AAK27GA0000NYS000500SPY   0001425400Y
S28874693AAK27GA00010CB001000SPY   0001424900Y
S28874693XAK27GA000107005000
S28874694XAK27GA000106002500
S28874694AAK27GA00010DB002500SPY   0001425100Y
S28874694XAK27GA0000ZZ000500
S28874695XAK27GA000100002500
S28874695AAK27GA00010EB000500SPY   0001425100Y
S28874695XAK27GA000104000500
S28874703X8K27G6000037000500
S28874702A4K27GA0000E8S000200DIA   0001298600Y
S28874703X8K27G6000038000100
S28874704XAK27GA0000SY003000
S28874704XAK27GA0000SX003000
S28874704A8K27G600003FS000100MVV   0000809400Y
S28874704A8K27G600003GB000500MZZ   0000491600Y
S28874704XAK27GA0000E9001000
S28874704AAK27GA0000E9S001000SPY   0001425400Y
S28874704AAK27GA00010FS003000SPY   0001425600Y
S28874704AAK27GA00010GS003000SPY   0001425600Y
S28874706XAK27GA0000Z7001000
S28874706XAK27GA0000Z2001000
S28874706AAK27GA00010HS001000SPY   0001425700Y
S28874711XBK27GA0000PZ001000
S28874717X8K27G600002W000100
S28874717A8K27G600003HS000100MVV   0000809200Y
S28874717A8K27G600003IB000500MZZ   0000491700Y
S28874721A6K27GA00008KS002000IWM   0000736900Y
S28874721X6K27GA00006Z002000
S28874727X8K27G600002V000500
S28874909AAK27GA00010IS000500SPY   0001425600Y
S28875101AAK27GA00010JS002500SPY   0001425600Y
S28875350X3K27G600006X002000
S28875383XAK27GA0000ZF002000
S28875408XBK27GA0000Q2002000
S28875411AAK27GA00010KB002000SHLD  0000744300Y
S28875412XBK27GA0000Q1002000
S28875413XCK27GA00003E002000
S28875423X1K27GA000068002000
S28875428X1K27GA000067002000
S28875452X4K27GA0000E6002000
S28875461X2K27G600005G002000
S28875462X6K27GA00008K002000
S28875463X6K27GA00008I002000
S28875476X3K27G600007C002000
S28875484A7K27GA000048B002000LMT   0000218300Y
S28875488X3K27G600007F002000
S28875499X5K27GA000050002000
S28875502X6K27GA00006B002000
S28875515X6K27GA00006K002000
S28875526A2K27G600005LB002000BMY   0000037600Y
S28875540X4K27GA0000E8000200
S28875541A5K27GA000051B002000GM    0000176600Y
S28875545A1K27GA000069B002000AFL   0000131400Y
S28875552A4K27GA0000E9S000200DIA   0001298900Y
S28875552A1K27GA00006AB002000ANN   0000258100Y
S28875559A7K27GA000049B002000LMT   0000219100Y
S28875561A2K27G600005MB002000CAG   0000039700Y
S28875574ACK27GA00003FB002000WYE   0000082900Y
S28875578XAK27GA0000NY000500
S28875578AAK27GA0000NYS000500SPY   0001425800Y
S28875578XAK27GA0000E9001000
S28875578AAK27GA0000E9S001000SPY   0001425800Y
S28875581XAK27GA00010B005000
S28875581XAK27GA00010I000500
S28875581XAK27GA0000ZR002000
S28875581AAK27GA00010LS000500SPY   0001425700Y
S28875581XAK27GA0000FI000500
S28875581AAK27GA0000FIB000500SPY   0001425200Y
S28875581XAK27GA0000E7001000
S28875581AAK27GA0000E7B001000SPY   0001425300Y
S28875581XAK27GA0000QB000500
S28875581AAK27GA0000QBS000500SPY   0001425800Y
S28875581AAK27GA00010MS005000SPY   0001425700Y
S28875581XAK27GA0000O2000500
S28875581AAK27GA0000O2S000500SPY   0001425900Y
S28875581XAK27GA0000F5000500
S28875581AAK27GA0000F5B000500SPY   0001425200Y
S28875581X4K27GA00007C000200
S28875581A4K27GA00007CB000200DIA   0001298500Y
S28875582X4K27GA0000DZ000200
S28875581AAK27GA00010NB002000SPY   0001425300Y
S28875581XAK27GA00010C001000
S28875581XAK27GA000108001000
S28875582AAK27GA00010OB001000SPY   0001425300Y
S28875583XAK27GA0000F2000500
S28875583AAK27GA0000F2B000500SPY   0001425300Y
S28875583ABK27GA0000Q4B001000SSO   0000763900Y
S28875583AAK27GA00010PS001000SPY   0001425800Y
S28875583XAK27GA00010M005000
S28875584XAK27GA0000ZY001000
S28875584XBK27GA0000Q3001000
S28875585XAK27GA00010J002500
S28875586AAK27GA00010QS002500SPY   0001425700Y
S28875586ABK27GA0000Q5S001000SSO   0000765100Y
S28875586XAK27GA00010D002500
S28875586A4K27GA0000EAS000200DIA   0001299000Y
S28875587X4K27GA0000DE000200
S28875591A3K27G600007IB002000CVS   0000080000Y
S28875591A1K27GA00006BB002000AFL   0000132200Y
S28875591XAK27GA000109001000
S28875592XAK27GA00010A000100
S28875592A4K27GA0000EBS000200DIA   0001299100Y
S28875593X3K27G600007H000100
S28875592X4K27GA0000E7000100
S28875593AAK27GA00010RB001000SDS   0000547700Y
S28875593XAK27GA00010H001000
S28875594A9K27G60000PKB002000QQQQ  0000495500Y
S28875597XAK27GA00010G003000
S28875597XAK27GA00010F003000
S28875597X4K27GA0000EB000200
S28875598A4K27GA0000ECB002000DIS   0000328500Y
S28875601X8K27G600003G000500
S28875601X8K27G6000033000500
S28875601X8K27G600003H000100
S28875600XAK27GA0000K1001000
S28875600AAK27GA0000K1S001000SPY   0001425900Y
S28875600XAK27GA0000EW000500
S28875600AAK27GA0000EWS000500SPY   0001425900Y
S28875600A4K27GA0000EDS000200DIA   0001298800Y
S28875601X8K27G600003F000100
S28875601X8K27G6000032000500
S28875601X8K27G600003I000500
S28875601X8K27G6000034000100
S28875601X8K27G6000031000100
S28875601XAK27GA0000FE000500
S28875601AAK27GA0000FEB000500SPY   0001425300Y
S28875601AAK27GA00010SS003000SPY   0001426200Y
S28875601X9K27G60000G8002000
S28875601A9K27G60000G8B002000QQQQ  0000495700Y
S28875601XAK27GA0000ZV003000
S28875601XAK27GA0000ZI003000
S28875601XAK27GA0000ZK002000
S28875601XAK27GA0000ZX001000
S28875601X9K27G60000G1002000
S28875601A9K27G60000G1S002000QQQQ  0000496300Y
S28875601AAK27GA00010TS003000SPY   0001426200Y
S28875601XAK27GA00010N002000
S28875601AAK27GA00010NB002000SPY   0001425300Y
S28875601XAK27GA0000O6000500
S28875601AAK27GA0000O6S000500SPY   0001426000Y
S28875601XAK27GA0000EX000500
S28875601AAK27GA0000EXB000500SPY   0001425300Y
S28875601XAK27GA0000E5001000
S28875601AAK27GA0000E5S001000SPY   0001426000Y
S28875601AAK27GA00010UB003000SPY   0001425300Y
S28875601XAK27GA0000ZM000500
S28875601AAK27GA0000ZMS000500SPY   0001426000Y
S28875601XAK27GA0000ZH003000
S28875601XAK27GA0000ZT003000
S28875601AAK27GA00010VB003000SPY   0001425300Y
S28875601AAK27GA00010WB002000SPY   0001425300Y
S28875602XAK27GA0000ZS002000
S28875602A1K27GA00006CB002000ANN   0000258900Y
S28875602X4K27GA0000ED000200
S28875602XAK27GA0000FD000500
S28875602AAK27GA0000FDB000500SPY   0001425300Y
S28875602AAK27GA00010XS001000SDS   0000549000Y
S28875602AAK27GA00010YB002000SPY   0001425300Y
S28875603XBK27GA0000Q0001000
S28875603ABK27GA0000Q6B001000SSO   0000764200Y
S28875603AAK27GA00010ZS003000SPY   0001426400Y
S28875603A8K27G600003JB000500MZZ   0000491600Y
S28875603XBK27GA0000Q5001000
S28875604A8K27G600003KS000100MVV   0000809400Y
S28875603AAK27GA000110S001000SPY   0001425900Y
S28875603AAK27GA000111S003000SPY   0001426400Y
S28875603AAK27GA000112S002000SPY   0001425900Y
S28875603XAK27GA0000F7000500
S28875603AAK27GA0000F7B000500SPY   0001425300Y
S28875603XAK27GA0000E4001000
S28875603AAK27GA0000E4B001000SPY   0001425300Y
S28875604XAK27GA0000ZU001000
S28875604AAK27GA000113B001000SPY   0001425300Y
S28875604XAK27GA0000EB001000
S28875604AAK27GA0000EBB001000SPY   0001425300Y
S28875605XBK27GA0000Q4001000
S28875605ABK27GA0000Q7B001000SSO   0000764000Y
S28875604AAK27GA000114S000100SH    0000618900Y
S28875605ABK27GA0000Q8B001000SSO   0000764300Y
S28875605XBK27GA0000Q6001000
S28875605ABK27GA0000Q9S001000SSO   0000765200Y
S28875605XAK27GA0000ZQ001000
S28875605AAK27GA000115B001000SPY   0001425300Y
S28875606XBK27GA0000Q8001000
S28875606XAK27GA000114000100
S28875606XAK27GA0000F7000500
S28875606AAK27GA0000F7B000500SPY   0001425100Y
S28875606XAK27GA00010L000500
S28875606XAK27GA00010Q002500
S28875607ABK27GA0000QAB001000SSO   0000764100Y
S28875607A4K27GA0000EES000200DIA   0001299100Y
S28875608XBK27GA0000Q7001000
S28875608ABK27GA0000QBB001000SSO   0000764300Y
S28875607AAK27GA000116S000100SH    0000618900Y
S28875608XAK27GA0000ZP001000
S28875608XAK27GA0000F7000500
S28875608AAK27GA0000F7B000500SPY   0001425300Y
S28875611XAK27GA00010R001000
S28875613AAK27GA000117B001000SDS   0000547600Y
S28875613A6K27GA00008LB002000IWM   0000736400Y
S28875615X4K27GA0000E0000100
S28875615X3K27G600007A000100
S28875616A8K27G600003LS000100MVV   0000809300Y
S28875617A4K27GA0000EFB002000ELN   0000227400Y
S28875617AAK27GA000118S001000SPY   0001426000Y
S28875621A4K27GA0000EGB002000EIX   0000094900Y
S28875621X6K27GA00005F000500
S28875621A6K27GA00005FB000500IWM   0000736500Y
S28875624ABK27GA0000QCB000100UWM   0000542400Y
S28875624ABK27GA0000QDS000100TWM   0000702400Y
S28875624XBK27GA0000PY000100
S28875622X6K27GA00005F000500
S28875622A6K27GA00005FB000500IWM   0000736100Y
S28875625X6K27GA00005F000500
S28875625A6K27GA00005FB000500IWM   0000736500Y
S28875631A5K27GA000052B002000HNZ   0000086100Y
S28875632A5K27GA000053B002000HNZ   0000086900Y
S28875636X9K27G60000F6003200
S28875636A9K27G60000F6S003200QQQQ  0000496400Y
S28875636X6K27GA00005F000500
S28875636A6K27GA00005FB000500IWM   0000736100Y
S28875639A5K27GA000054B002000HOT   0000088900Y
S28875640X6K27GA00005F000500
S28875640A6K27GA00005FB000500IWM   0000736500Y
S28875645A7K27GA00004AB002000MAY   0000092200Y
S28875648XAK27GA00010N002000
S28875648AAK27GA00010NB002000SPY   0001425400Y
S28875648XAK27GA0000EX000500
S28875648AAK27GA0000EXB000500SPY   0001425400Y
S28875648XAK27GA00010U003000
S28875648AAK27GA00010UB003000SPY   0001425400Y
S28875648XAK27GA00010V003000
S28875648AAK27GA00010VB003000SPY   0001425400Y
S28875648XAK27GA0000FD000500
S28875648AAK27GA0000FDB000500SPY   0001425400Y
S28875648XAK27GA00010Y002000
S28875648AAK27GA00010YB002000SPY   0001425400Y
S28875648XAK27GA0000E4001000
S28875648AAK27GA0000E4B001000SPY   0001425400Y
S28875648XAK27GA000113001000
S28875648AAK27GA000113B001000SPY   0001425400Y
S28875648XAK27GA0000EB001000
S28875648AAK27GA0000EBB001000SPY   0001425400Y
S28875648XAK27GA000115001000
S28875648AAK27GA000115B001000SPY   0001425400Y
S28875648XAK27GA0000F7000500
S28875648AAK27GA0000F7B000500SPY   0001425400Y
S28875649X4K27GA0000E9000200
S28875651A9K27G60000PLS001000QID   0000382000Y
S28875651A9K27G60000PMB001000QLD   0000889100Y
S28875650X6K27GA00002A000500
S28875650A6K27GA00002AS000500IWM   0000737100Y
S28875651X9K27G60000PL001000
S28875652A9K27G60000PNS001000QID   0000381900Y
S28875652X9K27G60000PM001000
S28875652A9K27G60000POB001000QLD   0000889200Y
S28875652A4K27GA0000EHS000200DIA   0001298900Y
S28875652X4K27GA0000DY000100
S28875653A9K27G60000PPS000100QID   0000382200Y
S28875651X6K27GA00008F002000
S28875653X3K27G6000079000100
S28875652XAK27GA000112002000
S28875654X4K27GA0000EH000200
S28875654AAK27GA000119S002000SPY   0001426000Y
S28875656XBK27GA0000PQ000100
S28875656XBK27GA0000PR000100
S28875656XBK27GA0000PS000100
S28875660X9K27G60000PO001000
S28875660A9K27G60000PQB001000QLD   0000889300Y
S28875662X9K27G60000F6003200
S28875662A9K27G60000F6S003200QQQQ  0000495900Y
S28875662A9K27G60000PRB001000QQQQ  0000495400Y
S28875662X9K27G60000PR001000
S28875662A4K27GA0000EIS000200DIA   0001299200Y
S28875664A9K27G60000PSB001000QQQQ  0000495400Y
S28875666X9K27G60000PS001000
S28875666XAK27GA000119001000
S28875668X8K27G600003J000500
S28875668X8K27G600003K000100
S28875668X8K27G600003L000100
S28875670A8K27G600003MB000500MZZ   0000491500Y
S28875670A8K27G600003NS000100MVV   0000809500Y
S28875672X6K27GA00008B000500
S28875672A6K27GA00008BB000500IWM   0000736600Y
S28875673A6K27GA00008MB002000IWM   0000736500Y
S28875676A8K27G600003OS000500MZZ   0000494000Y
S28875676A8K27G600003PB000100MVV   0000806100Y
S28875675ABK27GA0000QEB000100UWM   0000542500Y
S28875676ABK27GA0000QFS000100TWM   0000702200Y
S28875676XBK27GA0000QD000100
S28875675X6K27GA00008B000500
S28875675A6K27GA00008BB000500IWM   0000736200Y
S28875686X4K27GA0000DX000200
S28875686A4K27GA0000DXB000200DIA   0001298600Y
S28875686X4K27GA000062000200
S28875686A4K27GA000062B000200DIA   0001298700Y
S28875688A4K27GA0000EJS000100DOG   0000598400Y
S28875688A4K27GA0000EKS000100DXD   0000500200Y
S28875688A3K27G600007JB000100DDM   0000801100Y
S28875710XBK27GA0000Q9001000
S28875712ABK27GA0000QGS001000SSO   0000765300Y
S28875730X9K27G60000F6003200
S28875730A9K27G60000F6S003200QQQQ  0000496400Y
S28875741X9K27G60000PB005000
S28875744X4K27GA00007C000200
S28875744A4K27GA00007CB000200DIA   0001298800Y
S28875744A9K27G60000PTB005000QQQQ  0000495800Y
S28875746A9K27G60000PUB001000QLD   0000889200Y
S28875746A4K27GA0000ELS000100DOG   0000598300Y
S28875746A4K27GA0000EMS000100DXD   0000500100Y
S28875746A3K27G600007KB000100DDM   0000801200Y
S28875751XAK27GA000117001000
S28875767AAK27GA00011AS001000SPY   0001426100Y
S28875767XAK27GA000119001000
S28875769AAK27GA00011BS001000SPY   0001426100Y
S28875769X9K27G60000PA005000
S28875770X9K27G60000P7005000
S28875770A9K27G60000PVB002000QQQQ  0000495800Y
S28875770X9K27G60000P6005000
S28875770A9K27G60000PWB005000QQQQ  0000495800Y
S28875771X9K27G60000EO002000
S28875771A9K27G60000EOB002000QQQQ  0000495800Y
S28875771X9K27G60000P5002000
S28875771A9K27G60000PXS005000QQQQ  0000496300Y
S28875772A9K27G60000PYS005000QQQQ  0000496300Y
S28875780X9K27G60000ET002000
S28875780A9K27G60000ETS002000QQQQ  0000496200Y
S28875781XAK27GA0000O8000500
S28875781AAK27GA0000O8S000500SPY   0001426100Y
S28875784AAK27GA00011CB000500SPY   0001425400Y
S28875785XAK27GA00010E000500
S28875940XAK27GA0000NZ000500
S28875940AAK27GA0000NZS000500SPY   0001426100Y
S28875951AAK27GA00011DS001000SDS   0000548900Y
S28875951XBK27GA0000QB001000
S28875951ABK27GA0000QHB001000SSO   0000764400Y
S28875953XBK27GA0000QA001000
S28875953ABK27GA0000QIB001000SSO   0000764200Y
S28875968AAK27GA00011EB001000SPY   0001425400Y
S28875968XAK27GA000101001000
S28875968XAK27GA000102001000
S28875983AAK27GA00011FS005000SPY   0001426200Y
S28875983XAK27GA000105005000
S28875986AAK27GA00011GB002500SPY   0001425400Y
S28875988AAK27GA00011HS000500SPY   0001426000Y
S28876044X6K27GA00008B000500
S28876046XBK27GA0000QE000100
S28876046XBK27GA0000QF000100
S28876048ABK27GA0000QJS000100TWM   0000702400Y
S28876049ABK27GA0000QKB000100UWM   0000542500Y
S28876049ABK27GA0000QLS000100TWM   0000702200Y
S28876050XBK27GA0000QJ000100
S28876049A6K27GA00008NB000500IWM   0000736600Y
S28876062X6K27GA00008N000500
S28876062A6K27GA00008NB000500IWM   0000736200Y
S28876066XBK27GA0000QK000100
S28876066XBK27GA0000QL000100
S28876068ABK27GA0000QMS000100TWM   0000702400Y
S28876067X6K27GA00008N000500
S28876067A6K27GA00008NB000500IWM   0000736600Y
S28876069ABK27GA0000QNB000100UWM   0000542500Y
S28876069XBK27GA0000QM000100
S28876069ABK27GA0000QOS000100TWM   0000702200Y
S28876075X6K27GA00008N000500
S28876075A6K27GA00008NB000500IWM   0000736200Y
S28876078XBK27GA0000QN000100
S28876078XBK27GA0000QO000100
S28876080ABK27GA0000QPS000100TWM   0000702400Y
S28876079X6K27GA00008N000500
S28876079A6K27GA00008NB000500IWM   0000736600Y
S28876082ABK27GA0000QQB000100UWM   0000542500Y
S28876082ABK27GA0000QRS000100TWM   0000702200Y
S28876082XBK27GA0000QP000100
S28876085X6K27GA00008N000500
S28876085A6K27GA00008NB000500IWM   0000736200Y
S28876088XBK27GA0000QQ000100
S28876090XBK27GA0000QR000100
S28876088A6K27GA00008OB000100IWM   0000736100Y
S28876089X6K27GA00008N000500
S28876089A6K27GA00008NB000500IWM   0000736600Y
S28876090X6K27GA00008O000100
S28876091ABK27GA0000QSB000100UWM   0000542500Y
S28876091ABK27GA0000QTS000100TWM   0000702200Y
S28876095X6K27GA00008N000500
S28876095A6K27GA00008NB000500IWM   0000736200Y
S28876098XBK27GA0000QS000100
S28876098XBK27GA0000QT000100
S28876100ABK27GA0000QUS000100TWM   0000702400Y
S28876099X6K27GA00008N000500
S28876099A6K27GA00008NB000500IWM   0000736600Y
S28876102ABK27GA0000QVB000100UWM   0000542500Y
S28876102ABK27GA0000QWS000100TWM   0000702200Y
S28876102XBK27GA0000QU000100
S28876105X6K27GA00008N000500
S28876105A6K27GA00008NB000500IWM   0000736200Y
S28876108XBK27GA0000QV000100
S28876108XBK27GA0000QW000100
S28876107X6K27GA00008N000500
S28876107A6K27GA00008NB000500IWM   0000736600Y
S28876110ABK27GA0000QXB000100UWM   0000542500Y
S28876110ABK27GA0000QYS000100TWM   0000702200Y
S28876136A8K27G600003QB000100MVV   0000806300Y
S28876136A8K27G600003RB000100MVV   0000806200Y
S28876136A8K27G600003SS000500MZZ   0000493800Y
S28876136A8K27G600003TS000500MZZ   0000493900Y
S28876197A9K27G60000PZB002000QQQQ  0000495600Y
S28876302X6K27GA00002B000500
S28876302A6K27GA00002BS000500IWM   0000737200Y
S28876306XBK27GA0000ND000100
S28876307XBK27GA0000NE000100
S28876307XBK27GA0000NF000100
S28876308ABK27GA0000QZB000100TWM   0000700500Y
S28876377A9K27G60000Q0B000500QQQQ  0000495200Y
S28876388AAK27GA00011IS002500SPY   0001426000Y
S28876393A3K27G600007LB002000CELG  0000479900Y
S28876393X4K27GA0000DN000100
S28876393X3K27G6000074000100
S28876393X4K27GA0000EA000200
S28876393X4K27GA0000DO000100
S28876394X7K27GA000049002000
S28876395A4K27GA0000ENB000100DXD   0000499100Y
S28876395A3K27G600007MS000100DDM   0000802700Y
S28876397X7K27GA000048002000
S28876402A4K27GA0000EOS000200DIA   0001299300Y
S28876413X9K27G60000F5003200
S28876413A9K27G60000F5B003200QQQQ  0000495800Y
S28876415X1K27GA000069002000
S28876430XCK27GA00003F002000
S28876432X1K27GA00005E002000
S28876432AAK27GA00011JB002000SPLS  0000038600Y
S28876449X2K27G600005K002000
S28876457X1K27GA00006B002000
S28876463X2K27G6000059002000
S28876463X1K27GA00005G002000
S28876472X3K27G600007G002000
S28876481X2K27G600005B002000
S28876481X3K27G600007I002000
S28876501X2K27G600005I002000
S28876500A6K27GA00008PB010000IOM   0000038200Y
S28876503X5K27GA000052002000
S28876505X5K27GA000054002000
S28876518X4K27GA0000EG002000
S28876517X6K27GA000066002000
S28876523X5K27GA000053002000
S28876530X7K27GA00003Z002000
S28876537X6K27GA00008J002000
S28876547ABK27GA0000R0B002000UTX   0000145100Y
S28876548ABK27GA0000R1B002000UTX   0000144300Y
S28876563A1K27GA00006DB002000ABT   0000108900Y
S28876564ACK27GA00003GB002000WYE   0000083300Y
S28876579A1K27GA00006EB002000ABT   0000108000Y
S28876589XAK27GA0000FG000500
S28876589AAK27GA0000FGB000500SPY   0001425500Y
S28876592A4K27GA0000EPB002000EIX   0000095500Y
S28876610A6K27GA00008QB002000JCI   0000064200Y
S28876627A2K27G600005NB002000BBT   0000064100Y
S28876629A7K27GA00004BB002000MMC   0000041300Y
S28876646A3K27G600007NB002000COH   0000067500Y
S28876648A7K27GA00004CB002000MRK   0000075300Y
S28876664A3K27G600007OB002000CVS   0000082000Y
S28876668A8K27G600003UB002000MYL   0000014300Y
S28876697A5K27GA000055B002000HOT   0000091100Y
S28876703A6K27GA00008RB002000JCP   0000414100Y
S28876713A6K27GA00008SB002000KEY   0000211600Y
S28877136XAK27GA00011J002000
S28877136X3K27G600007L002000
S28877136XAK27GA00010K002000
S28877139X3K27G600007E002000
S28877139X4K27GA0000DP002000
S28877140X9K27G60000P0002000
S28877138X6K27GA00007T002000
S28877141XAK27GA0000XY002000
S28877141X4K27GA0000CC002000
S28877142X9K27G60000N7002000
S28877143X3K27G6000054002000
S28877141XCK27GA00001Q002000
S28877141XCK27GA00001O002000
S28877142X8K27G6000030002000
S28877141X1K27GA00005A002000
S28877141X1K27GA000059002000
S28877142X1K27GA000053002000
S28877141X7K27GA000035002000
S28877144XBK27GA00006R002000
S28877144XBK27GA00006Q002000
S28877144XBK27GA00006P002000
S28877144XBK27GA00006L002000
S28877144XBK27GA00006K002000
S28877142XAK27GA0000SM002000
S28877145XBK27GA00006J002000
S28877145XBK27GA000069002000
S28877146XAK27GA0000HV002000
S28877146XAK27GA0000HO002000
S28877146XAK27GA0000HI002000
S28877146XAK27GA0000HC002000
S28877147X9K27G60000HF002000
S28877147X9K27G60000HE002000
S28877151X9K27G60000H5002000
S28877151X8K27G600000T002000
S28877151X8K27G600000S002000
S28877151X8K27G600000R002000
S28877153X8K27G600000P002000
S28877154X8K27G600000O002000
S28877155X8K27G600000N002000
S28877154X7K27GA000016002000
S28877154X7K27GA000013002000
S28877156X7K27GA000011002000
S28877157X7K27GA000010002000
S28877157X7K27GA00000Z002000
S28877157X7K27GA00000Y002000
S28877156X6K27GA00002Z002000
S28877156X6K27GA00002Y002000
S28877156X6K27GA00002X002000
S28877158X4K27GA00004A002000
S28877163X4K27GA000048002000
S28877163X4K27GA000047002000
S28877164X3K27G600000S002000
S28877164X3K27G600000R002000
S28877165X3K27G600000Q002000
S28877165X3K27G600000P002000
S28877165X3K27G600000N002000
S28877166X3K27G600000M002000
S28877166X3K27G600000L002000
S28877166X3K27G600000K002000
S28877166X2K27G600000M002000
S28877167X2K27G600000L002000
S28877168X1K27GA00001J002000
S28877169X1K27GA00001I002000
S28877169X1K27GA00001G002000
S28877169X1K27GA00001E002000
S28877169XCK27GA00001A002000
S28877169XCK27GA000019002000
S28877171XCK27GA000018002000
S28877171XCK27GA000017002000
S28877173XBK27GA000014002000
S28877173XBK27GA000013002000
S28877173XAK27GA0000FN002000
S28877174XAK27GA0000FM002000
S28877174X9K27G60000FV002000
S28877174X9K27G60000FU002000
S28877175X8K27G6000007002000
S28877174X7K27GA00000K002000
S28877173X6K27GA00002H002000
S28877174X6K27GA00002G002000
S28877176X5K27GA000011002000
S28877176X5K27GA000010002000
S28877176X4K27GA00003Z002000
S28877176X4K27GA00003Y002000
S28877177X4K27GA00003W002000
S28877177X4K27GA00003V002000
S28877178X3K27G600000H002000
S28877179X3K27G600000G002000
S28877179X3K27G600000F002000
S28877180X2K27G600000F002000
S28877179X1K27GA000013002000
S28877184X1K27GA000012002000
S28877186X8K27G6000006002000
S28877306XAK27GA0000E6001000
S28877306AAK27GA0000E6S001000SPY   0001426100Y
S28877383X4K27GA0000EO000200
S28877383XAK27GA0000E6001000
S28877383AAK27GA0000E6S001000SPY   0001425700Y
S28877383XAK27GA0000FG000500
S28877383AAK27GA0000FGB000500SPY   0001425100Y
S28877384XAK27GA0000O8000500
S28877384AAK27GA0000O8S000500SPY   0001425700Y
S28877384A4K27GA0000EQS000047DIA   0001299000Y
S28877385AAK27GA00011KB005000SPY   0001425200Y
S28877386A3K27G600007PS000100DDM   0000802600Y
S28877385A4K27GA0000ERB000100DXD   0000499400Y
S28877386A4K27GA0000ESB000100DOG   0000597000Y
S28877443X2K27G600005L002000
S28877443XBK27GA0000R1002000
S28877445XCK27GA00003G002000
S28877451XBK27GA0000R0002000
S28877472X1K27GA00006E002000
S28877472X1K27GA00006D002000
S28877491X2K27G600005M002000
S28877496X3K27G600007O002000
S28877498X4K27GA0000EP002000
S28877527X3K27G600006G002000
S28877544X7K27GA00004C002000
S28877547X5K27GA000055002000
S28877565XAK27GA00011E001000
S28877568A7K27GA00004EB002000LMT   0000225100Y
S28877600ACK27GA00003HB002000WYE   0000085300Y
S28877614A1K27GA00006FB002000AFL   0000135900Y
S28877622A7K27GA00004FB002000LMT   0000224300Y
S28877632A1K27GA00006GB002000ARO   0000296500Y
S28877655A2K27G600005OB002000BDX   0000766000Y
S28877661A1K27GA00006HB002000AFL   0000135100Y
S28877685A1K27GA00006IB002000ARO   0000295700Y
S28877688A2K27G600005PB002000CAG   0000041800Y
S28877713A2K27G600005QB002000BBT   0000064200Y
S28877721A4K27GA0000ETB002000EIX   0000097700Y
S28877729A2K27G600005RB002000BDX   0000765200Y
S28877739A3K27G600007QB002000COH   0000067700Y
S28877743A5K27GA000056B002000HNZ   0000089500Y
S28877757A3K27G600007RB002000CVS   0000082400Y
S28877759A6K27GA00008TB002000JCI   0000066000Y
S28877795A5K27GA000057B002000HNZ   0000088700Y
S28877817A5K27GA000058B002000HOT   0000091600Y
S28877825A6K27GA00008UB002000KFT   0000305100Y
S28878117X1K27GA00004W000100
S28878117A1K27GA00004WB000100AAPL  0001829900Y
S28878128X1K27GA00004W000100
S28878128A1K27GA00004WB000100AAPL  0001830000Y
S28878136X1K27GA00000V000100
S28878136A1K27GA00000VB000100AAPL  0001830000Y
S28878289XAK27GA0000O8000500
S28878289AAK27GA0000O8S000500SPY   0001426100Y
S28878352A2K27G600005SB002000BMY   0000039400Y
S28878371X7K27GA00004E002000
S28878382ABK27GA0000R2B002000UTX   0000149100Y
S28878385XCK27GA00003H002000
S28878397X1K27GA00006F002000
S28878402A1K27GA00006JB002000ABT   0000112000Y
S28878405X2K27G600005N002000
S28878412X3K27G600007N002000
S28878427A3K27G600007SB002000CVS   0000084400Y
S28878436X4K27GA0000AQ002000
S28878447X4K27GA0000ET002000
S28878452A3K27G600007TB002000DD    0000458000Y
S28878455X4K27GA0000AS002000
S28878469X5K27GA000056002000
S28878476X7K27GA00004F002000
S28878517X1K27GA00006H002000
S28878535ABK27GA0000R3B002000UTX   0000148300Y
S28878539A5K27GA000059B002000HOT   0000093700Y
S28878539X3K27G600007R002000
S28878546X3K27G600006J002000
S28878555X4K27GA0000AO002000
S28878564ACK27GA00003IB002000WYE   0000085700Y
S28878577A7K27GA00004GB002000MCD   0000589000Y
S28878589X5K27GA000057002000
S28878595X5K27GA000058002000
S28878595A1K27GA00006KB002000ABT   0000111100Y
S28878606X6K27GA00008Q002000
S28878621A2K27G600005TB002000CAG   0000041600Y
S28878631A4K27GA0000EUB002000EIX   0000098300Y
S28878632X7K27GA00004B002000
S28878659A7K27GA00004HB002000MDY   0001576800Y
S28878667A7K27GA00004IB002000MRK   0000077500Y
S28879071XBK27GA0000QI001000
S28879387XBK27GA0000R3002000
S28879387XBK27GA0000R2002000
S28879389XCK27GA00003I002000
S28879402X1K27GA00006K002000
S28879402X1K27GA00006J002000
S28879410X1K27GA00004D002000
S28879414X1K27GA00004C002000
S28879418X2K27G600005J002000
S28879419X2K27G600005Q002000
S28879424X2K27G600005H002000
S28879437X3K27G600007Q002000
S28879438X2K27G600005P002000
S28879455X4K27GA0000EU002000
S28879458A7K27GA00004JB002000LMT   0000231100Y
S28879472X4K27GA0000B4002000
S28879472X5K27GA00001L002000
S28879473X3K27G600007S002000
S28879474X7K27GA00004I002000
S28879475A7K27GA00004KB002000LMT   0000230300Y
S28879492ABK27GA0000R4B001000SSO   0000764200Y
S28879492ACK27GA00003JB002000WYE   0000087700Y
S28879512A1K27GA00006LB002000AFL   0000138800Y
S28879514A1K27GA00006MB002000AFL   0000139600Y
S28879534A2K27G600005UB002000BBT   0000066900Y
S28879550X4K27GA0000B6002000
S28879559A3K27G600007UB002000CVS   0000084700Y
S28879564X5K27GA00001Q002000
S28879580A3K27G600007VB002000DD    0000457300Y
S28879583X5K27GA000059002000
S28879589X6K27GA00008T002000
S28879591A4K27GA0000EVB002000DUK   0000163300Y
S28879596A3K27G600007WB002000COH   0000070500Y
S28879602A5K27GA00005AB002000HNZ   0000091200Y
S28879611XAK27GA0000FG000500
S28879611AAK27GA0000FGB000500SPY   0001425500Y
S28879612A5K27GA00005BB002000HOT   0000094300Y
S28879616A4K27GA0000EWB002000DUK   0000164100Y
S28879621A6K27GA00008VB002000JCI   0000067100Y
S28879632A4K27GA0000EXB002000EIX   0000100500Y
S28879640A7K27GA00004LB002000MMC   0000043400Y
S28879647A4K27GA0000EYB002000EK    0000147600Y
S28880003XBK27GA0000R4001000
S28880004X4K27GA00007C000200
S28880004A4K27GA00007CB000200DIA   0001298500Y
S28880008X4K27GA0000EI000200
S28880008A4K27GA0000EIS000200DIA   0001298900Y
S28880011ABK27GA0000R5B001000SSO   0000764100Y
S28880011XAK27GA00011D001000
S28880011XBK27GA0000QH001000
S28880012X4K27GA0000EI000200
S28880012A4K27GA0000EIS000200DIA   0001299200Y
S28880012X4K27GA0000EL000100
S28880012X4K27GA0000EM000100
S28880012X3K27G600007K000100
S28880014ABK27GA0000R6B001000SSO   0000764300Y
S28880381X2K27G600005S002000
S28880382X7K27GA00004K002000
S28880387P4K27GA0000EZB000100DRYS  0001074900000A001NJEPR
S28880399X7K27GA00004J002000
S28880402ABK27GA0000R7B002000UTX   0000152300Y
S28880409XCK27GA00003J002000
S28880419X1K27GA00006M002000
S28880429X2K27G600004L002000
S28880428ACK27GA00003KB002000WYE   0000088100Y
S28880440X4K27GA0000EX002000
S28880447X4K27GA000098002000
S28880451A1K27GA00006NB002000ABT   0000114200Y
S28880457X1K27GA00006L002000
S28880460ABK27GA0000R8B002000UTX   0000153100Y
S28880482A1K27GA00006OB002000ABT   0000115000Y
S28880489A1K27GA00006PB002000ANF   0000721300Y
S28880502X2K27G600004J002000
S28880503A2K27G600005VB002000AXP   0000407900Y
S28880505A1K27GA00006QB002000ANF   0000722100Y
S28880508A2K27G600005WB002000BBT   0000067100Y
S28880526X2K27G600005T002000
S28880531A2K27G600005XB002000AXP   0000408700Y
S28880541A3K27G600007XB002000COH   0000070700Y
S28880549X4K27GA00007C000200
S28880549A4K27GA00007CB000200DIA   0001298800Y
S28880549XAK27GA0000E6001000
S28880549AAK27GA0000E6S001000SPY   0001426100Y
S28880551A2K27G600005YB002000CAG   0000043700Y
S28880552X3K27G600007U002000
S28880552A4K27GA0000F0S000100DOG   0000598300Y
S28880552AAK27GA00011LB005000SPY   0001425400Y
S28880552A3K27G600007YB000100DDM   0000801200Y
S28880552A4K27GA0000F1S000100DXD   0000500100Y
S28880552XAK27GA00011K005000
S28880574A3K27G600007ZB002000CVS   0000086700Y
S28880595X8K27G600003M000500
S28880595X8K27G600003N000100
S28880597A8K27G600003VB000500MZZ   0000491400Y
S28880597A8K27G600003WS000100MVV   0000809700Y
S28880598A4K27GA0000F2B002000EIX   0000101100Y
S28880606A8K27G600003XS000100MVV   0000809600Y
S28880611X4K27GA0000AY002000
S28880619X4K27GA000099002000
S28880620A4K27GA0000F3B002000FDX   0000878900Y
S28880629A4K27GA0000F4B002000FDX   0000878100Y
S28880636X4K27GA00007C000200
S28880636A4K27GA00007CB000200DIA   0001298500Y
S28880638X4K27GA0000F0000100
S28880638X4K27GA0000F1000100
S28880639X3K27G600007Y000100
S28880639X5K27GA00004I002000
S28880642X5K27GA00005A002000
S28880642A5K27GA00005CB002000FRE   0000253100Y
S28880644A5K27GA00005DB002000FRE   0000253900Y
S28880651X5K27GA00005B002000
S28880673X8K27G600003U002000
S28881388XBK27GA0000HW002000
S28881388XBK27GA0000R8002000
S28881392X1K27GA00006O002000
S28881395A7K27GA00004MB002000LMT   0000236300Y
S28881413X2K27G600005U002000
S28881420XBK27GA0000R7002000
S28881428X2K27G600004E002000
S28881440XCK27GA00003K002000
S28881450X3K27G600007W002000
S28881484X3K27G600007Z002000
S28881505X4K27GA00007C000200
S28881505A4K27GA00007CB000200DIA   0001298800Y
S28881507A4K27GA0000F5S000100DOG   0000598300Y
S28881507AAK27GA00011MB005000SPY   0001425500Y
S28881507A4K27GA0000F6S000100DXD   0000500100Y
S28881508A3K27G6000080B000100DDM   0000801200Y
S28881508AAK27GA00011NB000500SPY   0001425500Y
S28881508XAK27GA00011L005000
S28881508XAK27GA00011C000500
S28881508XAK27GA0000F5000500
S28881508AAK27GA0000F5B000500SPY   0001425500Y
S28881510XBK27GA0000R6001000
S28881509AAK27GA00011OS001000SDS   0000548900Y
S28881510ABK27GA0000R9B001000SSO   0000764400Y
S28881511XBK27GA0000R5001000
S28881511ABK27GA0000RAB001000SSO   0000764200Y
S28881511XAK27GA0000F5000500
S28881511AAK27GA0000F5B000500SPY   0001425200Y
S28881511XAK27GA0000NZ000500
S28881511AAK27GA0000NZS000500SPY   0001425700Y
S28881511XAK27GA0000E8001000
S28881511AAK27GA0000E8B001000SPY   0001425500Y
S28881511AAK27GA00011PB002000SPY   0001425500Y
S28881513X4K27GA0000EQ000047
S28881517A4K27GA0000F7S000200DIA   0001299300Y
S28881521X1K27GA00006N002000
S28881520X6K27GA000084002000
S28881528XAK27GA0000NZ000500
S28881528AAK27GA0000NZS000500SPY   0001426100Y
S28881528XAK27GA0000ZO001000
S28881527X6K27GA00006J002000
S28881529AAK27GA00011QB001000SPY   0001425500Y
S28881540X6K27GA00007U000500
S28881540A6K27GA00007UB000500IWM   0000736700Y
S28881541A6K27GA00008WB002000IWM   0000736600Y
S28881541X6K27GA00008H002000
S28881543ABK27GA0000RBB000100UWM   0000542700Y
S28881543ABK27GA0000RCS000100TWM   0000702000Y
S28881543XBK27GA0000QY000100
S28881544X6K27GA00007U000500
S28881544A6K27GA00007UB000500IWM   0000736300Y
S28881546AAK27GA00011RB001000SPY   0001425400Y
S28881554X6K27GA00007U000500
S28881554A6K27GA00007UB000500IWM   0000736700Y
S28881556XBK27GA0000RB000100
S28881556XBK27GA0000RC000100
S28881558ABK27GA0000RDB000100UWM   0000542700Y
S28881558ABK27GA0000RES000100TWM   0000702000Y
S28881564X6K27GA00007U000500
S28881564A6K27GA00007UB000500IWM   0000736300Y
S28881568X4K27GA0000F2002000
S28881574X6K27GA00007U000500
S28881574A6K27GA00007UB000500IWM   0000736700Y
S28881576XBK27GA0000RD000100
S28881576XBK27GA0000RE000100
S28881578ABK27GA0000RFB000100UWM   0000542700Y
S28881578ABK27GA0000RGS000100TWM   0000702000Y
S28881584X6K27GA00007U000500
S28881584A6K27GA00007UB000500IWM   0000736300Y
S28881594A2K27G600005ZB002000BMY   0000041200Y
S28881594X6K27GA00008V002000
S28881594X6K27GA00007U000500
S28881594A6K27GA00007UB000500IWM   0000736700Y
S28881596XBK27GA0000RF000100
S28881596XBK27GA0000RG000100
S28881598ABK27GA0000RHB000100UWM   0000542700Y
S28881596A6K27GA00008XB000100IWM   0000736200Y
S28881597X6K27GA00008X000100
S28881598ABK27GA0000RIS000100TWM   0000702000Y
S28881598X6K27GA00007U000500
S28881598A6K27GA00007UB000500IWM   0000736300Y
S28881601XBK27GA0000RH000100
S28881601XBK27GA0000RI000100
S28881602A6K27GA00008YB000100IWM   0000736200Y
S28881603ABK27GA0000RJS000100TWM   0000702200Y
S28881602X6K27GA00008Y000100
S28881602X6K27GA00007U000500
S28881602A6K27GA00007UB000500IWM   0000736700Y
S28881605ABK27GA0000RKB000100UWM   0000542700Y
S28881605XBK27GA0000RJ000100
S28881605ABK27GA0000RLS000100TWM   0000702000Y
S28881606X7K27GA00002A002000
S28881604X6K27GA00007U000500
S28881604A6K27GA00007UB000500IWM   0000736300Y
S28881607X7K27GA00002O002000
S28881610X7K27GA00004L002000
S28881610XAK27GA0000E8001000
S28881610AAK27GA0000E8B001000SPY   0001425600Y
S28881610XAK27GA00011P002000
S28881610AAK27GA00011PB002000SPY   0001425600Y
S28881610XAK27GA00011Q001000
S28881610AAK27GA00011QB001000SPY   0001425600Y
S28881616XBK27GA0000RK000100
S28881616XBK27GA0000RL000100
S28881618ABK27GA0000RMS000100TWM   0000702200Y
S28881621A7K27GA00004NB002000LMT   0000237100Y
S28881628X8K27G600003D000100
S28881628A8K27G600003YB000100MVV   0000806400Y
S28881636A1K27GA00006RB002000AFL   0000142500Y
S28881642ACK27GA00003LB002000WYE   0000090100Y
S28881647A2K27G6000060B002000AZN   0000418900Y
S28881654A2K27G6000061B002000CAG   0000043600Y
S28881670A1K27GA00006SB002000AFL   0000143300Y
S28881670A3K27G6000081B002000CVS   0000087100Y
S28881673A2K27G6000062B002000AZN   0000419700Y
S28881691A4K27GA0000F8B002000EK    0000146900Y
S28881694A4K27GA0000F9B002000EIX   0000103300Y
S28881707A4K27GA0000FAB002000FCX   0001224600Y
S28881709A4K27GA0000FBB002000FCX   0001225400Y
S28881713A5K27GA00005EB002000HMY   0000087500Y
S28881719A5K27GA00005FB002000HNZ   0000093800Y
S28881726A5K27GA00005GB002000HOT   0000096900Y
S28881730A5K27GA00005HB002000HNZ   0000094600Y
S28882352X7K27GA00004M002000
S28882357X7K27GA00004N002000
S28882387ABK27GA0000RNB002000TGT   0000519100Y
S28882386XCK27GA00003L002000
S28882403ABK27GA0000ROB002000UTX   0000156300Y
S28882405X1K27GA00006S002000
S28882408ABK27GA0000RPB002000UTX   0000157100Y
S28882421ACK27GA00003MB002000WYE   0000090500Y
S28882432A1K27GA00006TB002000ABT   0000118100Y
S28882438X1K27GA00006R002000
S28882449A1K27GA00006UB002000ABT   0000117200Y
S28882461A2K27G6000063B002000BBT   0000069800Y
S28882470X2K27G600005Y002000
S28882481X2K27G600004N002000
S28882487X2K27G600005W002000
S28882492X2K27G600004K002000
S28882499X3K27G600007X002000
S28882505X3K27G6000081002000
S28882520A2K27G6000064B002000BK    0000427400Y
S28882519X3K27G6000059002000
S28882545X3K27G6000058002000
S28882550X5K27GA00005F002000
S28882553X5K27GA00005G002000
S28882560X4K27GA0000F9002000
S28882561X7K27GA00002G002000
S28882566A4K27GA0000FCB002000EIX   0000103900Y
S28882586A3K27G6000082B002000COH   0000073500Y
S28882591X5K27GA00004P002000
S28882600X5K27GA00005H002000
S28882599A6K27GA00008ZB002000JCI   0000069900Y
S28882615A7K27GA00004OB002000KMB   0000611900Y
S28882622A7K27GA00004PB002000LLY   0000464500Y
S28882625A3K27G6000083B002000CVS   0000089100Y
S28882652A5K27GA00005IB002000HOT   0000099100Y
S28882662A6K27GA000090B002000JCI   0000070700Y
S28883208XAK27GA00011G002500
S28883352A7K27GA00004QB002000LMT   0000242300Y
S28883356X2K27G600005Z002000
S28883392A7K27GA00004RB002000LMT   0000243100Y
S28883399XBK27GA0000RO002000
S28883409XBK27GA0000I4002000
S28883410XCK27GA00003M002000
S28883430X9K27G60000PZ002000
S28883432XBK27GA0000RP002000
S28883432X1K27GA00006U002000
S28883446A1K27GA00006VB002000AFL   0000146200Y
S28883452ACK27GA00003NB002000WYE   0000092600Y
S28883469X1K27GA00006T002000
S28883479X2K27G600003L002000
S28883479X9K27G60000PX005000
S28883479X9K27G60000F5003200
S28883479A9K27G60000F5B003200QQQQ  0000495300Y
S28883479X9K27G60000PY005000
S28883480A9K27G60000Q1S005000QQQQ  0000495900Y
S28883480A9K27G60000Q2S005000QQQQ  0000495900Y
S28883486A2K27G6000065B002000BBT   0000069900Y
S28883489A1K27GA00006WB002000AFL   0000147000Y
S28883504X2K27G600003K002000
S28883512X2K27G600005O002000
S28883522X2K27G600005R002000
S28883526X9K27G60000ET002000
S28883526A9K27G60000ETS002000QQQQ  0000495900Y
S28883526A9K27G60000Q3S002000QQQQ  0000496000Y
S28883529X2K27G600004G002000
S28883529A2K27G6000066B002000BK    0000426600Y
S28883541X2K27G600004F002000
S28883544X2K27G6000061002000
S28883553A2K27G6000067B002000CAG   0000045700Y
S28883557A3K27G6000084B002000COH   0000073700Y
S28883572A3K27G6000085B002000CVS   0000089500Y
S28883582A3K27G6000086B002000DHR   0000760300Y
S28883593X4K27GA0000FC002000
S28883599A2K27G6000068B002000CAT   0000818000Y
S28883615X3K27G6000083002000
S28883619A5K27GA00005JB002000HNZ   0000096300Y
S28883635A5K27GA00005KB002000HOT   0000099600Y
S28883655A3K27G6000087B002000DHR   0000761100Y
S28883666A4K27GA0000FDB002000EIX   0000106100Y
S28883675A5K27GA00005LB002000HMY   0000088500Y
S28883682X5K27GA00005I002000
S28883711AAK27GA00011SB002500SPY   0001425400Y
S28883841X6K27GA00008W002000
S28883857A6K27GA000091S002000IWM   0000737100Y
S28884044X8K27G600003S000500
S28884044X8K27G600003Q000100
S28884044X8K27G600003Y000100
S28884046A8K27G600003ZS000500MZZ   0000493800Y
S28884046A8K27G6000040B000100MVV   0000806300Y
S28884112XAK27GA00011S002500
S28884135X6K27GA000091002000
S28884152A6K27GA000092S002000IWM   0000737100Y
S28884162AAK27GA00011TB002500SPY   0001425400Y
S28884172X6K27GA000092002000
S28884187A6K27GA000093S002000IWM   0000737100Y
S28884189X1K27GA00000V000100
S28884189A1K27GA00000VB000100AAPL  0001828700Y
S28884196X1K27GA00004W000100
S28884196A1K27GA00004WB000100AAPL  0001828700Y
S28884197X6K27GA000093002000
S28884211A6K27GA000094S002000IWM   0000737100Y
S28884219X6K27GA000094002000
S28884235X9K27G60000Q3002000
S28884241A6K27GA000095S002000IWM   0000737100Y
S28884269X9K27G60000Q1005000
S28884269X9K27G60000Q2005000
S28884269X9K27G60000F5003200
S28884269A9K27G60000F5B003200QQQQ  0000495800Y
S28884270X9K27G60000ET002000
S28884270A9K27G60000ETS002000QQQQ  0000496200Y
S28884271A9K27G60000Q4S005000QQQQ  0000496300Y
S28884271A9K27G60000Q5S005000QQQQ  0000496300Y
S28884272A9K27G60000Q6B002000QQQQ  0000495600Y
S28884275X1K27GA00004W000100
S28884275A1K27GA00004WB000100AAPL  0001830000Y
S28884276X6K27GA000095002000
S28884292A6K27GA000096B002000IWM   0000736600Y
S28884377X4K27GA000041002000
S28884380X4K27GA000044002000
S28884394X6K27GA000070002000
S28884398X7K27GA00004Q002000
S28884408A1K27GA00006XB002000AMAT  0000183300Y
S28884442X1K27GA00006V002000
S28884442X7K27GA00004R002000
S28884445X2K27G600004U002000
S28884451X3K27G6000085002000
S28884450XCK27GA00003N002000
S28884457A8K27G6000041B000100MVV   0000806400Y
S28884469X4K27GA0000AW002000
S28884484X1K27GA00006W002000
S28884498A1K27GA00006YS002000AMAT  0000204800Y
S28884499X2K27G6000063002000
S28884499X5K27GA00005J002000
S28884514X5K27GA00005K002000
S28884526A2K27G6000069B002000BMY   0000043100Y
S28884525X6K27GA00008Z002000
S28884532ABK27GA0000RQB002000UTX   0000160300Y
S28884546A1K27GA00006ZB002000AMGN  0000413600Y
S28884553ACK27GA00003OB002000WYE   0000093000Y
S28884572A1K27GA000070B002000ABT   0000120300Y
S28884585A2K27G600006AB002000BA    0000853200Y
S28884588A2K27G600006BB002000BDX   0000766600Y
S28884600A2K27G600006CB002000BNI   0001059900Y
S28884608A1K27GA000071S002000AMGN  0000489900Y
S28884609A2K27G600006DB002000CAG   0000045500Y
S28884609XAK27GA00011T002500
S28884612ABK27GA0000RRB002000TGT   0000520000Y
S28884622X3K27G6000082002000
S28884654A1K27GA000072B002000AMZN  0000800000Y
S28884673X4K27GA0000AV002000
S28884673A4K27GA0000FEB002000EIX   0000106700Y
S28884674ABK27GA0000RSB002000UTX   0000161100Y
S28884693X4K27GA0000FD002000
S28884726X6K27GA000090002000
S28884728A1K27GA000073S002000AMZN  0000834800Y
S28884732A7K27GA00004SB002000KMX   0000186900Y
S28884744A7K27GA00004TB002000MMC   0000046800Y
S28884777A2K27G600006EB002000BRCM  0000261200Y
S28884780A1K27GA000074B002000ABT   0000121100Y
S28884814A2K27G600006FB002000BA    0000854000Y
S28884818A2K27G600006GS002000BRCM  0000290800Y
S28884837A2K27G600006HB002000BDX   0000767400Y
S28884848A3K27G6000088B002000CELG  0000482800Y
S28884848X6K27GA00001N000100
S28884848A6K27GA000097S000100IYF   0000858600Y
S28884848A6K27GA000098S000100IYF   0000858500Y
S28884850ABK27GA0000RTS000100UYG   0000321900Y
S28884848X6K27GA00001M000100
S28884859A2K27G600006IB002000BNI   0001060700Y
S28884866A3K27G6000089S002000CELG  0000613300Y
S28884878A3K27G600008AB002000CVS   0000091400Y
S28884923XAK27GA0000E8001000
S28884923AAK27GA0000E8B001000SPY   0001425200Y
S28884924X4K27GA0000F7000200
S28884924XAK27GA0000NZ000500
S28884924AAK27GA0000NZS000500SPY   0001425700Y
S28884924XAK27GA00011Q001000
S28884924XAK27GA00011N000500
S28884924XAK27GA00011P002000
S28884924AAK27GA00011UB000500SPY   0001425400Y
S28884925AAK27GA00011VB002500SPY   0001425400Y
S28884926XAK27GA00011M005000
S28884926AAK27GA00011WB001000SPY   0001425200Y
S28884926AAK27GA00011XB005000SPY   0001425200Y
S28884929A4K27GA0000FFS000200DIA   0001299000Y
S28884931XAK27GA0000F7000500
S28884931AAK27GA0000F7B000500SPY   0001425100Y
S28884942XAK27GA00011R001000
S28884942X9K27G60000Q5005000
S28884942X9K27G60000F5003200
S28884942A9K27G60000F5B003200QQQQ  0000495300Y
S28884942X9K27G60000Q4005000
S28884941X6K27GA000096002000
S28884942X4K27GA00007C000200
S28884942A4K27GA00007CB000200DIA   0001298500Y
S28884943A9K27G60000Q7S005000QQQQ  0000495900Y
S28884943A9K27G60000Q8S005000QQQQ  0000495900Y
S28884943X9K27G60000Q6002000
S28884944XAK27GA0000FG000500
S28884944AAK27GA0000FGB000500SPY   0001425100Y
S28884944X4K27GA0000F5000100
S28884944X4K27GA0000F6000100
S28884944X3K27G6000080000100
S28884952A6K27GA000099S002000IWM   0000737100Y
S28884989X8K27G600003V000500
S28884989X8K27G600003W000100
S28884989X8K27G600003X000100
S28884990A8K27G6000042B000500MZZ   0000491400Y
S28884991A8K27G6000043S000100MVV   0000809700Y
S28884998X6K27GA00002B000500
S28884998A6K27GA00002BS000500IWM   0000736800Y
S28885001ABK27GA0000RUS000100UWM   0000543500Y
S28885002ABK27GA0000RVB000100TWM   0000700900Y
S28885002ABK27GA0000RWB000100TWM   0000700800Y
S28885010A8K27G6000044S000100MVV   0000809600Y
S28885035X8K27G6000042000500
S28885035X8K27G6000044000100
S28885035X8K27G6000043000100
S28885037A8K27G6000045B000500MZZ   0000491400Y
S28885037A8K27G6000046S000100MVV   0000809700Y
S28885072A4K27GA0000FGB000100DXD   0000499500Y
S28885072A3K27G600008BS000100DDM   0000802500Y
S28885127A8K27G6000047B000500MZZ   0000491500Y
S28885127A8K27G6000048S000100MVV   0000809500Y
S28885156X8K27G600003Z000500
S28885156X8K27G6000041000100
S28885156X8K27G6000040000100
S28885158A8K27G6000049S000500MZZ   0000493800Y
S28885158A8K27G600004AB000100MVV   0000806300Y
S28885397XBK27GA0000RS002000
S28885405XBK27GA0000RQ002000
S28885405A3K27G600008CB002000CHKP  0000232100Y
S28885404X1K27GA000074002000
S28885448XCK27GA00003O002000
S28885451X2K27G600005X002000
S28885450X1K27GA000070002000
S28885451X2K27G6000067002000
S28885453X2K27G600005V002000
S28885453X3K27G600008A002000
S28885453X2K27G6000065002000
S28885453A3K27G600008DS002000CHKP  0000263100Y
S28885451X6K27GA00006L002000
S28885453A4K27GA0000FHB002000DNA   0000687200Y
S28885453X3K27G6000084002000
S28885454X4K27GA0000FE002000
S28885473X7K27GA00004H002000
S28885473X9K27G60000Q7005000
S28885474X9K27G60000F5003200
S28885474A9K27G60000F5B003200QQQQ  0000495800Y
S28885474X9K27G60000Q8005000
S28885475A9K27G60000Q9B002000QQQQ  0000495600Y
S28885475A9K27G60000QAS005000QQQQ  0000496300Y
S28885475A9K27G60000QBS005000QQQQ  0000496300Y
S28885495X7K27GA00003Q002000
S28885501A4K27GA0000FIB002000DNA   0000686400Y
S28885502X9K27G60000F5003200
S28885502A9K27G60000F5B003200QQQQ  0000495300Y
S28885503X9K27G60000Q9002000
S28885505A7K27GA00004UB002000LMT   0000249100Y
S28885511X9K27G60000QA005000
S28885511X9K27G60000QB005000
S28885511A3K27G600008EB002000CREE  0000238500Y
S28885512A9K27G60000QCS005000QQQQ  0000495900Y
S28885512A9K27G60000QDS005000QQQQ  0000495900Y
S28885511A6K27GA00009AB002000JNJ   0000641300Y
S28885517X9K27G60000QC005000
S28885517X9K27G60000QD005000
S28885518X9K27G60000F5003200
S28885518A9K27G60000F5B003200QQQQ  0000495800Y
S28885519A9K27G60000QES005000QQQQ  0000496300Y
S28885519A9K27G60000QFS005000QQQQ  0000496300Y
S28885526A7K27GA00004VB002000LMT   0000248300Y
S28885531X9K27G60000QE005000
S28885531X9K27G60000QF005000
S28885531X9K27G60000F5003200
S28885531A9K27G60000F5B003200QQQQ  0000495300Y
S28885531A9K27G60000QGS005000QQQQ  0000495900Y
S28885531A9K27G60000QHS005000QQQQ  0000495900Y
S28885539X9K27G60000ET002000
S28885539A9K27G60000ETS002000QQQQ  0000495900Y
S28885542A3K27G600008FB002000CYMI  0000285200Y
S28885544ACK27GA00003PB002000WYE   0000095000Y
S28885580A1K27GA000075B002000AFL   0000150700Y
S28885585A2K27G600006JB002000BBT   0000072600Y
S28885591A1K27GA000076B002000AFL   0000149900Y
S28885598A3K27G600008GS002000CYMI  0000320900Y
S28885601A2K27G600006KB002000CAT   0000817300Y
S28885617A3K27G600008HB002000COH   0000076500Y
S28885630A3K27G600008IB002000CVS   0000091800Y
S28885633A4K27GA0000FJB002000DISH  0000320300Y
S28885659A4K27GA0000FKB002000DOW   0000399400Y
S28885660A4K27GA0000FLB002000DOW   0000398600Y
S28885661A4K27GA0000FMS002000DISH  0000359800Y
S28885704A4K27GA0000FNB002000DRIV  0000359900Y
S28885704A4K27GA0000FOB002000EIX   0000108900Y
S28885713A5K27GA00005MB002000HNZ   0000098900Y
S28885735A4K27GA0000FPS002000DRIV  0000394000Y
S28885736A5K27GA00005NB002000HOT   0000102300Y
S28885774A6K27GA00009BB002000JCI   0000072800Y
S28885779A4K27GA0000FQB002000EBAY  0000293600Y
S28886397X2K27G6000069002000
S28886406A4K27GA0000FRS002000EBAY  0000330100Y
S28886407X6K27GA000073002000
S28886411X2K27G600004I002000
S28886420X7K27GA00004U002000
S28886434XCK27GA00003P002000
S28886441A4K27GA0000FSB002000ENZN  0000069500Y
S28886452X7K27GA00004V002000
S28886455X1K27GA000075002000
S28886473X4K27GA000059002000
S28886492X4K27GA0000FO002000
S28886496X1K27GA000076002000
S28886506ABK27GA0000RXB002000UTX   0000165100Y
S28886519A4K27GA0000FTS002000ENZN  0000105500Y
S28886527X2K27G600006D002000
S28886543X3K27G600008I002000
S28886545A1K27GA000077B002000ABT   0000124200Y
S28886554A5K27GA00005OB002000GILD  0000515700Y
S28886558X4K27GA00005C002000
S28886572X5K27GA00005M002000
S28886591A5K27GA00005PS002000GILD  0000553400Y
S28886592X5K27GA00005N002000
S28886597X7K27GA00004T002000
S28886610A2K27G600006LB002000AXP   0000410100Y
S28886618ABK27GA0000RYB002000UTX   0000164300Y
S28886622A5K27GA00005QB002000IACI  0000220300Y
S28886639ACK27GA00003QB002000WYE   0000095400Y
S28886642A2K27G600006MB002000CAG   0000047600Y
S28886661A1K27GA000078B002000ABT   0000123300Y
S28886662A5K27GA00005RS002000IACI  0000265400Y
S28886684A3K27G600008JB002000CVS   0000093800Y
S28886699A6K27GA00009CB002000IMCL  0000345400Y
S28886707A2K27G600006NB002000AXP   0000409300Y
S28886728A6K27GA00009DS002000IMCL  0000520400Y
S28886731A5K27GA00005SB002000HNZ   0000101000Y
S28886732A2K27G600006OB002000BBT   0000072800Y
S28886756A6K27GA00009EB002000INTC  0000237800Y
S28886758A5K27GA00005TB002000HOT   0000104400Y
S28886767A3K27G600008KB002000COH   0000076700Y
S28886789A6K27GA00009FB002000JCI   0000074500Y
S28886793A4K27GA0000FUB002000EIX   0000109500Y
S28886841A7K27GA00004WB002000MDY   0001578100Y
S28886930A6K27GA00009GB002000IWM   0000736500Y
S28887152A6K27GA00009HS002000IWM   0000737400Y
S28887157X9K27G60000PW005000
S28887158X9K27G60000PV002000
S28887158A9K27G60000QIS002000QQQQ  0000496000Y
S28887159A9K27G60000QJB005000QQQQ  0000495400Y
S28887160X9K27G60000EO002000
S28887160A9K27G60000EOB002000QQQQ  0000495500Y
S28887170X9K27G60000PU001000
S28887172A9K27G60000QKB001000QQQQ  0000495400Y
S28887176X9K27G60000QK001000
S28887394A6K27GA00009IS002000INTC  0000258900Y
S28887400XBK27GA0000RX002000
S28887405A6K27GA00009JB002000IWM   0000736400Y
S28887411X5K27GA00004V002000
S28887412XBK27GA0000RY002000
S28887430X1K27GA000077002000
S28887429XCK27GA00003Q002000
S28887443X1K27GA000078002000
S28887446A2K27G600006PB002000BRL   0000373700Y
S28887451A6K27GA00009KB002000INTU  0000258200Y
S28887455X2K27G600006J002000
S28887471X3K27G600008H002000
S28887472XAK27GA0000E6001000
S28887472AAK27GA0000E6S001000SPY   0001425700Y
S28887472XAK27GA00010Y002000
S28887472X4K27GA0000EI000200
S28887472XAK27GA0000O8000500
S28887472AAK27GA0000O8S000500SPY   0001425700Y
S28887473XBK27GA0000RA001000
S28887474AAK27GA00011YS002500SPY   0001425900Y
S28887474AAK27GA00011ZS005000SPY   0001426000Y
S28887474AAK27GA000120S000500SPY   0001425900Y
S28887475XAK27GA00011H000500
S28887475XAK27GA00011F005000
S28887475XAK27GA00011I002500
S28887481XAK27GA00011O001000
S28887481XBK27GA0000R9001000
S28887481ABK27GA0000RZB001000SSO   0000764100Y
S28887481A4K27GA0000FVS000200DIA   0001298900Y
S28887483ABK27GA0000S0B001000SSO   0000764300Y
S28887486X3K27G600008J002000
S28887486XAK27GA0000ZM000500
S28887486AAK27GA0000ZMS000500SPY   0001425700Y
S28887487AAK27GA000121B001000SDS   0000547600Y
S28887488AAK27GA000122S001000SPY   0001426000Y
S28887500X4K27GA0000D8002000
S28887500A6K27GA00009LS002000INTU  0000291500Y
S28887510X8K27G6000049000500
S28887510X8K27G600004A000100
S28887512X5K27GA00005S002000
S28887523A7K27GA00004XB002000LMT   0000254300Y
S28887525X5K27GA00005T002000
S28887538A6K27GA00009MS002000IVGN  0001029800Y
S28887545A2K27G600006QB002000BMY   0000044900Y
S28887580A7K27GA00004YB002000MRVL  0000135300Y
S28887581A6K27GA00009NB002000JNJ   0000642200Y
S28887588A6K27GA00009OB002000IWM   0000736300Y
S28887595X9K27G60000PT005000
S28887595XAK27GA0000ZM000500
S28887595AAK27GA0000ZMS000500SPY   0001425600Y
S28887597X9K27G60000PN001000
S28887597A9K27G60000QLB001000QQQQ  0000495200Y
S28887597X9K27G60000PQ001000
S28887599A9K27G60000QMB001000QQQQ  0000495400Y
S28887600A9K27G60000QNB005000QQQQ  0000495400Y
S28887601A7K27GA00004ZB002000LMT   0000255100Y
S28887606X9K27G60000PP000100
S28887606X9K27G60000QM001000
S28887623A7K27GA000050S002000MRVL  0000158000Y
S28887642ACK27GA00003RB002000WYE   0000097400Y
S28887650A1K27GA000079B002000AFL   0000153600Y
S28887656A8K27G600004BB002000MSFT  0000283100Y
S28887673X4K27GA0000FU002000
S28887691A1K27GA00007AB002000AFL   0000154400Y
S28887704X4K27GA0000D7002000
S28887705A8K27G600004CS002000MSFT  0000306000Y
S28887724A4K27GA0000FWB002000DOX   0000303500Y
S28887739X6K27GA00009B002000
S28887739X6K27GA00007D002000
S28887741A2K27G600006RB002000CAG   0000047500Y
S28887745A8K27G600004DB002000NFLX  0000307700Y
S28887761A4K27GA0000FXB002000EIX   0000111700Y
S28887764A3K27G600008LB002000CVS   0000094200Y
S28887787A6K27GA00009PB002000JWN   0000351900Y
S28887796A4K27GA0000FYB002000DOX   0000302700Y
S28887814A6K27GA00009QS002000IWM   0000737300Y
S28888035A6K27GA00009RS002000IWM   0000737500Y
S28888256A6K27GA00009SB002000IWM   0000736200Y
S28888373X7K27GA00003D002000
S28888406X7K27GA00003E002000
S28888408A9K27G60000QOB002000QCOM  0000457500Y
S28888409X7K27GA00004X002000
S28888410X7K27GA00004Z002000
S28888428X1K27GA000079002000
S28888427XCK27GA00003R002000
S28888436X2K27G600006O002000
S28888442X1K27GA00007A002000
S28888446X3K27G600008K002000
S28888455X3K27G600008L002000
S28888455X2K27G600006M002000
S28888460A9K27G60000QPS002000QCOM  0000487300Y
S28888468X5K27GA00004N002000
S28888470X4K27GA0000FX002000
S28888478X5K27GA00004O002000
S28888478A5K27GA00005UB002000GM    0000176800Y
S28888477A6K27GA00009TS002000IWM   0000737200Y
S28888490ABK27GA0000S1B002000UTX   0000168300Y
S28888498A9K27G60000QQB002000QLGC  0000144200Y
S28888508X6K27GA00009F002000
S28888512X9K27G60000F6003200
S28888512A9K27G60000F6S003200QQQQ  0000495900Y
S28888528ABK27GA0000S2B002000UTX   0000169100Y
S28888531ACK27GA00003SB002000WYE   0000097800Y
S28888543A9K27G60000QRS002000QLGC  0000179200Y
S28888552A1K27GA00007BB002000ABT   0000126400Y
S28888565A1K27GA00007CB002000ABT   0000127300Y
S28888592AAK27GA000123B002000SHLD  0000751900Y
S28888600A2K27G600006SB002000BBT   0000075500Y
S28888628AAK27GA000124B002000SINA  0000509800Y
S28888639A3K27G600008MB002000COH   0000079500Y
S28888640A4K27GA0000FZB002000EIX   0000112300Y
S28888659A4K27GA0000G0B002000ESI   0000618000Y
S28888665AAK27GA000125S002000SINA  0000557500Y
S28888666A5K27GA00005VB002000HNZ   0000102700Y
S28888675A3K27G600008NB002000CVS   0000096200Y
S28888696AAK27GA000126B002000SMTC  0000162200Y
S28888701A6K27GA00009UB002000IWM   0000736100Y
S28888702A4K27GA0000G1B002000ESI   0000618800Y
S28888710A5K27GA00005WB002000HOT   0000106300Y
S28888732AAK27GA000127S002000SMTC  0000197100Y
S28888738A5K27GA00005XB002000HNZ   0000103500Y
S28888741A6K27GA00009VB002000JCI   0000075600Y
S28888752A6K27GA00009WB002000KEY   0000211400Y
S28888765A5K27GA00005YB002000HOT   0000107100Y
S28888846X6K27GA00008N000500
S28888846A6K27GA00008NB000500IWM   0000736200Y
S28888854X6K27GA00008N000500
S28888854A6K27GA00008NB000500IWM   0000736600Y
S28888856XBK27GA0000QX000100
S28888856XBK27GA0000RM000100
S28888858ABK27GA0000S3B000100UWM   0000542500Y
S28888858ABK27GA0000S4S000100TWM   0000702200Y
S28888858X6K27GA00008N000500
S28888858A6K27GA00008NB000500IWM   0000736200Y
S28888859A6K27GA00009XS002000IWM   0000737600Y
S28888861XBK27GA0000S3000100
S28888861XBK27GA0000S4000100
S28888861A6K27GA00009YB000100IWM   0000736100Y
S28888863ABK27GA0000S5S000100TWM   0000702400Y
S28888861X6K27GA00009Y000100
S28888862X6K27GA00008N000500
S28888862A6K27GA00008NB000500IWM   0000736600Y
S28888864ABK27GA0000S6B000100UWM   0000542500Y
S28888865ABK27GA0000S7S000100TWM   0000702200Y
S28888865XBK27GA0000S5000100
S28888864X6K27GA00008N000500
S28888864A6K27GA00008NB000500IWM   0000736200Y
S28888874X6K27GA00008N000500
S28888874A6K27GA00008NB000500IWM   0000736600Y
S28888876XBK27GA0000S6000100
S28888876XBK27GA0000S7000100
S28888878ABK27GA0000S8B000100UWM   0000542500Y
S28888878ABK27GA0000S9S000100TWM   0000702200Y
S28888884X6K27GA00008N000500
S28888884A6K27GA00008NB000500IWM   0000736200Y
S28888894X6K27GA00008N000500
S28888894A6K27GA00008NB000500IWM   0000736600Y
S28888896XBK27GA0000S8000100
S28888896XBK27GA0000S9000100
S28888898ABK27GA0000SAS000100TWM   0000702200Y
S28888898ABK27GA0000SBB000100UWM   0000542500Y
S28888904X6K27GA00008N000500
S28888904A6K27GA00008NB000500IWM   0000736200Y
S28888914X6K27GA00008N000500
S28888914A6K27GA00008NB000500IWM   0000736600Y
S28888916XBK27GA0000SB000100
S28888916XBK27GA0000SA000100
S28888916A6K27GA00009ZB000100IWM   0000736100Y
S28888917ABK27GA0000SCB000100UWM   0000542500Y
S28888916X6K27GA00009Z000100
S28888918ABK27GA0000SDS000100TWM   0000702200Y
S28888924X6K27GA00008N000500
S28888924A6K27GA00008NB000500IWM   0000736200Y
S28888934X6K27GA00008N000500
S28888934A6K27GA00008NB000500IWM   0000736600Y
S28888936XBK27GA0000SC000100
S28888936XBK27GA0000SD000100
S28888938ABK27GA0000SES000100TWM   0000702200Y
S28888938ABK27GA0000SFB000100UWM   0000542500Y
S28888944X6K27GA00008N000500
S28888944A6K27GA00008NB000500IWM   0000736200Y
S28888954X6K27GA00008N000500
S28888954A6K27GA00008NB000500IWM   0000736600Y
S28888956XBK27GA0000SF000100
S28888956XBK27GA0000SE000100
S28888958ABK27GA0000SGB000100UWM   0000542500Y
S28888958ABK27GA0000SHS000100TWM   0000702200Y
S28888964X6K27GA00008N000500
S28888964A6K27GA00008NB000500IWM   0000736200Y
S28888974X6K27GA00008N000500
S28888974A6K27GA00008NB000500IWM   0000736600Y
S28888976XBK27GA0000SG000100
S28888976XBK27GA0000SH000100
S28888978ABK27GA0000SIS000100TWM   0000702400Y
S28888984X6K27GA00008N000500
S28888984A6K27GA00008NB000500IWM   0000736200Y
S28888986ABK27GA0000SJB000100UWM   0000542500Y
S28888986XBK27GA0000SI000100
S28888986ABK27GA0000SKS000100TWM   0000702200Y
S28888994X6K27GA00008N000500
S28888994A6K27GA00008NB000500IWM   0000736600Y
S28888996XBK27GA0000SJ000100
S28888996XBK27GA0000SK000100
S28888998ABK27GA0000SLS000100TWM   0000702400Y
S28889004X6K27GA00008N000500
S28889004A6K27GA00008NB000500IWM   0000736200Y
S28889014X6K27GA00008N000500
S28889014A6K27GA00008NB000500IWM   0000736600Y
S28889024X6K27GA00008N000500
S28889024A6K27GA00008NB000500IWM   0000736200Y
S28889034X6K27GA00008N000500
S28889034A6K27GA00008NB000500IWM   0000736600Y
S28889044X6K27GA00008N000500
S28889044A6K27GA00008NB000500IWM   0000736200Y
S28889054X6K27GA00008N000500
S28889054A6K27GA00008NB000500IWM   0000736600Y
S28889064X6K27GA00008N000500
S28889064A6K27GA00008NB000500IWM   0000736200Y
S28889074X6K27GA00008N000500
S28889074A6K27GA00008NB000500IWM   0000736600Y
S28889084X6K27GA00008N000500
S28889084A6K27GA00008NB000500IWM   0000736200Y
S28889094X6K27GA00008N000500
S28889094A6K27GA00008NB000500IWM   0000736600Y
S28889104X6K27GA00008N000500
S28889104A6K27GA00008NB000500IWM   0000736200Y
S28889114X6K27GA00008N000500
S28889114A6K27GA00008NB000500IWM   0000736600Y
S28889124X6K27GA00008N000500
S28889124A6K27GA00008NB000500IWM   0000736200Y
S28889134X6K27GA00008N000500
S28889134A6K27GA00008NB000500IWM   0000736600Y
S28889144X6K27GA00008N000500
S28889144A6K27GA00008NB000500IWM   0000736200Y
S28889154X6K27GA00008N000500
S28889154A6K27GA00008NB000500IWM   0000736600Y
S28889164X6K27GA00008N000500
S28889164A6K27GA00008NB000500IWM   0000736200Y
S28889174X6K27GA00008N000500
S28889174A6K27GA00008NB000500IWM   0000736600Y
S28889184X6K27GA00008N000500
S28889184A6K27GA00008NB000500IWM   0000736200Y
S28889194X6K27GA00008N000500
S28889194A6K27GA00008NB000500IWM   0000736600Y
S28889204X6K27GA00008N000500
S28889204A6K27GA00008NB000500IWM   0000736200Y
S28889214X6K27GA00008N000500
S28889214A6K27GA00008NB000500IWM   0000736600Y
S28889224X6K27GA00008N000500
S28889224A6K27GA00008NB000500IWM   0000736200Y
S28889382X2K27G600006Q002000
S28889406AAK27GA000128B002000SOHU  0000800400Y
S28889411XBK27GA0000S2002000
S28889426X1K27GA00007C002000
S28889438A7K27GA000051B002000KSS   0000456300Y
S28889459XBK27GA0000S1002000
S28889460AAK27GA000129S002000SOHU  0000850800Y
S28889474X3K27G600008N002000
S28889478XCK27GA00003S002000
S28889490X5K27GA00005X002000
S28889495A7K27GA000052B002000LMT   0000260300Y
S28889507X1K27GA00007B002000
S28889511X5K27GA00005Y002000
S28889514AAK27GA00012AB002000SPLS  0000046700Y
S28889525A7K27GA000053B002000KSS   0000457100Y
S28889553AAK27GA00012BS002000SPLS  0000249600Y
S28889574X6K27GA00008N000500
S28889575A6K27GA0000A0B000500IWM   0000736100Y
S28889579A7K27GA000054B002000LMT   0000261100Y
S28889584X6K27GA0000A0000500
S28889584A6K27GA0000A0B000500IWM   0000736200Y
S28889587A1K27GA00007DB002000AFL   0000157400Y
S28889594X6K27GA0000A0000500
S28889594A6K27GA0000A0B000500IWM   0000736600Y
S28889597ABK27GA0000SMB002000SYMC  0000195200Y
S28889598ABK27GA0000SNS000100TWM   0000702200Y
S28889598ABK27GA0000SOB000100UWM   0000542500Y
S28889598XBK27GA0000SL000100
S28889596X6K27GA0000A0000500
S28889596A6K27GA0000A0B000500IWM   0000736200Y
S28889600XBK27GA0000SN000100
S28889600XBK27GA0000SO000100
S28889601ABK27GA0000SPS000100TWM   0000702400Y
S28889603X2K27G600006R002000
S28889605X6K27GA0000A0000500
S28889605A6K27GA0000A0B000500IWM   0000736600Y
S28889608ABK27GA0000SQB000100UWM   0000542500Y
S28889608XBK27GA0000SP000100
S28889608ABK27GA0000SRS000100TWM   0000702200Y
S28889615X6K27GA0000A0000500
S28889615A6K27GA0000A0B000500IWM   0000736200Y
S28889618XBK27GA0000SQ000100
S28889618XBK27GA0000SR000100
S28889620ABK27GA0000SSS000100TWM   0000702400Y
S28889621A2K27G600006TB002000BBT   0000075600Y
S28889625X6K27GA0000A0000500
S28889625A6K27GA0000A0B000500IWM   0000736600Y
S28889628ABK27GA0000STB000100UWM   0000542500Y
S28889628XBK27GA0000SS000100
S28889628ABK27GA0000SUS000100TWM   0000702200Y
S28889631ABK27GA0000SVS002000SYMC  0000217800Y
S28889630ACK27GA00003TB002000WYE   0000099800Y
S28889635X6K27GA0000A0000500
S28889635A6K27GA0000A0B000500IWM   0000736200Y
S28889638XBK27GA0000ST000100
S28889638XBK27GA0000SU000100
S28889640ABK27GA0000SWS000100TWM   0000702400Y
S28889645X6K27GA0000A0000500
S28889645A6K27GA0000A0B000500IWM   0000736600Y
S28889648ABK27GA0000SXB000100UWM   0000542500Y
S28889649ABK27GA0000SYS000100TWM   0000702200Y
S28889649XBK27GA0000SW000100
S28889650A3K27G600008OB002000COH   0000079700Y
S28889654X6K27GA0000A0000500
S28889654A6K27GA0000A0B000500IWM   0000736200Y
S28889657XBK27GA0000SX000100
S28889657XBK27GA0000SY000100
S28889659ABK27GA0000SZS000100TWM   0000702400Y
S28889659X6K27GA0000A0000500
S28889659A6K27GA0000A0B000500IWM   0000736600Y
S28889662ABK27GA0000T0S000100TWM   0000702200Y
S28889662ABK27GA0000T1B000100UWM   0000542500Y
S28889662XBK27GA0000SZ000100
S28889663ABK27GA0000T2B002000TTWO  0000255100Y
S28889664X6K27GA0000A0000500
S28889664A6K27GA0000A0B000500IWM   0000736200Y
S28889668XBK27GA0000T1000100
S28889668XBK27GA0000T0000100
S28889669ABK27GA0000T3S000100TWM   0000702400Y
S28889674X6K27GA0000A0000500
S28889674A6K27GA0000A0B000500IWM   0000736600Y
S28889677ABK27GA0000T4B000100UWM   0000542500Y
S28889677XBK27GA0000T3000100
S28889677ABK27GA0000T5S000100TWM   0000702200Y
S28889676X6K27GA0000A0000500
S28889676A6K27GA0000A0B000500IWM   0000736200Y
S28889680XBK27GA0000T5000100
S28889680XBK27GA0000T4000100
S28889681ABK27GA0000T6S000100TWM   0000702400Y
S28889685X6K27GA0000A0000500
S28889685A6K27GA0000A0B000500IWM   0000736600Y
S28889688ABK27GA0000T7B000100UWM   0000542500Y
S28889688XBK27GA0000T6000100
S28889688ABK27GA0000T8S000100TWM   0000702200Y
S28889689A1K27GA00007EB002000AFL   0000158200Y
S28889695X6K27GA0000A0000500
S28889695A6K27GA0000A0B000500IWM   0000736200Y
S28889697X4K27GA0000FZ002000
S28889698XBK27GA0000T7000100
S28889698XBK27GA0000T8000100
S28889700ABK27GA0000T9S000100TWM   0000702400Y
S28889701ABK27GA0000TAS002000TTWO  0000286600Y
S28889705X6K27GA0000A0000500
S28889705A6K27GA0000A0B000500IWM   0000736600Y
S28889715X6K27GA0000A0000500
S28889715A6K27GA0000A0B000500IWM   0000736200Y
S28889717A3K27G600008PB002000CVS   0000096600Y
S28889717X6K27GA0000A0000500
S28889717A6K27GA0000A0B000500IWM   0000736600Y
S28889723A2K27G600006UB002000CAG   0000049600Y
S28889724X6K27GA0000A0000500
S28889724A6K27GA0000A0B000500IWM   0000736200Y
S28889730ACK27GA00003UB002000VSEA  0000373100Y
S28889734X6K27GA0000A0000500
S28889734A6K27GA0000A0B000500IWM   0000736600Y
S28889739X5K27GA00005V002000
S28889744X6K27GA0000A0000500
S28889744A6K27GA0000A0B000500IWM   0000736200Y
S28889747X5K27GA00005W002000
S28889754X6K27GA0000A0000500
S28889754A6K27GA0000A0B000500IWM   0000736600Y
S28889756X6K27GA0000A0000500
S28889756A6K27GA0000A0B000500IWM   0000736200Y
S28889765X6K27GA0000A0000500
S28889765A6K27GA0000A0B000500IWM   0000736600Y
S28889769A4K27GA0000G2B002000EIX   0000114500Y
S28889775X6K27GA0000A0000500
S28889775A6K27GA0000A0B000500IWM   0000736200Y
S28889786A5K27GA00005ZB002000GE    0000300400Y
S28889785X6K27GA0000A0000500
S28889785A6K27GA0000A0B000500IWM   0000736600Y
S28889793X7K27GA00002Z002000
S28889793A5K27GA000060B002000GE    0000301200Y
S28889795X6K27GA0000A0000500
S28889795A6K27GA0000A0B000500IWM   0000736200Y
S28889797X6K27GA0000A0000500
S28889797A6K27GA0000A0B000500IWM   0000736600Y
S28889804X6K27GA0000A0000500
S28889804A6K27GA0000A0B000500IWM   0000736200Y
S28889812A6K27GA0000A1B002000JCI   0000077400Y
S28889814X6K27GA0000A0000500
S28889814A6K27GA0000A0B000500IWM   0000736600Y
S28889819X3K27G600008P002000
S28889819X5K27GA00005Z002000
S28889822X3K27G600008O002000
S28889822X2K27G600006T002000
S28889822X1K27GA00007D002000
S28889824X7K27GA000052002000
S28889824X7K27GA000051002000
S28889823X6K27GA00009W002000
S28889823X6K27GA00009V002000
S28889824X4K27GA0000G0002000
S28889825X5K27GA00005U002000
S28889824X4K27GA0000FY002000
S28889825X2K27G600006P002000
S28889825X7K27GA00004W002000
S28889826X2K27G600006N002000
S28889824X6K27GA0000A0000500
S28889824A6K27GA0000A0B000500IWM   0000736200Y
S28889833X4K27GA0000FL002000
S28889835X2K27G600006K002000
S28889833X6K27GA00009A002000
S28889834X4K27GA0000FI002000
S28889835X7K27GA00004S002000
S28889834X6K27GA0000A0000500
S28889834A6K27GA0000A0B000500IWM   0000736600Y
S28889837X2K27G600006C002000
S28889837X2K27G600006B002000
S28889837X2K27G600006A002000
S28889837X3K27G6000086002000
S28889837X2K27G6000066002000
S28889837X7K27GA00004P002000
S28889837X7K27GA00004O002000
S28889836X6K27GA0000A0000500
S28889836A6K27GA0000A0B000500IWM   0000736200Y
S28889836A6K27GA0000A2B002000KFT   0000306300Y
S28889838XBK27GA0000RN002000
S28889838X5K27GA00005E002000
S28889839X4K27GA0000FA002000
S28889839X4K27GA0000F8002000
S28889840X2K27G6000060002000
S28889839X5K27GA00005C002000
S28889839X4K27GA0000F4002000
S28889839X1K27GA00006P002000
S28889840X4K27GA0000EV002000
S28889840X3K27G600007V002000
S28889840X6K27GA00008U002000
S28889842X1K27GA00006I002000
S28889842X4K27GA0000EF002000
S28889843X4K27GA0000EC002000
S28889843X1K27GA00006A002000
S28889844X7K27GA000047002000
S28889845X8K27G600003E002000
S28889843XCK27GA00003D002000
S28889846X5K27GA00004U002000
S28889844X6K27GA00008A002000
S28889847X3K27G6000070002000
S28889845X6K27GA0000A0000500
S28889845A6K27GA0000A0B000500IWM   0000736600Y
S28889847X4K27GA0000DF002000
S28889847X6K27GA00007O002000
S28889849X3K27G600006T002000
S28889849X4K27GA0000D4002000
S28889849X7K27GA00003S002000
S28889852X7K27GA00003O002000
S28889852X6K27GA00007E002000
S28889853X7K27GA00003M002000
S28889854X7K27GA00003H002000
S28889855X7K27GA00003A002000
S28889855X7K27GA000038002000
S28889855X7K27GA000033002000
S28889856X1K27GA000056002000
S28889856X5K27GA00003W002000
S28889856X7K27GA000030002000
S28889855X6K27GA0000A0000500
S28889855A6K27GA0000A0B000500IWM   0000736200Y
S28889856X7K27GA00002V002000
S28889856X7K27GA00002U002000
S28889857X7K27GA00002T002000
S28889857X7K27GA00002P002000
S28889857X7K27GA00002L002000
S28889857X7K27GA00002I002000
S28889858X7K27GA00002H002000
S28889858X1K27GA00004I002000
S28889858X6K27GA00005Y002000
S28889858X6K27GA00005H002000
S28889859X6K27GA000055002000
S28889859X6K27GA000052002000
S28889859X6K27GA000051002000
S28889859X6K27GA000050002000
S28889861X5K27GA00002F002000
S28889862X5K27GA000027002000
S28889863X5K27GA000021002000
S28889863X5K27GA00001Y002000
S28889863X5K27GA00001X002000
S28889864X5K27GA00001W002000
S28889865X5K27GA00001T002000
S28889865X5K27GA00001R002000
S28889866X5K27GA00001P002000
S28889866X5K27GA00001N002000
S28889866X5K27GA00001K002000
S28889866X4K27GA000070002000
S28889865X6K27GA0000A0000500
S28889865A6K27GA0000A0B000500IWM   0000736600Y
S28889866X4K27GA00006P002000
S28889867X4K27GA00006N002000
S28889868X4K27GA00006I002000
S28889868X4K27GA00006B002000
S28889868X4K27GA00006A002000
S28889868X4K27GA000069002000
S28889868X4K27GA00005X002000
S28889869X4K27GA00005R002000
S28889870X3K27G6000021002000
S28889872X3K27G600001V002000
S28889874X3K27G600001U002000
S28889874X3K27G600001T002000
S28889874X3K27G600001P002000
S28889874X3K27G600001J002000
S28889874X3K27G600001I002000
S28889875X3K27G600001H002000
S28889875X3K27G600001F002000
S28889876X3K27G600001B002000
S28889876X2K27G600001L002000
S28889875X6K27GA0000A0000500
S28889875A6K27GA0000A0B000500IWM   0000736200Y
S28889877X2K27G600001K002000
S28889877X2K27G600001J002000
S28889877X2K27G600001I002000
S28889878X2K27G600001H002000
S28889878X2K27G600001C002000
S28889878X2K27G6000018002000
S28889878X2K27G6000013002000
S28889879X2K27G6000011002000
S28889879X2K27G6000010002000
S28889880X2K27G600000P002000
S28889880X1K27GA000027002000
S28889881X1K27GA00001W002000
S28889883X1K27GA00001P002000
S28889884X1K27GA00001N002000
S28889885X1K27GA00001M002000
S28889884XCK27GA00001C002000
S28889884XCK27GA00001B002000
S28889886XBK27GA000017002000
S28889886XBK27GA000016002000
S28889884X6K27GA0000A0000500
S28889884A6K27GA0000A0B000500IWM   0000736600Y
S28889887X8K27G6000009002000
S28889887X8K27G6000008002000
S28889886X7K27GA00000P002000
S28889887X7K27GA00000N002000
S28889885X6K27GA00002I002000
S28889887X5K27GA000012002000
S28889887X4K27GA000042002000
S28889888X3K27G600000I002000
S28889888X2K27G600000I002000
S28889888X2K27G600000G002000
S28889888X1K27GA00001A002000
S28889888X1K27GA000019002000
S28889888X1K27GA000018002000
S28889888X1K27GA000017002000
S28889889X1K27GA000016002000
S28889889X1K27GA000015002000
S28889895X6K27GA0000A0000500
S28889895A6K27GA0000A0B000500IWM   0000736200Y
S28889905X6K27GA0000A0000500
S28889905A6K27GA0000A0B000500IWM   0000736600Y
S28889915X6K27GA0000A0000500
S28889915A6K27GA0000A0B000500IWM   0000736200Y
S28889925X6K27GA0000A0000500
S28889925A6K27GA0000A0B000500IWM   0000736600Y
S28889935X6K27GA0000A0000500
S28889935A6K27GA0000A0B000500IWM   0000736200Y
S28889945X6K27GA0000A0000500
S28889945A6K27GA0000A0B000500IWM   0000736600Y
S28889947X6K27GA0000A0000500
S28889947A6K27GA0000A0B000500IWM   0000736200Y
S28889955X6K27GA0000A0000500
S28889955A6K27GA0000A0B000500IWM   0000736600Y
S28889965X6K27GA0000A0000500
S28889965A6K27GA0000A0B000500IWM   0000736200Y
S28889974X6K27GA0000A0000500
S28889974A6K27GA0000A0B000500IWM   0000736600Y
S28889985X6K27GA0000A0000500
S28889985A6K27GA0000A0B000500IWM   0000736200Y
S28889987X6K27GA0000A0000500
S28889987A6K27GA0000A0B000500IWM   0000736600Y
S28889994X6K27GA0000A0000500
S28889994A6K27GA0000A0B000500IWM   0000736200Y
S28890345X6K27GA0000A0000500
S28890345A6K27GA0000A3B000500IWM   0000736100Y
S28890348X3K27G6000088002000
S28890354X6K27GA0000A3000500
S28890354A6K27GA0000A3B000500IWM   0000736200Y
S28890365X6K27GA0000A3000500
S28890365A6K27GA0000A3B000500IWM   0000736600Y
S28890368ABK27GA0000TBB000100UWM   0000542500Y
S28890368XBK27GA0000T9000100
S28890368ABK27GA0000TCS000100TWM   0000702200Y
S28890375X6K27GA0000A3000500
S28890375A6K27GA0000A3B000500IWM   0000736200Y
S28890378XBK27GA0000TB000100
S28890378XBK27GA0000TC000100
S28890380ABK27GA0000TDS000100TWM   0000702400Y
S28890386A2K27G600006VB002000BMY   0000046800Y
S28890385X6K27GA0000A3000500
S28890385A6K27GA0000A3B000500IWM   0000736600Y
S28890388ABK27GA0000TEB000100UWM   0000542500Y
S28890388XBK27GA0000TD000100
S28890388ABK27GA0000TFS000100TWM   0000702200Y
S28890395X6K27GA0000A3000500
S28890395A6K27GA0000A3B000500IWM   0000736200Y
S28890398XBK27GA0000TE000100
S28890398XBK27GA0000TF000100
S28890400ABK27GA0000TGS000100TWM   0000702400Y
S28890400X5K27GA000051002000
S28890404ACK27GA00003VS002000VSEA  0000430500Y
S28890404X6K27GA0000A3000500
S28890404A6K27GA0000A3B000500IWM   0000736600Y
S28890408ABK27GA0000THB000100UWM   0000542500Y
S28890408XBK27GA0000TG000100
S28890408ABK27GA0000TIS000100TWM   0000702200Y
S28890409X7K27GA000054002000
S28890414X6K27GA0000A3000500
S28890414A6K27GA0000A3B000500IWM   0000736200Y
S28890417XBK27GA0000TH000100
S28890417XBK27GA0000TI000100
S28890419ABK27GA0000TJS000100TWM   0000702400Y
S28890418A6K27GA0000A4B000100IWM   0000736100Y
S28890418X6K27GA0000A4000100
S28890418X6K27GA0000A3000500
S28890418A6K27GA0000A3B000500IWM   0000736600Y
S28890421ABK27GA0000TKB000100UWM   0000542500Y
S28890422ABK27GA0000TLS000100TWM   0000702200Y
S28890422XBK27GA0000TJ000100
S28890424X6K27GA0000A3000500
S28890424A6K27GA0000A3B000500IWM   0000736200Y
S28890428XBK27GA0000TK000100
S28890428XBK27GA0000TL000100
S28890426ACK27GA00003WB002000WFMI  0000276500Y
S28890429X6K27GA0000A3000500
S28890429A6K27GA0000A3B000500IWM   0000736600Y
S28890431ABK27GA0000TMS000100TWM   0000702400Y
S28890430A6K27GA0000A5B000100IWM   0000736100Y
S28890430X6K27GA0000A5000100
S28890430XCK27GA00003T002000
S28890432XBK27GA0000TM000100
S28890432ABK27GA0000TNB000100UWM   0000542500Y
S28890432ABK27GA0000TOS000100TWM   0000702200Y
S28890431X6K27GA0000A3000500
S28890431A6K27GA0000A3B000500IWM   0000736200Y
S28890434XBK27GA0000TN000100
S28890434XBK27GA0000TO000100
S28890434X6K27GA0000A3000500
S28890434A6K27GA0000A3B000500IWM   0000736600Y
S28890436ABK27GA0000TPS000100TWM   0000702400Y
S28890437ABK27GA0000TQB000100UWM   0000542500Y
S28890437XBK27GA0000TP000100
S28890437ABK27GA0000TRS000100TWM   0000702200Y
S28890440ABK27GA0000TSB002000UTX   0000173100Y
S28890444X6K27GA0000A3000500
S28890444A6K27GA0000A3B000500IWM   0000736200Y
S28890447XBK27GA0000TQ000100
S28890447XBK27GA0000TR000100
S28890448A6K27GA0000A6B000100IWM   0000736100Y
S28890449ABK27GA0000TTS000100TWM   0000702400Y
S28890448X6K27GA0000A6000100
S28890448X6K27GA0000A3000500
S28890448A6K27GA0000A3B000500IWM   0000736600Y
S28890450ACK27GA00003XB002000XLNX  0000255700Y
S28890452ABK27GA0000TUB000100UWM   0000542500Y
S28890452XBK27GA0000TT000100
S28890452ABK27GA0000TVS000100TWM   0000702200Y
S28890454X6K27GA0000A3000500
S28890454A6K27GA0000A3B000500IWM   0000736200Y
S28890458XBK27GA0000TU000100
S28890458XBK27GA0000TV000100
S28890458A6K27GA0000A7B000100IWM   0000736100Y
S28890459ABK27GA0000TWS000100TWM   0000702400Y
S28890458X6K27GA0000A7000100
S28890459X6K27GA0000A3000500
S28890459A6K27GA0000A3B000500IWM   0000736600Y
S28890461X6K27GA0000A3000500
S28890461A6K27GA0000A3B000500IWM   0000736200Y
S28890465X1K27GA00007E002000
S28890465X6K27GA0000A3000500
S28890465A6K27GA0000A3B000500IWM   0000736600Y
S28890467A1K27GA00007FB002000ABT   0000130300Y
S28890474X2K27G600006S002000
S28890475X6K27GA0000A3000500
S28890475A6K27GA0000A3B000500IWM   0000736200Y
S28890485X6K27GA0000A3000500
S28890485A6K27GA0000A3B000500IWM   0000736600Y
S28890486ACK27GA00003YS002000XLNX  0000289900Y
S28890490X2K27G600006H002000
S28890495X6K27GA0000A3000500
S28890495A6K27GA0000A3B000500IWM   0000736200Y
S28890500X3K27G600008M002000
S28890504X6K27GA0000A3000500
S28890504A6K27GA0000A3B000500IWM   0000736600Y
S28890506X6K27GA0000A3000500
S28890506A6K27GA0000A3B000500IWM   0000736200Y
S28890513ACK27GA00003ZB002000YHOO  0000265100Y
S28890515X6K27GA0000A3000500
S28890515A6K27GA0000A3B000500IWM   0000736600Y
S28890525X6K27GA0000A3000500
S28890525A6K27GA0000A3B000500IWM   0000736200Y
S28890534X6K27GA0000A3000500
S28890534A6K27GA0000A3B000500IWM   0000736600Y
S28890538ACK27GA000040S002000YHOO  0000287600Y
S28890540X4K27GA0000DG002000
S28890545X6K27GA0000A3000500
S28890545A6K27GA0000A3B000500IWM   0000736200Y
S28890553X4K27GA0000G2002000
S28890554X6K27GA0000A3000500
S28890554A6K27GA0000A3B000500IWM   0000736600Y
S28890556X6K27GA0000A3000500
S28890556A6K27GA0000A3B000500IWM   0000736200Y
S28890564A1K27GA00007GB002000AAPL  0001817200Y
S28890565X6K27GA0000A3000500
S28890565A6K27GA0000A3B000500IWM   0000736600Y
S28890569A3K27G600008QB002000CVS   0000098500Y
S28890575X6K27GA0000A3000500
S28890575A6K27GA0000A3B000500IWM   0000736200Y
S28890585A1K27GA00007HS002000AAPL  0001844700Y
S28890585X6K27GA0000A3000500
S28890585A6K27GA0000A3B000500IWM   0000736600Y
S28890592A5K27GA000061B002000HNZ   0000106100Y
S28890595X6K27GA0000A3000500
S28890595A6K27GA0000A3B000500IWM   0000736200Y
S28890597X6K27GA0000A3000500
S28890597A6K27GA0000A3B000500IWM   0000736600Y
S28890604X6K27GA0000A3000500
S28890604A6K27GA0000A3B000500IWM   0000736200Y
S28890607A1K27GA00007IB002000ADSK  0000384200Y
S28890611A5K27GA000062B002000HOT   0000109700Y
S28890614X6K27GA0000A3000500
S28890614A6K27GA0000A3B000500IWM   0000736600Y
S28890624X6K27GA0000A3000500
S28890624A6K27GA0000A3B000500IWM   0000736200Y
S28890634X6K27GA0000A3000500
S28890634A6K27GA0000A3B000500IWM   0000736600Y
S28890638A7K27GA000055B002000MDY   0001579600Y
S28890645X6K27GA0000A3000500
S28890645A6K27GA0000A3B000500IWM   0000736200Y
S28890655X6K27GA0000A3000500
S28890655A6K27GA0000A3B000500IWM   0000736600Y
S28890665X6K27GA0000A3000500
S28890665A6K27GA0000A3B000500IWM   0000736200Y
S28890675X6K27GA0000A3000500
S28890675A6K27GA0000A3B000500IWM   0000736600Y
S28890685X6K27GA0000A3000500
S28890685A6K27GA0000A3B000500IWM   0000736200Y
S28890695X6K27GA0000A3000500
S28890695A6K27GA0000A3B000500IWM   0000736600Y
S28890705X6K27GA0000A3000500
S28890705A6K27GA0000A3B000500IWM   0000736200Y
S28890715X6K27GA0000A3000500
S28890715A6K27GA0000A3B000500IWM   0000736600Y
S28890725X6K27GA0000A3000500
S28890725A6K27GA0000A3B000500IWM   0000736200Y
S28890735X6K27GA0000A3000500
S28890735A6K27GA0000A3B000500IWM   0000736600Y
S28890745X6K27GA0000A3000500
S28890745A6K27GA0000A3B000500IWM   0000736200Y
S28890754X6K27GA0000A3000500
S28890754A6K27GA0000A3B000500IWM   0000736600Y
S28890765X6K27GA0000A3000500
S28890765A6K27GA0000A3B000500IWM   0000736200Y
S28890788E1K27GA00004W00010000001AQ00004
S28890983XAK27GA000118001000
S28890984AAK27GA00012CS001000SPY   0001425600Y
S28890984XAK27GA000115001000
S28890985XBK27GA0000QG001000
S28890985ABK27GA0000TXS001000SSO   0000765200Y
S28890985AAK27GA00012DS005000SPY   0001425900Y
S28890986AAK27GA00012ES000500SPY   0001425800Y
S28890986XAK27GA00011Z005000
S28890986XAK27GA000120000500
S28890986AAK27GA00012FB001000SPY   0001425100Y
S28890995X4K27GA000062000200
S28890995A4K27GA000062B000200DIA   0001298400Y
S28890997X3K27G600007J000100
S28890999A3K27G600008RB000100DDM   0000801000Y
S28891010A6K27GA0000A8S002000IWM   0000737100Y
S28891033X6K27GA00008M002000
S28891321X8K27G600003T000500
S28891321X8K27G600003R000100
S28891373A3K27G600008SB002000CELG  0000485300Y
S28891376XBK27GA0000TS002000
S28891394X1K27GA00007F002000
S28891400A1K27GA00007KS002000ADSK  0000420200Y
S28891405X2K27G600006L002000
S28891417X2K27G600006U002000
S28891425A1K27GA00007LB002000ADTN  0000228200Y
S28891431A5K27GA000063B002000GM    0000177800Y
S28891441X3K27G600008Q002000
S28891453A1K27GA00007MS002000ADTN  0000264200Y
S28891454X3K27G600007T002000
S28891469A7K27GA000056B002000LMT   0000267100Y
S28891477A1K27GA00007NB002000ALTR  0000213300Y
S28891495ACK27GA000041B002000WYE   0000102200Y
S28891499A1K27GA00007OS002000ALTR  0000246300Y
S28891509X5K27GA000061002000
S28891516X5K27GA000062002000
S28891528X6K27GA0000A1002000
S28891534X7K27GA000031002000
S28891542X7K27GA00003L002000
S28891550A1K27GA00007PB002000APOL  0000410200Y
S28891561A1K27GA00007QB002000AFL   0000161900Y
S28891582A2K27G600006WB002000BBT   0000078300Y
S28891581A1K27GA00007RS002000APOL  0000536500Y
S28891594A2K27G600006XB002000BDX   0000768800Y
S28891594A1K27GA00007SB002000APPX  0000095800Y
S28891612A3K27G600008TB002000COH   0000082400Y
S28891627A4K27GA0000G3B002000EAT   0000200600Y
S28891637A4K27GA0000G4B002000EIX   0000117300Y
S28892374XAK27GA000123002000
S28892378X2K27G600006V002000
S28892384A1K27GA00007TS002000APPX  0000149400Y
S28892390X7K27GA000056002000
S28892399XCK27GA000041002000
S28892409X1K27GA00007Q002000
S28892410A2K27G600006YB002000BBBY  0000307600Y
S28892418X1K27GA00006G002000
S28892422X4K27GA0000G4002000
S28892431X7K27GA000032002000
S28892443A2K27G600006ZS002000BBBY  0000350200Y
S28892444ABK27GA0000TYB002000UTX   0000177100Y
S28892469A2K27G6000070B002000CAKE  0000193900Y
S28892477A1K27GA00007UB002000ABT   0000133400Y
S28892493A2K27G6000071S002000CAKE  0000251300Y
S28892500A2K27G6000072B002000AXP   0000411400Y
S28892512A3K27G600008UB002000CECO  0000107600Y
S28892520A2K27G6000073B002000CAG   0000051500Y
S28892537A3K27G600008VS002000CECO  0000193000Y
S28892541A3K27G600008WB002000CVS   0000100900Y
S28892557A3K27G600008XB002000DD    0000459100Y
S28892561A3K27G600008YB002000CEPH  0000645200Y
S28892577A5K27GA000064B002000HNZ   0000108600Y
S28892586A5K27GA000065B002000HOT   0000112400Y
S28892619A3K27G600008ZS002000CEPH  0000779800Y
S28892727X4K27GA000062000200
S28892727A4K27GA000062B000200DIA   0001298700Y
S28892730A3K27G6000090B000100DDM   0000801100Y
S28892730XAK27GA00012D005000
S28892730AAK27GA00012GS005000SPY   0001426200Y
S28892730XAK27GA00012E000500
S28892731AAK27GA00012HS000500SPY   0001425900Y
S28892731XAK27GA0000O8000500
S28892731AAK27GA0000O8S000500SPY   0001426100Y
S28892731X4K27GA0000FV000200
S28892731XAK27GA0000ZM000500
S28892731AAK27GA0000ZMS000500SPY   0001426000Y
S28892731XAK27GA00012C001000
S28892731XAK27GA00012F001000
S28892731AAK27GA00012IB002000SPY   0001425500Y
S28892731AAK27GA00012JB001000SPY   0001425500Y
S28892733AAK27GA00012KS001000SPY   0001426000Y
S28892733XBK27GA0000TX001000
S28892733XAK27GA00011Y002500
S28892734AAK27GA00012LS002500SPY   0001426000Y
S28892735ABK27GA0000TZS001000SSO   0000765300Y
S28892736A4K27GA0000G5S000200DIA   0001299200Y
S28892738XAK27GA00012H000500
S28892740XAK27GA000121001000
S28892745XAK27GA0000FG000500
S28892745AAK27GA0000FGB000500SPY   0001425500Y
S28892748X6K27GA0000A3000500
S28892748A6K27GA0000A9B002000IWM   0000736500Y
S28892750XAK27GA000122001000
S28892749A6K27GA0000AAB000500IWM   0000736600Y
S28892751ABK27GA0000U0B000100UWM   0000542500Y
S28892750X6K27GA0000A8002000
S28892751XBK27GA0000TW000100
S28892751ABK27GA0000U1S000100TWM   0000702200Y
S28892750X6K27GA0000AA000500
S28892750A6K27GA0000AAB000500IWM   0000736200Y
S28892752X6K27GA0000AA000500
S28892752A6K27GA0000AAB000500IWM   0000736600Y
S28892753XBK27GA0000U0000100
S28892754XBK27GA0000U1000100
S28892755ABK27GA0000U2B000100UWM   0000542500Y
S28892754A6K27GA0000ABB000100IWM   0000736100Y
S28892755ABK27GA0000U3S000100TWM   0000702200Y
S28892754X6K27GA0000AA000500
S28892754A6K27GA0000AAB000500IWM   0000736200Y
S28892754X6K27GA0000AB000100
S28892764X6K27GA0000AA000500
S28892764A6K27GA0000AAB000500IWM   0000736600Y
S28892766XBK27GA0000U2000100
S28892766XBK27GA0000U3000100
S28892768ABK27GA0000U4B000100UWM   0000542500Y
S28892768ABK27GA0000U5S000100TWM   0000702200Y
S28892767X6K27GA0000AA000500
S28892767A6K27GA0000AAB000500IWM   0000736200Y
S28892774X6K27GA0000AA000500
S28892774A6K27GA0000AAB000500IWM   0000736600Y
S28892778X6K27GA0000AA000500
S28892778A6K27GA0000AAB000500IWM   0000736200Y
S28892784X6K27GA0000AA000500
S28892784A6K27GA0000AAB000500IWM   0000736600Y
S28892794X6K27GA0000AA000500
S28892794A6K27GA0000AAB000500IWM   0000736200Y
S28892797XBK27GA0000U4000100
S28892797XBK27GA0000U5000100
S28892799ABK27GA0000U6S000100TWM   0000702400Y
S28892798X6K27GA0000AA000500
S28892798A6K27GA0000AAB000500IWM   0000736600Y
S28892801ABK27GA0000U7B000100UWM   0000542500Y
S28892801ABK27GA0000U8S000100TWM   0000702200Y
S28892801XBK27GA0000U6000100
S28892804X6K27GA0000AA000500
S28892804A6K27GA0000AAB000500IWM   0000736200Y
S28892807XBK27GA0000U7000100
S28892807XBK27GA0000U8000100
S28892809ABK27GA0000U9S000100TWM   0000702400Y
S28892814X6K27GA0000AA000500
S28892814A6K27GA0000AAB000500IWM   0000736600Y
S28892816ABK27GA0000UAB000100UWM   0000542500Y
S28892816ABK27GA0000UBS000100TWM   0000702200Y
S28892816XBK27GA0000U9000100
S28892824X6K27GA0000AA000500
S28892824A6K27GA0000AAB000500IWM   0000736200Y
S28892827XBK27GA0000UA000100
S28892827XBK27GA0000UB000100
S28892829ABK27GA0000UCS000100TWM   0000702400Y
S28892829X6K27GA0000AA000500
S28892829A6K27GA0000AAB000500IWM   0000736600Y
S28892834X6K27GA0000AA000500
S28892834A6K27GA0000AAB000500IWM   0000736200Y
S28892844X6K27GA0000AA000500
S28892844A6K27GA0000AAB000500IWM   0000736600Y
S28892846ABK27GA0000UDB000100UWM   0000542500Y
S28892846ABK27GA0000UES000100TWM   0000702200Y
S28892846XBK27GA0000UC000100
S28892854X6K27GA0000AA000500
S28892854A6K27GA0000AAB000500IWM   0000736200Y
S28892855XBK27GA0000UD000100
S28892855XBK27GA0000UE000100
S28892856A6K27GA0000ACB000100IWM   0000736100Y
S28892857ABK27GA0000UFS000100TWM   0000702400Y
S28892856X6K27GA0000AC000100
S28892856X6K27GA0000AA000500
S28892856A6K27GA0000AAB000500IWM   0000736600Y
S28892864X6K27GA0000AA000500
S28892864A6K27GA0000AAB000500IWM   0000736200Y
S28892874X6K27GA0000AA000500
S28892874A6K27GA0000AAB000500IWM   0000736600Y
S28892876ABK27GA0000UGB000100UWM   0000542500Y
S28892876XBK27GA0000UF000100
S28892876ABK27GA0000UHS000100TWM   0000702200Y
S28892884X6K27GA0000AA000500
S28892884A6K27GA0000AAB000500IWM   0000736200Y
S28892885XBK27GA0000UG000100
S28892885XBK27GA0000UH000100
S28892887ABK27GA0000UIS000100TWM   0000702400Y
S28892887X6K27GA0000AA000500
S28892887A6K27GA0000AAB000500IWM   0000736600Y
S28892891X6K27GA0000AA000500
S28892891A6K27GA0000AAB000500IWM   0000736200Y
S28892894X6K27GA0000AA000500
S28892894A6K27GA0000AAB000500IWM   0000736600Y
S28892896ABK27GA0000UJB000100UWM   0000542500Y
S28892896XBK27GA0000UI000100
S28892896ABK27GA0000UKS000100TWM   0000702200Y
S28892899XAK27GA0000E6001000
S28892899AAK27GA0000E6S001000SPY   0001426100Y
S28892904X6K27GA0000AA000500
S28892904A6K27GA0000AAB000500IWM   0000736200Y
S28892905XBK27GA0000UJ000100
S28892905XBK27GA0000UK000100
S28892907ABK27GA0000ULS000100TWM   0000702400Y
S28892907X6K27GA0000AA000500
S28892907A6K27GA0000AAB000500IWM   0000736600Y
S28892914X6K27GA0000AA000500
S28892914A6K27GA0000AAB000500IWM   0000736200Y
S28892924X6K27GA0000AA000500
S28892924A6K27GA0000AAB000500IWM   0000736600Y
S28892925ABK27GA0000UMB000100UWM   0000542500Y
S28892925XBK27GA0000UL000100
S28892926ABK27GA0000UNS000100TWM   0000702200Y
S28892934X6K27GA0000AA000500
S28892934A6K27GA0000AAB000500IWM   0000736200Y
S28892935XBK27GA0000UM000100
S28892935XBK27GA0000UN000100
S28892937AAK27GA00012MS000500SPY   0001426000Y
S28892937ABK27GA0000UOS000100TWM   0000702400Y
S28892937X6K27GA0000AA000500
S28892937A6K27GA0000AAB000500IWM   0000736600Y
S28892944X6K27GA0000AA000500
S28892944A6K27GA0000AAB000500IWM   0000736200Y
S28892954X6K27GA0000AA000500
S28892954A6K27GA0000AAB000500IWM   0000736600Y
S28892960A8K27G600004ES000500MZZ   0000493900Y
S28892960A8K27G600004FB000100MVV   0000806200Y
S28892964X6K27GA0000AA000500
S28892964A6K27GA0000AAB000500IWM   0000736200Y
S28892974X6K27GA0000AA000500
S28892974A6K27GA0000AAB000500IWM   0000736600Y
S28892984X6K27GA0000AA000500
S28892984A6K27GA0000AAB000500IWM   0000736200Y
S28892994X6K27GA0000AA000500
S28892994A6K27GA0000AAB000500IWM   0000736600Y
S28893004X6K27GA0000AA000500
S28893004A6K27GA0000AAB000500IWM   0000736200Y
S28893024X6K27GA0000AA000500
S28893024A6K27GA0000AAB000500IWM   0000736600Y
S28893034X6K27GA0000AA000500
S28893034A6K27GA0000AAB000500IWM   0000736200Y
S28893044X6K27GA0000AA000500
S28893044A6K27GA0000AAB000500IWM   0000736600Y
S28893054X6K27GA0000AA000500
S28893054A6K27GA0000AAB000500IWM   0000736200Y
S28893064X6K27GA0000AA000500
S28893064A6K27GA0000AAB000500IWM   0000736600Y
S28893070XAK27GA0000SJ000600
S28893074AAK27GA00012NB001000SPY   0001419700Y
S28893074X6K27GA0000AA000500
S28893074A6K27GA0000AAB000500IWM   0000736200Y
S28893084X6K27GA0000AA000500
S28893084A6K27GA0000AAB000500IWM   0000736600Y
S28893094X6K27GA0000AA000500
S28893094A6K27GA0000AAB000500IWM   0000736200Y
S28893104X6K27GA0000AA000500
S28893104A6K27GA0000AAB000500IWM   0000736600Y
S28893114X6K27GA0000AA000500
S28893114A6K27GA0000AAB000500IWM   0000736200Y
S28893124X6K27GA0000AA000500
S28893124A6K27GA0000AAB000500IWM   0000736600Y
S28893132X4K27GA0000FG000100
S28893132X3K27G600008B000100
S28893134X6K27GA0000AA000500
S28893134A6K27GA0000AAB000500IWM   0000736200Y
S28893144X6K27GA0000AA000500
S28893144A6K27GA0000AAB000500IWM   0000736600Y
S28893154X6K27GA0000AA000500
S28893154A6K27GA0000AAB000500IWM   0000736200Y
S28893186X4K27GA00007C000200
S28893186A4K27GA00007CB000200DIA   0001298800Y
S28893188A4K27GA0000G6S000100DOG   0000598300Y
S28893188A4K27GA0000G7S000100DXD   0000500100Y
S28893188A3K27G6000091B000100DDM   0000801200Y
S28893312XAK27GA00011V002500
S28893356X1K27GA000071002000
S28893375A2K27G6000074B002000BMY   0000048600Y
S28893389XAK27GA00012A002000
S28893396XBK27GA0000TY002000
S28893395AAK27GA00012OB002000SHLD  0000754800Y
S28893402XCK27GA00003B002000
S28893420A3K27G6000092B002000CCMP  0000354200Y
S28893423XAK27GA0000E8001000
S28893423AAK27GA0000E8B001000SPY   0001425600Y
S28893423XAK27GA0000F7000500
S28893423AAK27GA0000F7B000500SPY   0001425500Y
S28893423AAK27GA00012PB002000SPY   0001425600Y
S28893423XAK27GA0000NZ000500
S28893423AAK27GA0000NZS000500SPY   0001426100Y
S28893424XAK27GA00011W001000
S28893424XBK27GA0000S0001000
S28893424AAK27GA00012QS001000SDS   0000548900Y
S28893424ABK27GA0000UPB001000SSO   0000764400Y
S28893424XAK27GA00011X005000
S28893424AAK27GA00012RB001000SPY   0001425600Y
S28893425AAK27GA00012SB002500SPY   0001425500Y
S28893427ABK27GA0000UQB001000SSO   0000764200Y
S28893427XBK27GA0000RZ001000
S28893428A7K27GA000057B002000LMT   0000273100Y
S28893441XAK27GA0000ZJ001000
S28893443AAK27GA00012TS001000SPY   0001426100Y
S28893444A3K27G6000093S002000CCMP  0000390000Y
S28893444X1K27GA00007U002000
S28893445A6K27GA0000ADB002000IWM   0000736600Y
S28893446X6K27GA00002B000500
S28893446A6K27GA00002BS000500IWM   0000737200Y
S28893448X4K27GA0000FF000200
S28893448ABK27GA0000URB000100UWM   0000542500Y
S28893449ABK27GA0000USS000100TWM   0000702200Y
S28893449XBK27GA0000UO000100
S28893450XBK27GA0000TZ001000
S28893451A4K27GA0000G8S000200DIA   0001299300Y
S28893452A8K27G600004GS000500MZZ   0000493800Y
S28893452A8K27G600004HB000100MVV   0000806300Y
S28893452ABK27GA0000UTS001000SSO   0000765400Y
S28893456XBK27GA0000RU000100
S28893456XBK27GA0000RW000100
S28893456XBK27GA0000RV000100
S28893475X8K27G6000047000500
S28893475X8K27G6000048000100
S28893477A8K27G600004IS000100MVV   0000809600Y
S28893489A3K27G6000094B002000CMCSA 0000192800Y
S28893490ACK27GA000042B002000WYE   0000104600Y
S28893525A1K27GA00007VB002000AFL   0000165600Y
S28893546X2K27G600006W002000
S28893566A3K27G6000095S002000CMCSA 0000239100Y
S28893585X3K27G600008T002000
S28893599X3K27G600008W002000
S28893602AAK27GA00012UB001000SPY   0001425400Y
S28893613X6K27GA0000AA000500
S28893619A6K27GA0000AEB000500IWM   0000736600Y
S28893637A3K27G6000096S002000CMCSK 0000274600Y
S28893656X5K27GA000064002000
S28893663A3K27G6000097B002000COST  0000697300Y
S28893663A1K27GA00007WB002000ARO   0000297600Y
S28893671X5K27GA000065002000
S28893687A3K27G6000098S002000COST  0000745700Y
S28893704A4K27GA0000G9B002000EIX   0000120100Y
S28893716A6K27GA0000AFB002000JCI   0000081200Y
S28893728A7K27GA000058B002000KMB   0000613000Y
S28893739A7K27GA000059B002000KMX   0000188000Y
S28894362X7K27GA000057002000
S28894370A1K27GA00007XS002000AMGN  0000487400Y
S28894394ABK27GA0000UUB002000UTX   0000181100Y
S28894396AAK27GA00012VB002000SPLS  0000049900Y
S28894412A3K27G6000099B002000CSCO  0000251300Y
S28894411ACK27GA000043B002000WMT   0000539900Y
S28894422XCK27GA000042002000
S28894440A3K27G600009AS002000CSCO  0000274300Y
S28894445A1K27GA00007YB002000ABT   0000136400Y
S28894455X1K27GA00007V002000
S28894466A3K27G600009BB002000CTAS  0000281600Y
S28894485A2K27G6000075B002000BBT   0000081200Y
S28894487A3K27G600009CS002000CTAS  0000323900Y
S28894501X2K27G6000073002000
S28894514A3K27G600009DB002000CTSH  0000072100Y
S28894520A3K27G600009EB002000COH   0000085400Y
S28894534A3K27G600009FS002000CTSH  0000337600Y
S28894545A3K27G600009GB002000CVS   0000103300Y
S28894582A3K27G600009HB002000DAL   0000010000Y
S28894582X4K27GA0000G9002000
S28894590X5K27GA00005L002000
S28894602A5K27GA000066B002000HNZ   0000111200Y
S28894611A5K27GA000067B002000HOT   0000115100Y
S28894685XAK27GA00012P002000
S28894685XAK27GA00012R001000
S28894685XAK27GA00012T001000
S28894685X4K27GA0000G8000200
S28894685XAK27GA0000NZ000500
S28894685AAK27GA0000NZS000500SPY   0001425700Y
S28894685AAK27GA00012WS001000SPY   0001425700Y
S28894685XAK27GA0000E8001000
S28894685AAK27GA0000E8B001000SPY   0001425200Y
S28894687XBK27GA0000UT001000
S28894687ABK27GA0000UVS001000SSO   0000765300Y
S28894686AAK27GA00012XB001000SPY   0001425200Y
S28894687AAK27GA00012YB005000SPY   0001425200Y
S28894687XAK27GA00012S002500
S28894688AAK27GA00012ZB002500SPY   0001425400Y
S28894690XAK27GA00012Q001000
S28894691XBK27GA0000UP001000
S28894691ABK27GA0000UWB001000SSO   0000764100Y
S28894691A4K27GA0000GAS000200DIA   0001299000Y
S28894692XBK27GA0000UQ001000
S28894693ABK27GA0000UXB001000SSO   0000764300Y
S28894702X4K27GA00007C000200
S28894702A4K27GA00007CB000200DIA   0001298500Y
S28894704X4K27GA0000G6000100
S28894704X4K27GA0000G7000100
S28894704X3K27G6000091000100
S28894718X8K27G6000045000500
S28894719X8K27G600004I000100
S28894719X8K27G6000046000100
S28894720A8K27G600004JB000500MZZ   0000491400Y
S28894721A8K27G600004KS000100MVV   0000809700Y
S28894811A4K27GA0000GBB000100DXD   0000499500Y
S28894812A3K27G600009IS000100DDM   0000802500Y
S28894921XAK27GA00012U001000
S28894941A8K27G600004LB000500MZZ   0000491500Y
S28894941A8K27G600004MS000100MVV   0000809500Y
S28894940X4K27GA0000G5000200
S28894948A4K27GA0000GCS000200DIA   0001298900Y
S28895398X2K27G6000074002000
S28895398A3K27G600009JB002000CYBX  0000139900Y
S28895404XBK27GA0000UU002000
S28895407A1K27GA00007ZB002000AA    0000431500Y
S28895410X1K27GA00007Y002000
S28895423X3K27G6000071002000
S28895430X3K27G600009G002000
S28895436X5K27GA000066002000
S28895442A3K27G600009KS002000CYBX  0000190700Y
S28895450X5K27GA000067002000
S28895458X6K27GA00007V002000
S28895460A1K27GA000080S002000AA    0000462100Y
S28895468X6K27GA0000AF002000
S28895478X6K27GA0000AD002000
S28895479X6K27GA00002B000500
S28895479A6K27GA00002BS000500IWM   0000736800Y
S28895482ABK27GA0000UYS000100UWM   0000543500Y
S28895482ABK27GA0000UZB000100TWM   0000700900Y
S28895482ABK27GA0000V0B000100TWM   0000700800Y
S28895485A3K27G600009LB002000DELL  0000194500Y
S28895491A1K27GA000081B002000ADI   0000339900Y
S28895498A7K27GA00005AB002000LMT   0000279100Y
S28895515A3K27G600009MS002000DELL  0000223400Y
S28895531A1K27GA000082S002000ADI   0000366800Y
S28895542ACK27GA000044B002000WYE   0000107100Y
S28895560A4K27GA0000GDB002000ESRX  0000648000Y
S28895560A1K27GA000083B002000ADP   0000419300Y
S28895569A1K27GA000084B002000AFL   0000169300Y
S28895583A2K27G6000076B002000CAG   0000053500Y
S28895593A1K27GA000085S002000ADP   0000446600Y
S28895613A4K27GA0000GEB002000EIX   0000122900Y
S28895619A4K27GA0000GFS002000ESRX  0000735800Y
S28895628A1K27GA000086B002000AIG   0000372500Y
S28895634A5K27GA000068B002000HMY   0000089700Y
S28895654A4K27GA0000GGB002000EXPD  0000444000Y
S28895662A1K27GA000087S002000AIG   0000400200Y
S28895699A1K27GA000088B002000APA   0001428400Y
S28895699A4K27GA0000GHS002000EXPD  0000499400Y
S28895719A7K27GA00005BB002000LLY   0000465800Y
S28895729A1K27GA000089S002000APA   0001480900Y
S28895742A7K27GA00005CB002000MEE   0000624100Y
S28895772A7K27GA00005DB002000MER   0000463900Y
S28896221XAK27GA00012I002000
S28896221XAK27GA0000E6001000
S28896221AAK27GA0000E6S001000SPY   0001425700Y
S28896221XAK27GA0000O8000500
S28896221AAK27GA0000O8S000500SPY   0001425700Y
S28896221XAK27GA0000FG000500
S28896221AAK27GA0000FGB000500SPY   0001425100Y
S28896221XAK27GA0000F7000500
S28896221AAK27GA0000F7B000500SPY   0001425100Y
S28896221X4K27GA000062000200
S28896221A4K27GA000062B000200DIA   0001298400Y
S28896223AAK27GA000130S005000SPY   0001426000Y
S28896224X3K27G6000090000100
S28896224AAK27GA000131S000500SPY   0001425900Y
S28896224XAK27GA00012M000500
S28896225AAK27GA000132S002500SPY   0001425900Y
S28896225XAK27GA00012G005000
S28896225XAK27GA00012L002500
S28896234X8K27G600004G000500
S28896234X8K27G600004H000100
S28896238X6K27GA0000AE000500
S28896238A6K27GA0000AEB000500IWM   0000736200Y
S28896240AAK27GA000133S001000SPY   0001426000Y
S28896244X6K27GA0000AE000500
S28896244A6K27GA0000AEB000500IWM   0000736600Y
S28896246XBK27GA0000US000100
S28896246XBK27GA0000UR000100
S28896246A6K27GA0000AGB000100IWM   0000736100Y
S28896248ABK27GA0000V1S000100TWM   0000702200Y
S28896248ABK27GA0000V2B000100UWM   0000542500Y
S28896247X6K27GA0000AG000100
S28896254X6K27GA0000AE000500
S28896254A6K27GA0000AEB000500IWM   0000736200Y
S28896258X6K27GA0000AE000500
S28896258A6K27GA0000AEB000500IWM   0000736600Y
S28896261A4K27GA0000GIB000100DOG   0000597100Y
S28896262A3K27G600009NS000100DDM   0000802400Y
S28896264X6K27GA0000AE000500
S28896264A6K27GA0000AEB000500IWM   0000736200Y
S28896266X6K27GA0000AE000500
S28896266A6K27GA0000AEB000500IWM   0000736600Y
S28896274X6K27GA0000AE000500
S28896274A6K27GA0000AEB000500IWM   0000736200Y
S28896284X6K27GA0000AE000500
S28896284A6K27GA0000AEB000500IWM   0000736600Y
S28896285XBK27GA0000V2000100
S28896285XBK27GA0000V1000100
S28896287ABK27GA0000V3B000100UWM   0000542500Y
S28896287ABK27GA0000V4S000100TWM   0000702200Y
S28896294X6K27GA0000AE000500
S28896294A6K27GA0000AEB000500IWM   0000736200Y
S28896304X6K27GA0000AE000500
S28896304A6K27GA0000AEB000500IWM   0000736600Y
S28896305XBK27GA0000V3000100
S28896305XBK27GA0000V4000100
S28896307ABK27GA0000V5S000100TWM   0000702200Y
S28896307ABK27GA0000V6B000100UWM   0000542500Y
S28896314X6K27GA0000AE000500
S28896314A6K27GA0000AEB000500IWM   0000736200Y
S28896324X6K27GA0000AE000500
S28896324A6K27GA0000AEB000500IWM   0000736600Y
S28896325XBK27GA0000V6000100
S28896325XBK27GA0000V5000100
S28896327ABK27GA0000V7B000100UWM   0000542500Y
S28896327ABK27GA0000V8S000100TWM   0000702200Y
S28896333X9K27G60000O5002000
S28896334X6K27GA0000AE000500
S28896334A6K27GA0000AEB000500IWM   0000736200Y
S28896336A9K27G60000QSS000700QQQQ  0000495800Y
S28896344X6K27GA0000AE000500
S28896344A6K27GA0000AEB000500IWM   0000736600Y
S28896345XBK27GA0000V7000100
S28896346XBK27GA0000V8000100
S28896347ABK27GA0000V9S000100TWM   0000702400Y
S28896350X6K27GA00009D002000
S28896354X6K27GA0000AE000500
S28896354A6K27GA0000AEB000500IWM   0000736200Y
S28896355ABK27GA0000VAB000100UWM   0000542500Y
S28896355XBK27GA0000V9000100
S28896356ABK27GA0000VBS000100TWM   0000702200Y
S28896364X4K27GA0000D5002000
S28896364X6K27GA0000AE000500
S28896364A6K27GA0000AEB000500IWM   0000736600Y
S28896365XBK27GA0000VA000100
S28896365XBK27GA0000VB000100
S28896367ABK27GA0000VCS000100TWM   0000702400Y
S28896374X4K27GA0000EE000200
S28896374XAK27GA0000ZM000500
S28896374AAK27GA0000ZMS000500SPY   0001425600Y
S28896374X6K27GA0000AE000500
S28896374A6K27GA0000AEB000500IWM   0000736200Y
S28896376XAK27GA00012K001000
S28896376AAK27GA000134S001000SPY   0001425600Y
S28896376AAK27GA000135B001000SDS   0000547600Y
S28896376XAK27GA00012J001000
S28896377XBK27GA0000UV001000
S28896377ABK27GA0000VDS001000SSO   0000765200Y
S28896383A4K27GA0000GJS000200DIA   0001298800Y
S28896383AAK27GA000136B001000SPY   0001425100Y
S28896386A2K27G6000077B002000BAC   0000347800Y
S28896384X6K27GA0000AE000500
S28896384A6K27GA0000AEB000500IWM   0000736600Y
S28896394X6K27GA0000AE000500
S28896394A6K27GA0000AEB000500IWM   0000736200Y
S28896404X6K27GA0000AE000500
S28896404A6K27GA0000AEB000500IWM   0000736600Y
S28896406X7K27GA00005A002000
S28896414X6K27GA0000AE000500
S28896414A6K27GA0000AEB000500IWM   0000736200Y
S28896424X6K27GA0000AE000500
S28896424A6K27GA0000AEB000500IWM   0000736600Y
S28896434X6K27GA0000AE000500
S28896434A6K27GA0000AEB000500IWM   0000736200Y
S28896439XCK27GA000044002000
S28896444X6K27GA0000AE000500
S28896444A6K27GA0000AEB000500IWM   0000736600Y
S28896454X6K27GA0000AE000500
S28896454A6K27GA0000AEB000500IWM   0000736200Y
S28896459A2K27G6000078B002000BMY   0000050400Y
S28896459A2K27G6000079S002000BAC   0000372700Y
S28896464X6K27GA0000AE000500
S28896464A6K27GA0000AEB000500IWM   0000736600Y
S28896470A4K27GA0000GKB002000FFIV  0000265500Y
S28896474X6K27GA0000AE000500
S28896474A6K27GA0000AEB000500IWM   0000736200Y
S28896485XAK27GA0000EX000500
S28896485AAK27GA0000EXB000500SPY   0001425000Y
S28896484X6K27GA0000AE000500
S28896484A6K27GA0000AEB000500IWM   0000736600Y
S28896487X1K27GA000084002000
S28896487AAK27GA000137S000500SPY   0001425800Y
S28896488XAK27GA000131000500
S28896493X6K27GA0000AE000500
S28896493A6K27GA0000AEB000500IWM   0000736200Y
S28896496A6K27GA0000AHS002000IWM   0000737100Y
S28896507X6K27GA0000A9002000
S28896510X2K27G6000075002000
S28896519A2K27G600007AS002000BMY   0000234800Y
S28896520A4K27GA0000GLS002000FFIV  0000308200Y
S28896539ABK27GA0000VEB002000UTX   0000185100Y
S28896548A2K27G600007BB002000BRL   0000374100Y
S28896559X3K27G600009E002000
S28896572A4K27GA0000GMB002000FISV  0000500200Y
S28896578A1K27GA00008AB002000ABT   0000139500Y
S28896593A4K27GA0000GNS002000FISV  0000543500Y
S28896598X4K27GA0000GE002000
S28896612X4K27GA0000E2002000
S28896621A4K27GA0000GOB002000FITB  0000180200Y
S28896623XAK27GA0000EB001000
S28896623AAK27GA0000EBB001000SPY   0001425100Y
S28896625XAK27GA000132002500
S28896625AAK27GA000138S005000SPY   0001425900Y
S28896626XAK27GA000130005000
S28896631A3K27G600009OB002000CCE   0000192400Y
S28896637A9K27G60000QTS002000QQQQ  0000496000Y
S28896646X9K27G60000G8002000
S28896646A9K27G60000G8B002000QQQQ  0000495200Y
S28896645A4K27GA0000GPS002000FITB  0000226600Y
S28896666A2K27G600007CS002000BRL   0000424900Y
S28896677A3K27G600009PB002000CVS   0000105600Y
S28896677A6K27GA0000AIB002000INSP  0000078000Y
S28896701A5K27GA000069B002000HNZ   0000113700Y
S28896702A2K27G600007DB002000C     0000218600Y
S28896713X4K27GA0000E4000100
S28896713X4K27GA0000E5000100
S28896712A6K27GA0000AJS002000INSP  0000113700Y
S28896715A4K27GA0000GQB000100DRYS  0001073400Y
S28896715A4K27GA0000GRB000100DRYS  0001073400Y
S28896740A5K27GA00006AB002000HOT   0000117700Y
S28896741A2K27G600007ES002000C     0000238800Y
S28896757A6K27GA0000AKB002000IWN   0000666700Y
S28896767A3K27G600009QB002000COF   0000495200Y
S28896770A6K27GA0000ALB002000JCI   0000084000Y
S28896781A3K27G600009RS002000COF   0000525300Y
S28896792A7K27GA00005EB002000MET   0000590700Y
S28896791X4K27GA0000GQ000100
S28896791A4K27GA0000GQB000100DRYS  0001073500Y
S28896791X4K27GA0000GR000100
S28896791A4K27GA0000GRB000100DRYS  0001073500Y
S28896799A4K27GA0000GSB002000DNA   0000686500Y
S28896858AAK27GA000139S002500SPY   0001425900Y
S28896875XAK27GA000133001000
S28896884X8K27G600004E000500
S28896884X8K27G600004F000100
S28896964AAK27GA00013AS001000SPY   0001426000Y
S28896996XAK27GA00010N002000
S28896996X9K27G60000G1002000
S28896996A9K27G60000G1S002000QQQQ  0000495800Y
S28896996XAK27GA00010Z003000
S28896996X4K27GA0000DX000200
S28896996A4K27GA0000DXB000200DIA   0001298300Y
S28896996XAK27GA000111003000
S28896996XAK27GA0000E5001000
S28896996AAK27GA0000E5S001000SPY   0001425600Y
S28896996XAK27GA00010U003000
S28896996XAK27GA0000FD000500
S28896996AAK27GA0000FDB000500SPY   0001425000Y
S28896996XAK27GA0000O6000500
S28896996AAK27GA0000O6S000500SPY   0001425600Y
S28896996XAK27GA00010W001000
S28896996XAK27GA00010V003000
S28896996AAK27GA00013BS003000SPY   0001425700Y
S28896996AAK27GA00013CS003000SPY   0001425700Y
S28896996XAK27GA00011B001000
S28896997AAK27GA00013DS002000SPY   0001425800Y
S28896997XAK27GA0000F2000500
S28896997AAK27GA0000F2B000500SPY   0001424900Y
S28896998AAK27GA00013EB003000SPY   0001424800Y
S28896998X4K27GA0000EJ000100
S28896998X4K27GA0000EK000100
S28896998X3K27G600008R000100
S28896998AAK27GA00013FB003000SPY   0001424800Y
S28896999XAK27GA00012Y005000
S28896999XAK27GA0000F2000500
S28896999AAK27GA0000F2B000500SPY   0001425400Y
S28896999XAK27GA0000EX000500
S28896999AAK27GA0000EXB000500SPY   0001425300Y
S28896999XAK27GA00012Z002500
S28897000XAK27GA00011U000500
S28897001AAK27GA00013GB000500SPY   0001425200Y
S28897001XAK27GA0000F2000500
S28897001AAK27GA0000F2B000500SPY   0001425000Y
S28897001XAK27GA000137000500
S28897002XAK27GA0000E4001000
S28897002AAK27GA0000E4B001000SPY   0001425000Y
S28897002XAK27GA000113001000
S28897004AAK27GA00013HB001000SPY   0001425000Y
S28897010XAK27GA000116000100
S28897011XBK27GA0000UX001000
S28897011ABK27GA0000VFB001000SSO   0000764000Y
S28897011XBK27GA0000VF001000
S28897012XBK27GA0000UW001000
S28897012ABK27GA0000VGB001000SSO   0000764200Y
S28897013A6K27GA0000AMS002000IWM   0000737000Y
S28897020XAK27GA00010X001000
S28897020XBK27GA0000VG001000
S28897020ABK27GA0000VHB001000SSO   0000763900Y
S28897022ABK27GA0000VIB001000SSO   0000764100Y
S28897036X9K27G60000PK002000
S28897036A4K27GA0000GTS000047DIA   0001298700Y
S28897036X4K27GA0000GA000200
S28897044XAK27GA00010W001000
S28897044AAK27GA00013IB001000SPY   0001425200Y
S28897046AAK27GA00013JB001000SPY   0001425200Y
S28897051A8K27G600004NB000500MZZ   0000491600Y
S28897051A8K27G600004OS000100MVV   0000809300Y
S28897052X6K27GA00009G002000
S28897052A6K27GA0000ANB002000IWM   0000736000Y
S28897053X6K27GA00002A000500
S28897053A6K27GA00002AS000500IWM   0000736700Y
S28897055ABK27GA0000VJS000100UWM   0000543400Y
S28897054X6K27GA00005F000500
S28897054A6K27GA00005FB000500IWM   0000736100Y
S28897058ABK27GA0000VKB000100TWM   0000701100Y
S28897058XBK27GA0000QZ000100
S28897058ABK27GA0000VLB000100TWM   0000701000Y
S28897059AAK27GA00013KB005000SPY   0001425100Y
S28897061X4K27GA0000GC000200
S28897061A4K27GA0000GCS000200DIA   0001298600Y
S28897061X4K27GA00007C000200
S28897061A4K27GA00007CB000200DIA   0001298200Y
S28897063A4K27GA0000GUB000100DXD   0000499600Y
S28897063X4K27GA0000EN000100
S28897063X4K27GA00008X000100
S28897064X3K27G600007D000100
S28897064A3K27G600009SS000100DDM   0000802200Y
S28897064X3K27G600007M000100
S28897064XAK27GA0000E4001000
S28897064AAK27GA0000E4B001000SPY   0001425400Y
S28897064XAK27GA00013H001000
S28897064X4K27GA0000GC000200
S28897064A4K27GA0000GCS000200DIA   0001298900Y
S28897064XAK27GA0000F2000500
S28897064AAK27GA0000F2B000500SPY   0001425400Y
S28897064AAK27GA00013LB002000SPY   0001425300Y
S28897064X4K27GA00007C000200
S28897064A4K27GA00007CB000200DIA   0001298500Y
S28897064XAK27GA00013D001000
S28897064AAK27GA00013MB001000SPY   0001425400Y
S28897065X4K27GA0000GT000047
S28897066XBK27GA0000QC000100
S28897066XBK27GA0000VC000100
S28897065AAK27GA00013NS001000SDS   0000549000Y
S28897066ABK27GA0000VMB001000SSO   0000764200Y
S28897066XBK27GA0000VI001000
S28897066A4K27GA0000GVS000100DXD   0000500600Y
S28897066A3K27G600009TB000100DDM   0000800700Y
S28897066X3K27G600009S000100
S28897066A3K27G600009UB000100DDM   0000800800Y
S28897066X4K27GA0000GU000100
S28897066A4K27GA0000GWS000100DXD   0000500300Y
S28897068X8K27G600003P000100
S28897068XBK27GA0000VH001000
S28897068ABK27GA0000VNB001000SSO   0000764000Y
S28897068ABK27GA0000VOS000100TWM   0000702600Y
S28897069A8K27G600004PB000100MVV   0000806000Y
S28897069A4K27GA0000GXS000200DIA   0001299000Y
S28897071A4K27GA0000GYB000100DXD   0000499600Y
S28897072A3K27G600009VS000100DDM   0000802200Y
S28897072X4K27GA0000GY000100
S28897072X3K27G600009V000100
S28897150X9K27G60000F7003200
S28897150A9K27G60000F7B003200QQQQ  0000495200Y
S28897151A9K27G60000QUS002000QQQQ  0000495900Y
S28897226AAK27GA00013OS000500SPY   0001425700Y
S28897295AAK27GA00013PS002500SPY   0001425700Y
S28897296XAK27GA000139002500
S28897388XBK27GA0000VE002000
S28897409X3K27G600008S002000
S28897408A4K27GA0000GZS002000DNA   0000720400Y
S28897410XAK27GA00013D001000
S28897410AAK27GA00013QS001000SPY   0001425900Y
S28897412AAK27GA00013RS001000SPY   0001425900Y
S28897417XAK27GA00012O002000
S28897417X1K27GA00008A002000
S28897424X2K27G6000072002000
S28897424XAK27GA00011A001000
S28897424XAK27GA00013R001000
S28897426X3K27G600009D002000
S28897430A6K27GA0000AOS002000IMCL  0000518000Y
S28897434X2K27G600006X002000
S28897464AAK27GA00013SS001000SPY   0001425900Y
S28897467A4K27GA0000H0B002000DVN   0001208500Y
S28897468X2K27G6000076002000
S28897486X3K27G600009P002000
S28897491X4K27GA0000DV002000
S28897491A6K27GA0000APB002000ISIL  0000274200Y
S28897497XAK27GA0000O6000500
S28897497AAK27GA0000O6S000500SPY   0001426000Y
S28897497XAK27GA00013B003000
S28897497XAK27GA00013E003000
S28897497XAK27GA00013C003000
S28897497XAK27GA00013F003000
S28897497X4K27GA0000DX000200
S28897497A4K27GA0000DXB000200DIA   0001298600Y
S28897497XAK27GA0000F7000500
S28897497AAK27GA0000F7B000500SPY   0001425500Y
S28897497XAK27GA0000ZM000500
S28897497AAK27GA0000ZMS000500SPY   0001426000Y
S28897497AAK27GA00013TB002000SPY   0001425400Y
S28897497AAK27GA00013UB002000SPY   0001425300Y
S28897498AAK27GA00013VB003000SPY   0001425400Y
S28897498AAK27GA00013WB003000SPY   0001425400Y
S28897498AAK27GA00013XS003000SPY   0001426400Y
S28897498AAK27GA00013YS003000SPY   0001426400Y
S28897499AAK27GA00013ZS000100SH    0000618900Y
S28897499XAK27GA00013P002500
S28897499ABK27GA0000VPB001000SSO   0000764300Y
S28897499XBK27GA0000VM001000
S28897499A4K27GA0000H1S000100DXD   0000500200Y
S28897499A4K27GA0000H2S000100DOG   0000598400Y
S28897500A3K27G600009WB000100DDM   0000801000Y
S28897500AAK27GA000140B005000SPY   0001425200Y
S28897500XAK27GA0000FD000500
S28897500AAK27GA0000FDB000500SPY   0001425400Y
S28897501XAK27GA00013K005000
S28897502XAK27GA00013O000500
S28897502AAK27GA000141B000500SPY   0001425400Y
S28897502XAK27GA00013G000500
S28897506X5K27GA000069002000
S28897519XAK27GA00013Q001000
S28897519XAK27GA00013S001000
S28897520A4K27GA0000H3S002000DVN   0001240600Y
S28897520X5K27GA00006A002000
S28897521XAK27GA0000E5001000
S28897521AAK27GA0000E5S001000SPY   0001426000Y
S28897522XBK27GA0000VN001000
S28897522ABK27GA0000VQB001000SSO   0000764100Y
S28897527X6K27GA00008S002000
S28897531X4K27GA0000GI000100
S28897532X3K27G600009N000100
S28897532X9K27G60000F7003200
S28897532A9K27G60000F7B003200QQQQ  0000495700Y
S28897533A9K27G60000QVB002000QQQQ  0000495500Y
S28897533X6K27GA00005F000500
S28897533A6K27GA00005FB000500IWM   0000736500Y
S28897535ABK27GA0000VRB000100UWM   0000542400Y
S28897536XBK27GA0000VO000100
S28897536ABK27GA0000VSS000100TWM   0000702400Y
S28897534A6K27GA0000AQS002000ISIL  0000309800Y
S28897536X6K27GA00005F000500
S28897536A6K27GA00005FB000500IWM   0000736100Y
S28897546X6K27GA00005F000500
S28897546A6K27GA00005FB000500IWM   0000736500Y
S28897549X7K27GA000055002000
S28897558A4K27GA0000H4B002000EMR   0000555100Y
S28897557A6K27GA0000ARB002000IWM   0000736500Y
S28897559A4K27GA0000H5B002000EMR   0000554300Y
S28897572X9K27G60000QU002000
S28897576A8K27G600004QB000100MVV   0000806100Y
S28897580A6K27GA0000ASB002000JNPR  0000274000Y
S28897589A4K27GA0000H6S002000EMR   0000602400Y
S28897599A6K27GA0000ATS002000JNPR  0000305000Y
S28897600X6K27GA00002A000500
S28897600A6K27GA00002AS000500IWM   0000737100Y
S28897606XBK27GA0000VJ000100
S28897606XBK27GA0000VK000100
S28897606XBK27GA0000VL000100
S28897610A7K27GA00005FB002000LMT   0000285100Y
S28897626A5K27GA00006BB002000FNM   0000276200Y
S28897632A7K27GA00005GB002000KLAC  0000444200Y
S28897638X4K27GA0000GJ000200
S28897658A5K27GA00006CS002000FNM   0001545300Y
S28897659ACK27GA000045B002000WYE   0000109500Y
S28897677A7K27GA00005HS002000KLAC  0000479700Y
S28897685A5K27GA00006DB002000GG    0000385600Y
S28897697A1K27GA00008BB002000AFL   0000173000Y
S28897703X6K27GA0000AM002000
S28897709AAK27GA000142B002500SPY   0001425400Y
S28897709AAK27GA000143S000500SPY   0001425800Y
S28897715X8K27G600004N000500
S28897715X8K27G600004O000100
S28897714A7K27GA00005IB002000LAMR  0000381700Y
S28897722A5K27GA00006ES002000GG    0000436500Y
S28897729A2K27G600007FB002000BBT   0000084000Y
S28897750A5K27GA00006FB002000GM    0000177400Y
S28897753A3K27G600009XB002000COH   0000088400Y
S28897785A4K27GA0000H7B002000EIX   0000125700Y
S28897806A4K27GA0000H8B002000ELN   0000229200Y
S28897845X9K27G60000G1002000
S28897845A9K27G60000G1S002000QQQQ  0000496300Y
S28898068X6K27GA0000AH002000
S28898152A4K27GA0000H9S000200DIA   0001299100Y
S28898154AAK27GA000144S002500SPY   0001425900Y
S28898301XAK27GA0000EB001000
S28898301AAK27GA0000EBB001000SPY   0001425500Y
S28898306X9K27G60000G8002000
S28898306A9K27G60000G8B002000QQQQ  0000495700Y
S28898305AAK27GA000145B002000SPY   0001425500Y
S28898305XAK27GA0000NZ000500
S28898305AAK27GA0000NZS000500SPY   0001426100Y
S28898305XAK27GA000136001000
S28898306AAK27GA000146B001000SPY   0001425500Y
S28898308XAK27GA000138005000
S28898308XAK27GA000143000500
S28898308X4K27GA000062000200
S28898308A4K27GA000062B000200DIA   0001298700Y
S28898308XAK27GA0000O8000500
S28898308AAK27GA0000O8S000500SPY   0001426100Y
S28898308XAK27GA000134001000
S28898308AAK27GA000147S005000SPY   0001426000Y
S28898308AAK27GA000148S000500SPY   0001425900Y
S28898309XAK27GA0000F5000500
S28898309AAK27GA0000F5B000500SPY   0001425500Y
S28898310XAK27GA000144002500
S28898310AAK27GA000149S001000SPY   0001426000Y
S28898310AAK27GA00014AS001000SDS   0000548900Y
S28898310XBK27GA0000VP001000
S28898311ABK27GA0000VTB001000SSO   0000764400Y
S28898311A3K27G600009YB000100DDM   0000801100Y
S28898311XAK27GA000147005000
S28898311XBK27GA0000VD001000
S28898310X6K27GA0000AE000500
S28898310A6K27GA0000AEB000500IWM   0000736600Y
S28898311A6K27GA0000AUB002000IWM   0000736500Y
S28898313ABK27GA0000VUS001000SSO   0000765300Y
S28898313ABK27GA0000VVB000100UWM   0000542500Y
S28898313ABK27GA0000VWS000100TWM   0000702200Y
S28898313XBK27GA0000VS000100
S28898314X6K27GA0000AE000500
S28898314A6K27GA0000AEB000500IWM   0000736200Y
S28898316XAK27GA000148000500
S28898320XAK27GA000135001000
S28898322XAK27GA00013A001000
S28898322AAK27GA00014BS001000SPY   0001426100Y
S28898324AAK27GA00014CS001000SPY   0001426100Y
S28898326X6K27GA0000AE000500
S28898326A6K27GA0000AEB000500IWM   0000736600Y
S28898330X9K27G60000QT002000
S28898342A6K27GA0000AVB002000IWM   0000736600Y
S28898342X6K27GA0000AN002000
S28898346X4K27GA000062000200
S28898346A4K27GA000062B000200DIA   0001298400Y
S28898348X6K27GA00002B000500
S28898348A6K27GA00002BS000500IWM   0000737200Y
S28898352X3K27G600009Y000100
S28898352X4K27GA000062000200
S28898352A4K27GA000062B000200DIA   0001298700Y
S28898354A3K27G600009ZB000100DDM   0000801100Y
S28898355XBK27GA0000UY000100
S28898355XBK27GA0000UZ000100
S28898355XBK27GA0000V0000100
S28898357ABK27GA0000VXB000100TWM   0000700500Y
S28898369X4K27GA000062000200
S28898369A4K27GA000062B000200DIA   0001298400Y
S28898371A8K27G600004RS000500MZZ   0000493800Y
S28898371A8K27G600004SB000100MVV   0000806300Y
S28898382X3K27G600009Z000100
S28898389A4K27GA0000HAS000100DRYS  0001078300Y
S28898396X4K27GA000062000200
S28898396A4K27GA000062B000200DIA   0001298700Y
S28898398A3K27G60000A0B000100DDM   0000801100Y
S28898400A3K27G60000A1B002000CELG  0000487800Y
S28898401X5K27GA00006C002000
S28898411X2K27G6000078002000
S28898413XAK27GA00012V002000
S28898413X7K27GA00005F002000
S28898456XAK27GA0000F5000500
S28898456AAK27GA0000F5B000500SPY   0001425600Y
S28898457A5K27GA00006GS002000GM    0000229100Y
S28898458AAK27GA00014DB002000SHLD  0000757700Y
S28898468XCK27GA000045002000
S28898483A3K27G60000A2B002000CTSH  0000075600Y
S28898484A5K27GA00006HB002000GS    0001818600Y
S28898487XAK27GA0000FG000500
S28898487AAK27GA0000FGB000500SPY   0001425500Y
S28898500X1K27GA00008B002000
S28898507A7K27GA00005JS002000LAMR  0000439100Y
S28898521AAK27GA00014ES000500SPY   0001426000Y
S28898528A5K27GA00006IS002000GS    0001863100Y
S28898535X4K27GA0000H7002000
S28898544A7K27GA00005KB002000LLTC  0000354600Y
S28898556X6K27GA0000AL002000
S28898581A6K27GA0000AWB002000IBM   0001246600Y
S28898591X7K27GA00003U002000
S28898596ABK27GA0000VYB002000UTX   0000189100Y
S28898620A1K27GA00008CB002000ABT   0000142600Y
S28898619A6K27GA0000AXS002000IBM   0001274700Y
S28898628A7K27GA00005LS002000LLTC  0000389200Y
S28898646A2K27G600007GB002000AXP   0000412700Y
S28898657A7K27GA00005MB002000LNCR  0000236100Y
S28898657A6K27GA0000AYB002000JNJ   0000641900Y
S28898660AAK27GA00014FS002500SPY   0001426000Y
S28898682A2K27G600007HB002000BDX   0000770200Y
S28898693A7K27GA00005NS002000LNCR  0000280900Y
S28898698A6K27GA0000AZS002000JNJ   0000690800Y
S28898717A2K27G600007IB002000CAG   0000055400Y
S28898739A7K27GA00005OB002000LPNT  0000204900Y
S28898743A7K27GA00005PB002000KSS   0000456700Y
S28898756A3K27G60000A3B002000CVS   0000108000Y
S28898769AAK27GA00014GB005000SPY   0001425400Y
S28898769XAK27GA000140005000
S28898771A7K27GA00005QS002000KSS   0000506400Y
S28898772A4K27GA0000HBB002000DIS   0000330300Y
S28898778A9K27G60000QWS002000QQQQ  0000496000Y
S28898785X1K27GA00000V000100
S28898785A1K27GA00000VB000100AAPL  0001829900Y
S28898788A7K27GA00005RB002000LMT   0000287300Y
S28898792A5K27GA00006JB002000HNZ   0000116300Y
S28898803A5K27GA00006KB002000HOT   0000120400Y
S28898804X1K27GA00000V000100
S28898804A1K27GA00000VB000100AAPL  0001830000Y
S28898821A6K27GA0000B0B002000KEY   0000212700Y
S28898834A7K27GA00005SB002000MDY   0001580900Y
S28898854X5K27GA00001A000100
S28898856X5K27GA00000Z000100
S28898856A5K27GA00006LB000100FXP   0000653600Y
S28898862X5K27GA00006L000100
S28898862A5K27GA00006MB000100FXP   0000654000Y
S28898862X5K27GA00006M000100
S28898864A5K27GA00006NB000100FXP   0000653600Y
S28899161X7K27GA00005S002000
S28899160X6K27GA0000B0002000
S28899163X5K27GA00006K002000
S28899163X5K27GA00006J002000
S28899163X4K27GA0000HB002000
S28899164X3K27G60000A3002000
S28899164X2K27G600007I002000
S28899164X2K27G600007H002000
S28899164X2K27G600007G002000
S28899164X1K27GA00008C002000
S28899165X4K27GA0000H8002000
S28899166X3K27G600009X002000
S28899165XBK27GA0000VY002000
S28899166X2K27G600007F002000
S28899166X4K27GA0000H4002000
S28899167X7K27GA00005E002000
S28899166X6K27GA0000AK002000
S28899168X3K27G600009O002000
S28899168X7K27GA00005D002000
S28899168X7K27GA00005C002000
S28899169X7K27GA00005B002000
S28899170X5K27GA000068002000
S28899170X3K27G600009H002000
S28899169XCK27GA000043002000
S28899171X7K27GA000059002000
S28899171X7K27GA000058002000
S28899171X1K27GA00007W002000
S28899172X3K27G600008X002000
S28899173X4K27GA0000G3002000
S28899173X5K27GA000063002000
S28899172X6K27GA0000A2002000
S28899174X5K27GA000060002000
S28899174X7K27GA000053002000
S28899174X4K27GA0000G1002000
S28899173X6K27GA00009P002000
S28899175X4K27GA0000FW002000
S28899175X6K27GA00009N002000
S28899177X4K27GA0000FK002000
S28899178X4K27GA0000FH002000
S28899179X2K27G600006I002000
S28899179X2K27G600006F002000
S28899179XBK27GA0000RR002000
S28899180X3K27G6000087002000
S28899180X2K27G6000068002000
S28899181X2K27G6000064002000
S28899180X4K27GA0000FB002000
S28899181X2K27G6000062002000
S28899181X5K27GA00005D002000
S28899180X4K27GA0000F3002000
S28899181X1K27GA00006Q002000
S28899181X4K27GA0000EY002000
S28899181X4K27GA0000EW002000
S28899182X7K27GA00004G002000
S28899182X6K27GA00008R002000
S28899183X7K27GA00004A002000
S28899183X1K27GA00006C002000
S28899183X7K27GA000043002000
S28899184X5K27GA00004W002000
S28899184X3K27G600006V002000
S28899184X7K27GA00003T002000
S28899187X7K27GA00003R002000
S28899187X7K27GA00003N002000
S28899187X7K27GA00003I002000
S28899188X1K27GA00005I002000
S28899188X7K27GA000034002000
S28899189X5K27GA00003X002000
S28899188X6K27GA00006E002000
S28899189X7K27GA00002W002000
S28899189X1K27GA00004P002000
S28899189X6K27GA000062002000
S28899189X6K27GA00005O002000
S28899189X6K27GA00005M002000
S28899189X6K27GA00005L002000
S28899190X6K27GA00005I002000
S28899192X5K27GA00002I002000
S28899192X5K27GA00002C002000
S28899192X5K27GA00002A002000
S28899195X5K27GA000025002000
S28899195X5K27GA000024002000
S28899196X5K27GA000023002000
S28899196X5K27GA000022002000
S28899196X5K27GA000020002000
S28899197X5K27GA00001V002000
S28899197X5K27GA00001S002000
S28899197X5K27GA00001M002000
S28899197X4K27GA000075002000
S28899197X4K27GA000072002000
S28899202X4K27GA00006J002000
S28899203X4K27GA00006H002000
S28899203X4K27GA000068002000
S28899204X4K27GA000060002000
S28899204X4K27GA00005Z002000
S28899205X4K27GA00005W002000
S28899205X4K27GA00005H002000
S28899206X3K27G600001W002000
S28899206X3K27G600001N002000
S28899207X3K27G600001L002000
S28899207X3K27G600001K002000
S28899207X3K27G600001E002000
S28899207X3K27G600001A002000
S28899207X3K27G6000018002000
S28899208X3K27G6000017002000
S28899208X3K27G6000016002000
S28899209X3K27G6000015002000
S28899210X2K27G600001F002000
S28899210X2K27G600001E002000
S28899210X2K27G600001B002000
S28899211X2K27G6000019002000
S28899212X2K27G6000017002000
S28899212X2K27G6000015002000
S28899213X2K27G600000Z002000
S28899213X2K27G600000Y002000
S28899214X2K27G600000W002000
S28899220X2K27G600000V002000
S28899220X2K27G600000N002000
S28899219X1K27GA000025002000
S28899219X1K27GA000021002000
S28899220X1K27GA00001Z002000
S28899220X1K27GA00001V002000
S28899220X1K27GA00001T002000
S28899220X1K27GA00001R002000
S28899219XCK27GA00001F002000
S28899219XCK27GA00001E002000
S28899221XBK27GA00001B002000
S28899221XBK27GA00001A002000
S28899222X8K27G600000B002000
S28899222X8K27G600000A002000
S28899222X7K27GA00000V002000
S28899222X7K27GA00000S002000
S28899222X6K27GA00002L002000
S28899225X5K27GA000016002000
S28899225X4K27GA000045002000
S28899226X3K27G600000J002000
S28899227X2K27G600000K002000
S28899228X2K27G600000J002000
S28899228X1K27GA00001H002000
S28899228X1K27GA00001F002000
S28899228X1K27GA00001D002000
S28899228X1K27GA00001C002000
S28899228X1K27GA00001B002000
S28899239AAK27GA00014HS005000SPY   0001426200Y
S28899464AAK27GA00014IB002000SPLS  0000053000Y
S28899464X7K27GA00005R002000
S28899532A5K27GA00006OS002000FNM   0001535800Y
S28899566A7K27GA00005TS002000LPNT  0000463200Y
S28899606A7K27GA00005UB002000LRCX  0000392200Y
S28899610A7K27GA00005VS002000LMT   0001128800Y
S28899628A7K27GA00005WS002000LRCX  0000428300Y
S28899637A7K27GA00005XB002000MDT   0000478800Y
S28899646A7K27GA00005YB002000MNST  0000248500Y
S28899657A7K27GA00005ZS002000MDT   0000507800Y
S28899667A7K27GA000060S002000MNST  0000292300Y
S28899676A7K27GA000061B002000MMM   0000764100Y
S28899704A8K27G600004TB002000NPSP  0000030200Y
S28899716A7K27GA000062S002000MMM   0000816500Y
S28899728A8K27G600004US002000NPSP  0000051800Y
S28899741A7K27GA000063B002000MO    0000211600Y
S28899761A7K27GA000064S002000MO    0000239300Y
S28899773A8K27G600004VB002000NBR   0000402800Y
S28899785A8K27G600004WS002000NBR   0000429200Y
S28899872XAK27GA0000FG000500
S28899872AAK27GA0000FGB000500SPY   0001425100Y
S28899872XAK27GA0000O8000500
S28899872AAK27GA0000O8S000500SPY   0001425700Y
S28899916XAK27GA0000F5000500
S28899916AAK27GA0000F5B000500SPY   0001425200Y
S28899919XAK27GA0000F5000500
S28899919AAK27GA0000F5B000500SPY   0001425600Y
S28899920XAK27GA00014A001000
S28899920XBK27GA0000VT001000
S28899921AAK27GA00014JS001000SDS   0000548900Y
S28899922ABK27GA0000VZB001000SSO   0000764400Y
S28899929XAK27GA0000F5000500
S28899929AAK27GA0000F5B000500SPY   0001425200Y
S28899939XAK27GA0000F5000500
S28899939AAK27GA0000F5B000500SPY   0001425600Y
S28899940XAK27GA00014J001000
S28899940XBK27GA0000VZ001000
S28899941AAK27GA00014KS001000SDS   0000548900Y
S28899942ABK27GA0000W0B001000SSO   0000764400Y
S28899943XAK27GA0000F5000500
S28899943AAK27GA0000F5B000500SPY   0001425200Y
S28899945XAK27GA00014K001000
S28899945XBK27GA0000W0001000
S28899947ABK27GA0000W1B001000SSO   0000764300Y
S28899950XAK27GA0000F5000500
S28899950AAK27GA0000F5B000500SPY   0001425600Y
S28899951AAK27GA00014LS001000SDS   0000548900Y
S28899951XBK27GA0000W1001000
S28899952ABK27GA0000W2B001000SSO   0000764400Y
S28899959XAK27GA0000F5000500
S28899959AAK27GA0000F5B000500SPY   0001425200Y
S28899969XAK27GA00014L001000
S28899970XBK27GA0000W2001000
S28899972ABK27GA0000W3B001000SSO   0000764300Y
S28899996XAK27GA0000F5000500
S28899996AAK27GA0000F5B000500SPY   0001425600Y
S28899997AAK27GA00014MS001000SDS   0000548900Y
S28899998ABK27GA0000W4B001000SSO   0000764400Y
S28899998XBK27GA0000W3001000
S28899999XAK27GA0000F5000500
S28899999AAK27GA0000F5B000500SPY   0001425200Y
S28900010XAK27GA00014M001000
S28900010XBK27GA0000W4001000
S28900012ABK27GA0000W5B001000SSO   0000764300Y
S28900382X5K27GA00006O002000
S28900385A7K27GA000065B002000LMT   0000293300Y
S28900390A8K27G600004XB002000NTAP  0000246500Y
S28900405A8K27G600004YB002000NEM   0000472800Y
S28900422A8K27G600004ZS002000NEM   0000504800Y
S28900422A8K27G6000050S002000NTAP  0000278000Y
S28900435ABK27GA0000W6B002000TGT   0000520000Y
S28900436A8K27G6000051B002000NTRS  0000653200Y
S28900452A8K27G6000052S002000NTRS  0000783000Y
S28900454ABK27GA0000W7S002000TGT   0000627800Y
S28900468A8K27G6000053B002000NVTL  0000079900Y
S28900469ABK27GA0000W8B002000TXN   0000308400Y
S28900490ABK27GA0000W9S002000TXN   0000334300Y
S28900491A8K27G6000054S002000NVTL  0000117200Y
S28900507ABK27GA0000WAB002000TYC   0000439100Y
S28900509A8K27G6000055B002000OSIP  0000340300Y
S28900531ABK27GA0000WBS002000TYC   0000495800Y
S28900540ABK27GA0000WCB002000UTX   0000192300Y
S28900586XAK27GA0000O8000500
S28900586AAK27GA0000O8S000500SPY   0001426100Y
S28900589XAK27GA0000F5000500
S28900589AAK27GA0000F5B000500SPY   0001425600Y
S28900591AAK27GA00014NS001000SDS   0000548900Y
S28900591XBK27GA0000W5001000
S28900591ABK27GA0000WDB001000SSO   0000764400Y
S28900859A4K27GA0000HCS000100DRYS  0001078300Y
S28901244XAK27GA0000O8000500
S28901244AAK27GA0000O8S000500SPY   0001425700Y
S28901244XAK27GA0000F5000500
S28901244AAK27GA0000F5B000500SPY   0001425200Y
S28901246XAK27GA000145002000
S28901247AAK27GA00014OS000500SPY   0001425900Y
S28901247XAK27GA00014E000500
S28901247AAK27GA00014PS002500SPY   0001425900Y
S28901247XAK27GA00014F002500
S28901247XAK27GA00014G005000
S28901247AAK27GA00014QB005000SPY   0001425200Y
S28901248XAK27GA00014H005000
S28901250XAK27GA00014N001000
S28901250AAK27GA00014RS000500SPY   0001426000Y
S28901250XBK27GA0000WD001000
S28901252ABK27GA0000WEB001000SSO   0000764300Y
S28901256AAK27GA00014SB000500SPY   0001425400Y
S28901258X6K27GA00002B000500
S28901258A6K27GA00002BS000500IWM   0000736800Y
S28901261ABK27GA0000WFS000100UWM   0000543500Y
S28901261ABK27GA0000WGB000100TWM   0000700800Y
S28901261ABK27GA0000WHB000100TWM   0000700900Y
S28901261X6K27GA0000AV002000
S28901266AAK27GA00014TB000500SPY   0001424900Y
S28901269AAK27GA00014UB000500SPY   0001425100Y
S28901361AAK27GA00014VB000500SPY   0001424600Y
S28901362AAK27GA00014WB000500SPY   0001424400Y
S28901373A5K27GA00006PS002000FNM   0001526300Y
S28901376X3K27G60000A2002000
S28901380X7K27GA000065002000
S28901381A8K27G6000056S002000OSIP  0000367000Y
S28901388XBK27GA0000WC002000
S28901402ABK27GA0000WIS002000UTX   0001657100Y
S28901405A8K27G6000057B002000OVTI  0000149700Y
S28901434A8K27G6000058B002000PAYX  0000342700Y
S28901433ACK27GA000046B002000VZ    0000373800Y
S28901454ACK27GA000047S002000VZ    0000407200Y
S28901458A8K27G6000059S002000PAYX  0000389000Y
S28901486A9K27G60000QXB002000PCAR  0000471200Y
S28901488ACK27GA000048B002000WLP   0000500500Y
S28901507A9K27G60000QYS002000PCAR  0000532900Y
S28901512ACK27GA000049S002000WLP   0000527800Y
S28901530A9K27G60000QZB002000PDLI  0000028800Y
S28901534ACK27GA00004AB002000WMT   0000539500Y
S28901553A9K27G60000R0S002000PDLI  0000106900Y
S28901554ACK27GA00004BS002000WMT   0000582000Y
S28901588ACK27GA00004CB002000WYE   0000113500Y
S28901598ACK27GA00004DS002000WYE   0000473900Y
S28901670AAK27GA00014XS005000SPY   0001426000Y
S28901709X4K27GA000062000200
S28901709A4K27GA000062B000200DIA   0001298400Y
S28901711X3K27G60000A0000100
S28901718X9K27G60000G8002000
S28901718A9K27G60000G8B002000QQQQ  0000495200Y
S28901718X6K27GA0000AE000500
S28901718A6K27GA0000AEB000500IWM   0000736200Y
S28901723AAK27GA00014YS000500SPY   0001426700Y
S28901724AAK27GA00014ZS000500SPY   0001427000Y
S28901724X6K27GA0000AE000500
S28901724A6K27GA0000AEB000500IWM   0000736600Y
S28901725XBK27GA0000VV000100
S28901726XBK27GA0000VW000100
S28901725AAK27GA000150S001000SPY   0001426000Y
S28901727X8K27G600004R000500
S28901727X8K27G600004S000100
S28901727ABK27GA0000WJB000100UWM   0000542500Y
S28901727ABK27GA0000WKS000100TWM   0000702200Y
S28901729A8K27G600005AS000500MZZ   0000493900Y
S28901729A8K27G600005BB000100MVV   0000806200Y
S28901728AAK27GA000151S000500SPY   0001426500Y
S28901733X6K27GA0000AE000500
S28901733A6K27GA0000AEB000500IWM   0000736200Y
S28901740AAK27GA000152S000500SPY   0001426200Y
S28901754X6K27GA0000AE000500
S28901754A6K27GA0000AEB000500IWM   0000736600Y
S28901755XBK27GA0000WJ000100
S28901755XBK27GA0000WK000100
S28901757ABK27GA0000WLB000100UWM   0000542500Y
S28901755A6K27GA0000B1B000100IWM   0000736100Y
S28901757ABK27GA0000WMS000100TWM   0000702200Y
S28901756X6K27GA0000B1000100
S28901763X6K27GA0000AE000500
S28901763A6K27GA0000AEB000500IWM   0000736200Y
S28901774X6K27GA0000AE000500
S28901774A6K27GA0000AEB000500IWM   0000736600Y
S28901775XBK27GA0000WL000100
S28901775XBK27GA0000WM000100
S28901777ABK27GA0000WNB000100UWM   0000542500Y
S28901777ABK27GA0000WOS000100TWM   0000702200Y
S28901784X6K27GA0000AE000500
S28901784A6K27GA0000AEB000500IWM   0000736200Y
S28901791A4K27GA0000HDB000100DOG   0000597100Y
S28901792A3K27G60000A4S000100DDM   0000802400Y
S28901792X4K27GA0000H9000200
S28901794X6K27GA0000AE000500
S28901794A6K27GA0000AEB000500IWM   0000736600Y
S28901795XBK27GA0000WN000100
S28901795XBK27GA0000WO000100
S28901795A6K27GA0000B2B000100IWM   0000736100Y
S28901797ABK27GA0000WPB000100UWM   0000542500Y
S28901796X6K27GA0000B2000100
S28901797ABK27GA0000WQS000100TWM   0000702200Y
S28901803X6K27GA0000AE000500
S28901803A6K27GA0000AEB000500IWM   0000736200Y
S28901814X6K27GA0000AE000500
S28901814A6K27GA0000AEB000500IWM   0000736600Y
S28901815XBK27GA0000WP000100
S28901815XBK27GA0000WQ000100
S28901816A4K27GA0000HES000200DIA   0001298800Y
S28901817ABK27GA0000WRB000100UWM   0000542500Y
S28901817ABK27GA0000WSS000100TWM   0000702200Y
S28901823X6K27GA0000AE000500
S28901823A6K27GA0000AEB000500IWM   0000736200Y
S28901834X6K27GA0000AE000500
S28901834A6K27GA0000AEB000500IWM   0000736600Y
S28901835XBK27GA0000WR000100
S28901835XBK27GA0000WS000100
S28901836A6K27GA0000B3B000100IWM   0000736100Y
S28901837ABK27GA0000WTS000100TWM   0000702200Y
S28901837ABK27GA0000WUB000100UWM   0000542500Y
S28901836X6K27GA0000B3000100
S28901839AAK27GA000153S000500SPY   0001425800Y
S28901840XAK27GA00014O000500
S28901843X6K27GA0000AE000500
S28901843A6K27GA0000AEB000500IWM   0000736200Y
S28901846X6K27GA0000AE000500
S28901846A6K27GA0000AEB000500IWM   0000736600Y
S28901853X6K27GA0000AE000500
S28901853A6K27GA0000AEB000500IWM   0000736200Y
S28901859X6K27GA0000AE000500
S28901859A6K27GA0000AEB000500IWM   0000736600Y
S28901863X6K27GA0000AE000500
S28901863A6K27GA0000AEB000500IWM   0000736200Y
S28901869X6K27GA0000AE000500
S28901869A6K27GA0000AEB000500IWM   0000736600Y
S28901873X6K27GA0000AE000500
S28901873A6K27GA0000AEB000500IWM   0000736200Y
S28901875XBK27GA0000WU000100
S28901875XBK27GA0000WT000100
S28901875A6K27GA0000B4B000100IWM   0000736100Y
S28901875X6K27GA0000B4000100
S28901877ABK27GA0000WVS000100TWM   0000702400Y
S28901948XAK27GA000149001000
S28901948XAK27GA0000NZ000500
S28901948AAK27GA0000NZS000500SPY   0001425700Y
S28901949AAK27GA000154S001000SPY   0001425600Y
S28901949XAK27GA000146001000
S28901950AAK27GA000155B001000SDS   0000547600Y
S28901951ABK27GA0000WWS001000SSO   0000765200Y
S28901951XBK27GA0000VU001000
S28901960A6K27GA0000B5S002000IWM   0000737100Y
S28901970X6K27GA0000AU002000
S28902005X4K27GA0000GQ000100
S28902005A4K27GA0000HFB000100DRYS  0001068100Y
S28902024AAK27GA000156B001000SPY   0001425100Y
S28902024X4K27GA0000HF000100
S28902035A4K27GA0000HGB000100DRYS  0001068100Y
S28902054X4K27GA0000HG000100
S28902064A4K27GA0000HHB000100DRYS  0001075100Y
S28902078AAK27GA000157S005000SPY   0001425900Y
S28902080XAK27GA00014X005000
S28902169X8K27G600005A000500
S28902169X8K27G600005B000100
S28902186XAK27GA00014S000500
S28902188XAK27GA00014W000500
S28902188XAK27GA00014V000500
S28902188XAK27GA00014U000500
S28902188XAK27GA00014T000500
S28902202XAK27GA00014R000500
S28902202XAK27GA000152000500
S28902202XAK27GA000151000500
S28902202XAK27GA00014Z000500
S28902202XAK27GA00014Y000500
S28902348XAK27GA00014D002000
S28902367A3K27G60000A5B002000CTSH  0000079000Y
S28902367X5K27GA00006P002000
S28902395A9K27G60000R1B002000PETM  0000208100Y
S28902396XBK27GA0000WI002000
S28902406XCK27GA00004C002000
S28902419A9K27G60000R2S002000PETM  0000263200Y
S28902425A7K27GA000066B002000LMT   0000299300Y
S28902437A9K27G60000R3B002000PLCM  0000229800Y
S28902440ABK27GA0000WXB002000UTX   0000196300Y
S28902441X4K27GA0000HH000100
S28902444A1K27GA00008DB002000A     0000345300Y
S28902446P4K27GA0000HHB000100DRYS  0001075100000N4AQ00009
S28902458A9K27G60000R4S002000PLCM  0000273800Y
S28902465X4K27GA0000GR000100
S28902465A4K27GA0000HIB000100DRYS  0001070100Y
S28902465A1K27GA00008ES002000A     0000372200Y
S28902477A9K27G60000R5B002000PSUN  0000087100Y
S28902486A1K27GA00008FB002000ABT   0000147800Y
S28902498A9K27G60000R6S002000PSUN  0000124900Y
S28902515A1K27GA00008GS002000ABT   0000568000Y
S28902522AAK27GA000158B002000SBUX  0000158700Y
S28902539A1K27GA00008HB002000ABX   0000393000Y
S28902556A1K27GA00008IS002000ABX   0000426500Y
S28902644A1K27GA00008JB002000ACE   0000586400Y
S28902654A1K27GA00008KS002000ACE   0000641400Y
S28902663A1K27GA00008LB002000ACF   0000119500Y
S28902782X3K27G60000A4000100
S28902781X4K27GA0000HD000100
S28903082X4K27GA0000HE000200
S28903086A4K27GA0000HJS000200DIA   0001299100Y
S28903086XAK27GA0000NZ000500
S28903086AAK27GA0000NZS000500SPY   0001426100Y
S28903086AAK27GA000159B002000SPY   0001425500Y
S28903086XAK27GA0000O8000500
S28903086AAK27GA0000O8S000500SPY   0001426100Y
S28903086XAK27GA0000FG000500
S28903086AAK27GA0000FGB000500SPY   0001425500Y
S28903086XAK27GA000154001000
S28903086XAK27GA000156001000
S28903087X4K27GA000062000200
S28903087A4K27GA000062B000200DIA   0001298700Y
S28903087AAK27GA00015AB001000SPY   0001425500Y
S28903087XAK27GA0000F5000500
S28903087AAK27GA0000F5B000500SPY   0001425500Y
S28903088AAK27GA00015BS001000SPY   0001426000Y
S28903088AAK27GA00015CS001000SDS   0000548900Y
S28903089XBK27GA0000WE001000
S28903089ABK27GA0000WYB001000SSO   0000764400Y
S28903089XBK27GA0000WW001000
S28903089XAK27GA00014P002500
S28903089XAK27GA000157005000
S28903089A3K27G60000A6B000100DDM   0000801100Y
S28903089AAK27GA00015DS002500SPY   0001426000Y
S28903089AAK27GA00015ES005000SPY   0001426200Y
S28903090XAK27GA000155001000
S28903090XAK27GA000153000500
S28903091ABK27GA0000WZS001000SSO   0000765300Y
S28903091AAK27GA00015FS000500SPY   0001426000Y
S28903100X6K27GA0000B5002000
S28903104XAK27GA000150001000
S28903110X6K27GA0000AE000500
S28903111A6K27GA0000B6B000500IWM   0000736600Y
S28903111A6K27GA0000B7B002000IWM   0000736500Y
S28903113ABK27GA0000X0B000100UWM   0000542500Y
S28903113XBK27GA0000WV000100
S28903113ABK27GA0000X1S000100TWM   0000702200Y
S28903114X6K27GA0000B6000500
S28903114A6K27GA0000B6B000500IWM   0000736200Y
S28903119X9K27G60000G8002000
S28903119A9K27G60000G8B002000QQQQ  0000495700Y
S28903119X4K27GA0000GC000200
S28903118X6K27GA0000B6000500
S28903118A6K27GA0000B6B000500IWM   0000736600Y
S28903121A4K27GA0000HKS000200DIA   0001299200Y
S28903146X4K27GA0000HK000200
S28903146X4K27GA000062000200
S28903146A4K27GA000062B000200DIA   0001298400Y
S28903151A4K27GA0000HLS000200DIA   0001298800Y
S28903151X4K27GA0000HJ000200
S28903152X3K27G60000A6000100
S28903152X4K27GA000062000200
S28903152A4K27GA000062B000200DIA   0001298700Y
S28903154A3K27G60000A7B000100DDM   0000801100Y
S28903161X4K27GA0000HL000200
S28903161A4K27GA0000HLS000200DIA   0001298900Y
S28903163XAK27GA0000F5000500
S28903163AAK27GA0000F5B000500SPY   0001425600Y
S28903171A4K27GA0000HMS000200DIA   0001299100Y
S28903172X4K27GA000062000200
S28903172A4K27GA000062B000200DIA   0001298400Y
S28903175X4K27GA0000HM000200
S28903175A4K27GA0000HNS000047DIA   0001298800Y
S28903176X4K27GA000062000200
S28903176A4K27GA000062B000200DIA   0001298700Y
S28903181X4K27GA0000HN000047
S28903188A4K27GA0000HOS000200DIA   0001299100Y
S28903311A8K27G600005CS000500MZZ   0000493900Y
S28903311A8K27G600005DB000100MVV   0000806200Y
S28903371X7K27GA000066002000
S28903379XBK27GA0000WX002000
S28903383X1K27GA00007X002000
S28903386A5K27GA00006QS002000FNM   0001516800Y
S28903389X6K27GA00009C002000
S28903401XAK27GA00014I002000
S28903411X1K27GA00008F002000
S28903426X1K27GA00007R002000
S28903429AAK27GA00015GB002000SHLD  0000760600Y
S28903430ABK27GA0000X2S002000UTX   0001650100Y
S28903444AAK27GA00015HS002000SBUX  0000181300Y
S28903461ACK27GA00004EB002000WYE   0000115900Y
S28903464AAK27GA00015IB002000SEPR  0000177600Y
S28903481A1K27GA00008MB002000ACN   0000356600Y
S28903487AAK27GA00015JS002000SEPR  0000231000Y
S28903502A1K27GA00008NS002000ACN   0000409200Y
S28903514AAK27GA00015KB002000SHPGY 0000516500Y
S28903530A1K27GA00008OB002000AFL   0000183300Y
S28903543AAK27GA00015LS002000SHPGY 0000537800Y
S28903557A1K27GA00008PS002000AFL   0001640700Y
S28903583A1K27GA00008QB002000ALL   0000483400Y
S28903584A1K27GA00008RS002000ALL   0000526000Y
S28903591AAK27GA00015MB002000SLAB  0000352200Y
S28903595A1K27GA00008SB002000ANF   0000722000Y
S28903612AAK27GA00015NS002000SLAB  0000387900Y
S28903802XAK27GA00014Q005000
S28904359X3K27G60000A1002000
S28904360X5K27GA00006Q002000
S28904368A1K27GA00008TS002000AMGN  0000484900Y
S28904395XBK27GA0000W7002000
S28904405A6K27GA0000B8B002000IMCL  0000347600Y
S28904406A7K27GA000067B002000LMT   0000305300Y
S28904411XBK27GA0000X2002000
S28904421XCK27GA00004E002000
S28904432AAK27GA00015OB002000SPLS  0000056200Y
S28904433ABK27GA0000X3B002000UTX   0000200300Y
S28904450A1K27GA00008US002000APOL  0000534200Y
S28904453X1K27GA00008O002000
S28904457X1K27GA00008P002000
S28904472AAK27GA00015PB002000SNDK  0000236100Y
S28904480A1K27GA00008VB002000ABT   0000150900Y
S28904490A1K27GA00008WS002000ANF   0000773400Y
S28904505AAK27GA00015QS002000SNDK  0000313000Y
S28904511A1K27GA00008XB002000ANN   0000258600Y
S28904512A8K27G600005ES000500MZZ   0000493800Y
S28904512A8K27G600005FB000100MVV   0000806300Y
S28904533A1K27GA00008YS002000ANN   0000303500Y
S28904535ABK27GA0000X4B002000TASR  0000064100Y
S28904552ABK27GA0000X5B002000TECD  0000349200Y
S28904554A1K27GA00008ZB002000AOC   0000442300Y
S28904575ABK27GA0000X6S002000TECD  0000384500Y
S28904638A1K27GA000090S002000AOC   0000499700Y
S28904647A1K27GA000091B002000APC   0000764300Y
S28904656A1K27GA000092S002000APC   0000793700Y
S28904665A1K27GA000093B002000ARO   0000297600Y
S28904850E5K27GA00006N00010000005AQ00004
S28904852A5K27GA00006SB000100FXP   0000652300Y
S28905368X7K27GA000067002000
S28905368X3K27G60000A5002000
S28905382XBK27GA0000X3002000
S28905384A3K27G60000A8B002000CELG  0000490300Y
S28905389X1K27GA00008V002000
S28905399A5K27GA00006TS002000FNM   0001507300Y
S28905409ABK27GA0000X7B002000TEVA  0000448200Y
S28905415ABK27GA0000X8S002000TGT   0000626400Y
S28905427ABK27GA0000X9S002000TEVA  0000487600Y
S28905434ABK27GA0000XAS002000UTX   0001643200Y
S28905444ACK27GA00004FB002000WYE   0000118300Y
S28905456ABK27GA0000XBB002000THQI  0000175300Y
S28905462A1K27GA000094B002000AFL   0000187000Y
S28905469A1K27GA000095S002000AFL   0001633600Y
S28905472ABK27GA0000XCS002000THQI  0000210800Y
S28905491ABK27GA0000XDB002000UNTD  0000098500Y
S28905496A1K27GA000096S002000ARO   0000369800Y
S28905529ABK27GA0000XES002000UNTD  0000140400Y
S28905531A2K27G600007JB002000AVP   0000358000Y
S28905548ABK27GA0000XFB002000URBN  0000290200Y
S28905553A2K27G600007KS002000AVP   0000415200Y
S28905570A2K27G600007LB002000AXP   0000413400Y
S28905579A2K27G600007MS002000AXP   0000500800Y
S28906356A3K27G60000A9B002000CTSH  0000082500Y
S28906364X5K27GA00006T002000
S28906379XBK27GA0000XA002000
S28906381A1K27GA000097B002000AA    0000432300Y
S28906397XCK27GA00004F002000
S28906402ABK27GA0000XGS002000URBN  0000314800Y
S28906402X1K27GA000094002000
S28906408X1K27GA000095002000
S28906437A7K27GA000068B002000LMT   0000311300Y
S28906439A1K27GA000098S002000AA    0000461200Y
S28906447ABK27GA0000XHB002000UTSI  0000035700Y
S28906488ABK27GA0000XIB002000UTX   0000204300Y
S28906486ACK27GA00004GB002000VECO  0000169200Y
S28906496A1K27GA000099B002000ADI   0000340700Y
S28906510X4K27GA0000HL000200
S28906515A4K27GA0000HPS000200DIA   0001298900Y
S28906521X4K27GA0000GB000100
S28906522X3K27G600009I000100
S28906521ACK27GA00004HS002000VECO  0000204900Y
S28906527X4K27GA0000HP000200
S28906531A4K27GA0000HQS000200DIA   0001299200Y
S28906534A1K27GA00009AB002000ABT   0000154000Y
S28906542X4K27GA0000HQ000200
S28906542X4K27GA000062000200
S28906542A4K27GA000062B000200DIA   0001298400Y
S28906543A1K27GA00009BS002000ADI   0000366000Y
S28906551A4K27GA0000HRS000200DIA   0001298900Y
S28906552X3K27G60000A7000100
S28906562A3K27G60000AAB000100DDM   0000801100Y
S28906561ACK27GA00004IB002000VRSN  0000381200Y
S28906570X4K27GA0000HO000200
S28906571A4K27GA0000HSS000047DIA   0001298800Y
S28906571X3K27G60000AA000100
S28906572A3K27G60000ABS000100DDM   0000802500Y
S28906572A4K27GA0000HTB000100DXD   0000499500Y
S28906577X4K27GA0000HS000047
S28906578X4K27GA0000HT000100
S28906578X3K27G60000AB000100
S28906581A4K27GA0000HUS000200DIA   0001299100Y
S28906582A3K27G60000ACB000100DDM   0000801100Y
S28906581X4K27GA0000HR000200
S28906583A1K27GA00009CB002000ADP   0000420200Y
S28906585A1K27GA00009DS002000ADP   0000445800Y
S28906591A4K27GA0000HVS000200DIA   0001299200Y
S28906594A2K27G600007NB002000AZN   0000420200Y
S28906612X4K27GA0000HV000200
S28906614A4K27GA0000HWS000200DIA   0001298900Y
S28906615A1K27GA00009EB002000AIG   0000373400Y
S28906622X3K27G60000AC000100
S28906627A2K27G600007OS002000AZN   0000475600Y
S28906631A4K27GA0000HXB000100DXD   0000499500Y
S28906632A3K27G60000ADS000100DDM   0000802500Y
S28906632A3K27G60000AEB000100DDM   0000801100Y
S28906631ACK27GA00004JS002000VRSN  0000417400Y
S28906638X4K27GA0000HU000200
S28906640A4K27GA0000HYS000200DIA   0001298800Y
S28906641X4K27GA0000HX000100
S28906642X3K27G60000AD000100
S28906642X3K27G60000AE000100
S28906642X4K27GA0000HY000200
S28906643A4K27GA0000HZB000100DXD   0000499500Y
S28906643A3K27G60000AFS000100DDM   0000802500Y
S28906645A1K27GA00009FS002000AIG   0000399300Y
S28906647A4K27GA0000I0S000200DIA   0001299100Y
S28906651X4K27GA0000HZ000100
S28906651X3K27G60000AF000100
S28906651X4K27GA0000HW000200
S28906652A3K27G60000AGB000100DDM   0000801100Y
S28906654A4K27GA0000I1S000200DIA   0001299200Y
S28906660A2K27G600007PB002000BA    0000853900Y
S28906671A4K27GA0000I2B000100DXD   0000499500Y
S28906671A3K27G60000AHS000100DDM   0000802500Y
S28906679A1K27GA00009GB002000APA   0001429200Y
S28906680X4K27GA0000I1000200
S28906682A2K27G600007QS002000BA    0001678400Y
S28906683X4K27GA0000I0000200
S28906683A4K27GA0000I3S000200DIA   0001298800Y
S28906687A1K27GA00009HS002000APA   0001480100Y
S28906690A4K27GA0000I4S000200DIA   0001298900Y
S28906691A2K27G600007RB002000BAX   0000587000Y
S28906691X3K27G60000AG000100
S28906691X4K27GA0000I3000200
S28906693X4K27GA0000I2000100
S28906694X3K27G60000AH000100
S28906701A4K27GA0000I5S000200DIA   0001299100Y
S28906701A4K27GA0000I6B000100DXD   0000499500Y
S28906701X4K27GA0000I6000100
S28906702A3K27G60000AIS000100DDM   0000802500Y
S28906702A3K27G60000AJB000100DDM   0000801100Y
S28906702X3K27G60000AI000100
S28906706X4K27GA0000I5000200
S28906707A2K27G600007SS002000BAX   0000639100Y
S28906709A4K27GA0000I7S000200DIA   0001298800Y
S28906711A4K27GA0000I8B000100DXD   0000499500Y
S28906711A3K27G60000AKS000100DDM   0000802500Y
S28906711X4K27GA0000I7000200
S28906712X3K27G60000AJ000100
S28906719A4K27GA0000I9S000200DIA   0001299100Y
S28906722A3K27G60000ALB000100DDM   0000801100Y
S28906726X4K27GA0000I4000200
S28906731A4K27GA0000IAS000200DIA   0001299200Y
S28906731X4K27GA0000I8000100
S28906732X3K27G60000AK000100
S28906738X4K27GA0000IA000200
S28906741A4K27GA0000IBS000200DIA   0001298900Y
S28906741A4K27GA0000ICB000100DXD   0000499500Y
S28906742A3K27G60000AMS000100DDM   0000802500Y
S28906751X3K27G60000AL000100
S28906754X4K27GA0000IB000200
S28906761A4K27GA0000IDS000200DIA   0001299200Y
S28906761A3K27G60000ANB000100DDM   0000801100Y
S28906761X4K27GA0000IC000100
S28906762X3K27G60000AM000100
S28906938X4K27GA000062000200
S28906938A4K27GA0000IEB000200DIA   0001298700Y
S28907344X6K27GA0000AO002000
S28907350XAK27GA00015G002000
S28907390A2K27G600007TB002000BAC   0000348700Y
S28907403X7K27GA000068002000
S28907408XBK27GA0000XI002000
S28907413A5K27GA00006US002000FNM   0001497700Y
S28907425A2K27G600007US002000BAC   0000371900Y
S28907434X1K27GA00009A002000
S28907445ABK27GA0000XJS002000UTX   0001636300Y
S28907449A2K27G600007VB002000BMY   0000057200Y
S28907459ACK27GA00004KB002000WYE   0000120700Y
S28907473X2K27G600007Q002000
S28907473A2K27G600007WS002000BMY   0000234000Y
S28907494A1K27GA00009IB002000AFL   0000190800Y
S28907498A2K27G600007XB002000C     0000219400Y
S28907501A1K27GA00009JS002000AFL   0001626400Y
S28907516A2K27G600007YS002000C     0000238000Y
S28907518A2K27G600007ZB002000BBT   0000092700Y
S28907541A3K27G60000AOB002000COF   0000496000Y
S28907541XAK27GA0000E6001000
S28907541AAK27GA0000E6S001000SPY   0001426100Y
S28907544A2K27G6000080S002000BBT   0001514800Y
S28907545XAK27GA00012W001000
S28907545XAK27GA00012X001000
S28907546AAK27GA00015RB000400SPY   0001425600Y
S28907548ABK27GA0000XKB001000SSO   0000764200Y
S28907548XBK27GA0000VQ001000
S28907548AAK27GA00015SS001000SPY   0001426100Y
S28907549XAK27GA0000ZC000100
S28907550XBK27GA0000WZ001000
S28907552ABK27GA0000XLS001000SSO   0000765500Y
S28907561A2K27G6000081B002000BBY   0000423100Y
S28907562A3K27G60000APS002000COF   0000524500Y
S28907564AAK27GA00015TS002000SPY   0001426000Y
S28907564XAK27GA0000QB000500
S28907564AAK27GA0000QBS000500SPY   0001426200Y
S28907565XAK27GA00010P001000
S28907565XAK27GA00010O001000
S28907565XAK27GA0000EW000500
S28907565XAK27GA0000E9001000
S28907565AAK27GA0000E9S001000SPY   0001426200Y
S28907565XAK27GA0000E8001000
S28907565AAK27GA0000E8B001000SPY   0001425600Y
S28907565AAK27GA00015UB001000SPY   0001425600Y
S28907565XAK27GA0000NY000500
S28907565AAK27GA0000NYS000500SPY   0001426200Y
S28907565XAK27GA0000FI000500
S28907565AAK27GA0000FIB000500SPY   0001425600Y
S28907566AAK27GA00015VS001000SPY   0001426200Y
S28907567AAK27GA00015WS001000SDS   0000548800Y
S28907567ABK27GA0000XMB001000SSO   0000764500Y
S28907567XBK27GA0000WY001000
S28907567XAK27GA0000EX000500
S28907567AAK27GA0000EXB000500SPY   0001425600Y
S28907567XAK27GA000110001000
S28907568XAK27GA0000E7001000
S28907568AAK27GA0000E7B001000SPY   0001425600Y
S28907568XAK27GA00013M001000
S28907569AAK27GA00015XB001000SPY   0001425600Y
S28907569ABK27GA0000XNB001000SSO   0000764600Y
S28907569XBK27GA0000XM001000
S28907569AAK27GA00015YS001000SPY   0001426300Y
S28907570XAK27GA0000XS001000
S28907570XBK27GA0000XL001000
S28907570AAK27GA00015ZS000100SH    0000618800Y
S28907570AAK27GA000160S001000SDS   0000548700Y
S28907571AAK27GA000161B001000SDS   0000547400Y
S28907572ABK27GA0000XOS001000SSO   0000765600Y
S28907588XAK27GA00015D002500
S28907589AAK27GA000162B002500SPY   0001425500Y
S28907590XAK27GA000142002500
S28907605A4K27GA0000IFB002000DNA   0000687500Y
S28907607X4K27GA00007C000200
S28907607A4K27GA00007CB000200DIA   0001298800Y
S28907608XAK27GA0000ZM000500
S28907609A4K27GA0000IGS000100DOG   0000598300Y
S28907610A3K27G60000AQB000100DDM   0000801200Y
S28907610X3K27G600009T000100
S28907609X4K27GA0000GV000100
S28907609A4K27GA0000IHS000100DXD   0000500100Y
S28907610AAK27GA000163B005000SPY   0001425400Y
S28907613XAK27GA000162002500
S28907616A4K27GA0000IIS002000DNA   0000719500Y
S28907643A2K27G6000082S002000BBY   0000458300Y
S28907655A6K27GA0000B9B002000IWM   0000736600Y
S28907656X6K27GA00002B000500
S28907656A6K27GA00002BS000500IWM   0000737200Y
S28907665XBK27GA0000WF000100
S28907665XBK27GA0000WG000100
S28907665XBK27GA0000WH000100
S28907672A2K27G6000083B002000BDX   0000771200Y
S28907682A2K27G6000084S002000BDX   0000901100Y
S28907687XAK27GA00015U001000
S28907687AAK27GA00015UB001000SPY   0001425700Y
S28907687XAK27GA0000EX000500
S28907687AAK27GA0000EXB000500SPY   0001425700Y
S28907687XAK27GA0000E7001000
S28907687AAK27GA0000E7B001000SPY   0001425700Y
S28907687XAK27GA00015X001000
S28907687AAK27GA00015XB001000SPY   0001425700Y
S28907690ABK27GA0000XPB001000SSO   0000764700Y
S28907690XBK27GA0000XN001000
S28907693XAK27GA0000K1001000
S28907693AAK27GA0000K1S001000SPY   0001426300Y
S28907693X4K27GA0000GX000200
S28907693XAK27GA0000O2000500
S28907693AAK27GA0000O2S000500SPY   0001426300Y
S28907701A4K27GA0000IJS000200DIA   0001299300Y
S28907702XAK27GA0000FE000500
S28907702AAK27GA0000FEB000500SPY   0001425700Y
S28907711A4K27GA0000IKB000100DRYS  0001068100Y
S28907798XAK27GA00013I001000
S28907798XAK27GA00013J001000
S28907798AAK27GA000164B001000SPY   0001425400Y
S28908149AAK27GA000165S002500SPY   0001426000Y
S28908395XAK27GA00015O002000
S28908401A6K27GA0000BAS002000IMCL  0000515500Y
S28908408A4K27GA0000ILB002000DVN   0001209300Y
S28908430AAK27GA000166B002000SHLD  0000763500Y
S28908437A4K27GA0000IMS002000DVN   0001239800Y
S28908440X5K27GA00006U002000
S28908454XBK27GA0000XJ002000
S28908461XCK27GA00004K002000
S28908471X1K27GA00009I002000
S28908476X1K27GA00009J002000
S28908478A4K27GA0000INB002000EMR   0000555500Y
S28908484X2K27G6000080002000
S28908504A4K27GA0000IOS002000EMR   0000601500Y
S28908505A7K27GA000069B002000LMT   0000317300Y
S28908520ABK27GA0000XQB002000UTX   0000208300Y
S28908525A5K27GA00006VB002000FNM   0000277000Y
S28908526A1K27GA00009KB002000ABT   0000157000Y
S28908545A2K27G6000085S002000BA    0001672200Y
S28908550A5K27GA00006WS002000FNM   0001492200Y
S28908558A2K27G6000086B002000BHI   0000842700Y
S28908584A9K27G60000R7B000500QQQQ  0000495300Y
S28908584A9K27G60000R8B001000QQQQ  0000495300Y
S28908585A5K27GA00006XB002000GG    0000386600Y
S28908593X1K27GA00000V000100
S28908597A5K27GA00006YS002000GG    0000435400Y
S28908598P1K27GA00000VB000100AAPL  0001830000000N1AQ00005
S28908607A5K27GA00006ZB002000GM    0000179000Y
S28908616A5K27GA000070S002000GM    0000227900Y
S28908660A2K27G6000087S002000BHI   0000874700Y
S28908672A2K27G6000088B002000BJS   0000300300Y
S28908682A2K27G6000089S002000BJS   0000328100Y
S28908692A2K27G600008AB002000BK    0000427800Y
S28908701A2K27G600008BS002000BK    0000477700Y
S28908710A2K27G600008CB002000BMC   0000364800Y
S28908720X4K27GA0000HA000100
S28908720X4K27GA0000HC000100
S28909355X3K27G60000A9002000
S28909357AAK27GA000167B002000SPLS  0000059300Y
S28909405X2K27G600007V002000
S28909421X5K27GA00006W002000
S28909444A5K27GA000071B002000GS    0001819700Y
S28909450X7K27GA000069002000
S28909455XBK27GA0000XQ002000
S28909460X1K27GA00009K002000
S28909469X2K27G6000085002000
S28909473X2K27G600007Z002000
S28909481A5K27GA000072S002000GS    0001862100Y
S28909497A6K27GA0000BBB002000IBM   0001247400Y
S28909527A6K27GA0000BCS002000IBM   0001273900Y
S28909544A6K27GA0000BDB002000JNJ   0000643100Y
S28909560A5K27GA000073S002000FNM   0001488200Y
S28909573A6K27GA0000BES002000JNJ   0000689500Y
S28909586A7K27GA00006AB002000KSS   0000458000Y
S28909605ABK27GA0000XRS002000UTX   0001629400Y
S28909606A7K27GA00006BS002000KSS   0000505300Y
S28909612ACK27GA00004LB002000WYE   0000123200Y
S28909624A7K27GA00006CB002000LMT   0000321100Y
S28909627A1K27GA00009LB002000AFL   0000194500Y
S28909641A7K27GA00006DS002000LMT   0001128000Y
S28909645A1K27GA00009MS002000AFL   0001619200Y
S28909654A2K27G600008DS002000BBT   0001505600Y
S28909875A4K27GA0000IPS000100DRYS  0001074900Y
S28909875A4K27GA0000IQS000100DRYS  0001074900Y
S28910367X7K27GA00006C002000
S28910395A3K27G60000ARB002000CTSH  0000085900Y
S28910404A2K27G600008EB002000BMY   0000059000Y
S28910420X5K27GA000073002000
S28910449A5K27GA000074S002000FNM   0001482700Y
S28910468XBK27GA0000X8002000
S28910472XBK27GA0000XR002000
S28910477A7K27GA00006EB002000MDT   0000479800Y
S28910479XCK27GA00004L002000
S28910488X1K27GA00009L002000
S28910493X1K27GA00009M002000
S28910496X2K27G600007L002000
S28910498X9K27G60000QS000700
S28910498A9K27G60000R9S001000QID   0000382000Y
S28910498A9K27G60000RAB001000QLD   0000889100Y
S28910499A9K27G60000RBS001000QID   0000381900Y
S28910499X9K27G60000RA001000
S28910499A9K27G60000RCB001000QLD   0000889200Y
S28910508X2K27G600008D002000
S28910512A7K27GA00006FS002000MDT   0000506900Y
S28910528A9K27G60000RDB001000QLD   0000889300Y
S28910528X9K27G60000RC001000
S28910530A9K27G60000REB001000QQQQ  0000495400Y
S28910535A7K27GA00006GB002000MMM   0000765100Y
S28910536X9K27G60000RE001000
S28910561A7K27GA00006HS002000MMM   0000815300Y
S28910564A7K27GA00006IB002000LMT   0000323300Y
S28910671ABK27GA0000XSB002000UTX   0000212300Y
S28910680A1K27GA00009NB002000ABT   0000160100Y
S28910686A2K27G600008FS002000BA    0001666000Y
S28910691A2K27G600008GB002000BBT   0000095500Y
S28910705A2K27G600008HS002000BMC   0000391200Y
S28910708A7K27GA00006JB002000MO    0000212400Y
S28910724A2K27G600008IB002000BNI   0001061100Y
S28910727A7K27GA00006KS002000MO    0000238400Y
S28910743A2K27G600008JS002000BNI   0001129800Y
S28910748A8K27G600005GB002000NBR   0000403600Y
S28910760A2K27G600008KB002000BP    0000738400Y
S28910772A8K27G600005HS002000NBR   0000428200Y
S28911348X3K27G60000A8002000
S28911352X9K27G60000QZ002000
S28911386X5K27GA000074002000
S28911411X7K27GA00006I002000
S28911430A7K27GA00006LB002000LMT   0000327100Y
S28911435XBK27GA0000XS002000
S28911443A8K27G600005IB002000NEM   0000473600Y
S28911443X1K27GA00009N002000
S28911451X2K27G600008F002000
S28911468A8K27G600005JS002000NEM   0000503800Y
S28911482A5K27GA000075S002000FNM   0001478700Y
S28911488ABK27GA0000XTB002000TGT   0000521300Y
S28911505ABK27GA0000XUS002000TGT   0000624000Y
S28911525ABK27GA0000XVB002000TXN   0000309200Y
S28911545ABK27GA0000XWS002000TXN   0000333500Y
S28911550ABK27GA0000XXS002000TGT   0000624800Y
S28911582ABK27GA0000XYB002000TYC   0000439900Y
S28911592ABK27GA0000XZS002000TYC   0000495000Y
S28911601ABK27GA0000Y0B002000UTX   0000215100Y
S28911612ABK27GA0000Y1S002000UTX   0001621700Y
S28911634ABK27GA0000Y2S002000UTX   0001622500Y
S28911642ACK27GA00004MB002000WYE   0000125600Y
S28911651A1K27GA00009OB002000AFL   0000198200Y
S28911657A1K27GA00009PS002000AFL   0001612100Y
S28911666A2K27G600008LB002000AXP   0000414700Y
S28911832X8K27G600004L000500
S28911832X8K27G600004M000100
S28911835A8K27G600005KS000100MVV   0000809600Y
S28911835X8K27G600005K000100
S28911841A8K27G600005LS000100MVV   0000809600Y
S28912107XAK27GA0000F2000500
S28912107AAK27GA0000F2B000500SPY   0001425800Y
S28912107XAK27GA0000Z5003000
S28912107XAK27GA0000Z4003000
S28912107XAK27GA00015T002000
S28912107XAK27GA0000NZ000500
S28912107XAK27GA0000Z1003000
S28912107XAK27GA00014C001000
S28912107AAK27GA000168B003000SPY   0001425700Y
S28912107XAK27GA0000O6000500
S28912107AAK27GA0000O6S000500SPY   0001426400Y
S28912107AAK27GA000169B003000SPY   0001425700Y
S28912107XAK27GA0000E4001000
S28912107AAK27GA0000E4B001000SPY   0001425800Y
S28912107AAK27GA00016AB002000SPY   0001425600Y
S28912107XAK27GA00013U002000
S28912107XAK27GA0000Z3003000
S28912109ABK27GA0000Y3B001000SSO   0000764500Y
S28912109AAK27GA00016BS003000SPY   0001426600Y
S28912109XAK27GA0000FD000500
S28912109AAK27GA0000FDB000500SPY   0001425800Y
S28912110AAK27GA00016CS003000SPY   0001426600Y
S28912110AAK27GA00016DS005000SPY   0001426100Y
S28912110XAK27GA000165002500
S28912111XAK27GA00015E005000
S28912111AAK27GA00016EB002500SPY   0001425600Y
S28912111X4K27GA0000ES000100
S28912111X4K27GA0000ER000100
S28912112X3K27G600007P000100
S28912112XAK27GA00015F000500
S28912112AAK27GA00016FB000500SPY   0001425600Y
S28912113XAK27GA000141000500
S28912114A4K27GA0000IRB000100DXD   0000499100Y
S28912114A3K27G60000ASS000100DDM   0000802700Y
S28912121X6K27GA000099002000
S28912124X6K27GA00009T002000
S28912124A6K27GA0000BFS002000IWM   0000737700Y
S28912132XAK27GA000168003000
S28912132AAK27GA00016GS002000SPY   0001426000Y
S28912132XAK27GA000169003000
S28912132XAK27GA0000E4001000
S28912132AAK27GA0000E4B001000SPY   0001425400Y
S28912132XAK27GA0000FD000500
S28912132AAK27GA0000FDB000500SPY   0001425400Y
S28912132XAK27GA0000O6000500
S28912132AAK27GA0000O6S000500SPY   0001426000Y
S28912133XAK27GA0000F2000500
S28912133AAK27GA0000F2B000500SPY   0001425400Y
S28912133XAK27GA00016E002500
S28912134AAK27GA00016HB003000SPY   0001425600Y
S28912134AAK27GA00016IB003000SPY   0001425600Y
S28912135XAK27GA00016C003000
S28912135XAK27GA00016F000500
S28912135XAK27GA00016B003000
S28912136AAK27GA00016JS003000SPY   0001426000Y
S28912136AAK27GA00016KS003000SPY   0001426000Y
S28912141XAK27GA00016A002000
S28912141XBK27GA0000Y3001000
S28912141A3K27G60000ATS000100DDM   0000802600Y
S28912141A4K27GA0000ISB000100DOG   0000597000Y
S28912141A4K27GA0000ITB000100DXD   0000499400Y
S28912141A4K27GA0000IUS000047DIA   0001299000Y
S28912141X4K27GA0000IJ000200
S28912141AAK27GA00016LS001000SPY   0001426200Y
S28912141XAK27GA00014B001000
S28912142X9K27G60000F6003200
S28912142A9K27G60000F6S003200QQQQ  0000496400Y
S28912142X9K27G60000QN005000
S28912142X9K27G60000QJ005000
S28912142A9K27G60000RFB005000QQQQ  0000495800Y
S28912143A9K27G60000RGB005000QQQQ  0000495800Y
S28912143AAK27GA00016MB001000SPY   0001425400Y
S28912143A9K27G60000RHB001000QLD   0000889200Y
S28912143AAK27GA00016NS001000SPY   0001426200Y
S28912144X4K27GA0000IU000047
S28912146X6K27GA00007U000500
S28912146A6K27GA00007UB000500IWM   0000736700Y
S28912148XAK27GA00016K003000
S28912148XAK27GA0000O6000500
S28912148AAK27GA0000O6S000500SPY   0001426400Y
S28912148XAK27GA00016J003000
S28912148XAK27GA0000F2000500
S28912148AAK27GA0000F2B000500SPY   0001425800Y
S28912148A4K27GA0000IVS000200DIA   0001299300Y
S28912147A6K27GA0000BGB002000IWM   0000736600Y
S28912148AAK27GA00016OB001000SPY   0001425600Y
S28912148XAK27GA0000E4001000
S28912148AAK27GA0000E4B001000SPY   0001425800Y
S28912148XAK27GA00016M001000
S28912147X6K27GA00007U000500
S28912147A6K27GA00007UB000500IWM   0000736300Y
S28912149ABK27GA0000Y4B000100UWM   0000542700Y
S28912150ABK27GA0000Y5S000100TWM   0000702000Y
S28912150XBK27GA0000X1000100
S28912150ABK27GA0000Y6B001000SSO   0000764500Y
S28912150AAK27GA00016PS003000SPY   0001426600Y
S28912150AAK27GA00016QS003000SPY   0001426600Y
S28912151XAK27GA00016G002000
S28912151X4K27GA0000IS000100
S28912151X4K27GA0000IT000100
S28912152X3K27G60000AT000100
S28912152X6K27GA00007U000500
S28912152A6K27GA00007UB000500IWM   0000736700Y
S28912154XBK27GA0000Y4000100
S28912154XBK27GA0000Y5000100
S28912155ABK27GA0000Y7B000100UWM   0000542700Y
S28912155ABK27GA0000Y8S000100TWM   0000702000Y
S28912160X6K27GA00007U000500
S28912160A6K27GA00007UB000500IWM   0000736300Y
S28912164X6K27GA00007U000500
S28912164A6K27GA00007UB000500IWM   0000736700Y
S28912169X6K27GA00007U000500
S28912169A6K27GA00007UB000500IWM   0000736300Y
S28912170XAK27GA00016N001000
S28912173X6K27GA00007U000500
S28912173A6K27GA00007UB000500IWM   0000736700Y
S28912175XBK27GA0000Y7000100
S28912175XBK27GA0000Y8000100
S28912177ABK27GA0000Y9B000100UWM   0000542700Y
S28912177ABK27GA0000YAS000100TWM   0000702000Y
S28912179X4K27GA0000DX000200
S28912179A4K27GA0000DXB000200DIA   0001298800Y
S28912184X4K27GA0000DX000200
S28912184A4K27GA0000DXB000200DIA   0001298900Y
S28912186X4K27GA0000E3000100
S28912186A3K27G60000AUB000100DDM   0000801300Y
S28912186A4K27GA0000IWS000100DXD   0000500000Y
S28912186X3K27G600009U000100
S28912222XAK27GA000103000100
S28912222AAK27GA00016RB000100SPY   0001424600Y
S28912229XAK27GA000161001000
S28912231AAK27GA00016SB001000SDS   0000547300Y
S28912235XBK27GA0000IW001000
S28912282XAK27GA0000FD000500
S28912282AAK27GA0000FDB000500SPY   0001425800Y
S28912283AAK27GA00016TB001000SPY   0001425600Y
S28912289XBK27GA0000XO001000
S28912289XAK27GA0000U6000100
S28912290AAK27GA00016UB000100SH    0000618100Y
S28912291ABK27GA0000YBS001000SSO   0000765700Y
S28912311AAK27GA00016VB000100SH    0000618200Y
S28912311AAK27GA00016WB001000SDS   0000547400Y
S28912311ABK27GA0000YCS001000SSO   0000765600Y
S28912311XBK27GA0000YB001000
S28912313AAK27GA00016XB000500SPY   0001425600Y
S28912324X8K27G600004P000100
S28912324A8K27G600005MB000100MVV   0000806400Y
S28912326XAK27GA00016T001000
S28912341X1K27GA00008T002000
S28912370A3K27G60000AVB002000CELG  0000492800Y
S28912369X5K27GA000075002000
S28912374X2K27G600008E002000
S28912414X5K27GA00006F002000
S28912429XAK27GA000166002000
S28912436X7K27GA00006L002000
S28912460X3K27G6000096002000
S28912482A5K27GA000076S002000FNM   0001473200Y
S28912496XBK27GA0000Y0002000
S28912500A9K27G60000RIB002000PDLI  0000031100Y
S28912510XBK27GA0000Y1002000
S28912511XBK27GA0000Y2002000
S28912516X6K27GA000026000500
S28912516A6K27GA000026S000500IWM   0000737300Y
S28912519A6K27GA0000BHB002000IWM   0000736700Y
S28912520X6K27GA00009U002000
S28912524XCK27GA00004M002000
S28912524X6K27GA000027000500
S28912524A6K27GA000027B000500IWM   0000736800Y
S28912527ABK27GA0000YDS000100TWM   0000701800Y
S28912527ABK27GA0000YEB000100UWM   0000542800Y
S28912527XBK27GA0000EN000100
S28912527XBK27GA0000YA000100
S28912526X6K27GA000027000500
S28912526A6K27GA000027B000500IWM   0000736400Y
S28912528X6K27GA000027000500
S28912528A6K27GA000027B000500IWM   0000736800Y
S28912530XBK27GA0000YD000100
S28912530XBK27GA0000YE000100
S28912532ABK27GA0000YFS000100TWM   0000701800Y
S28912532ABK27GA0000YGB000100UWM   0000542800Y
S28912533X1K27GA00009O002000
S28912533X6K27GA000027000500
S28912533A6K27GA000027B000500IWM   0000736400Y
S28912535XBK27GA0000J0000100
S28912535XBK27GA0000J1000100
S28912535XBK27GA0000J2000100
S28912534A6K27GA0000BIS002000IWM   0000737300Y
S28912537XBK27GA0000YG000100
S28912537XBK27GA0000YF000100
S28912537ABK27GA0000YHB000100TWM   0000700400Y
S28912539ABK27GA0000YIS000100TWM   0000702000Y
S28912541X1K27GA00009P002000
S28912540X6K27GA000027000500
S28912540A6K27GA000027B000500IWM   0000736800Y
S28912541A6K27GA0000BJB002000IWM   0000736700Y
S28912541X6K27GA00005B002000
S28912543ABK27GA0000YJB000100UWM   0000542800Y
S28912543ABK27GA0000YKS000100TWM   0000701800Y
S28912543XBK27GA0000YI000100
S28912544A8K27G600005NS000500MZZ   0000493700Y
S28912544X8K27G600004Q000100
S28912544A8K27G600005OB000100MVV   0000806500Y
S28912560AAK27GA00016YB002500SPY   0001425600Y
S28912563X2K27G600008G002000
S28912584A9K27G60000RJB002000QQQQ  0000495800Y
S28912602X9K27G60000QG005000
S28912602X9K27G60000QH005000
S28912602X9K27G60000EO002000
S28912602A9K27G60000EOB002000QQQQ  0000495800Y
S28912602X9K27G60000QI002000
S28912603X9K27G60000QW002000
S28912603A9K27G60000RKB002000QQQQ  0000495600Y
S28912603A9K27G60000RLS005000QQQQ  0000496300Y
S28912604A9K27G60000RMS005000QQQQ  0000496300Y
S28912608X9K27G60000ET002000
S28912608A9K27G60000ETS002000QQQQ  0000496200Y
S28912608ACK27GA00004NB002000VZ    0000374600Y
S28912611A9K27G60000RNB002000QQQQ  0000495600Y
S28912611X6K27GA00006R002000
S28912619X2K27G6000083002000
S28912619X9K27G60000G3002000
S28912619A9K27G60000G3S002000QQQQ  0000496400Y
S28912622ACK27GA00004OS002000VZ    0000406200Y
S28912629X8K27G600004J000500
S28912629X8K27G600005L000100
S28912629X8K27G600004K000100
S28912630A8K27G600005PB000500MZZ   0000491300Y
S28912631A8K27G600005QS000100MVV   0000809800Y
S28912641ACK27GA00004PB002000WLP   0000501300Y
S28912645X8K27G600003C000500
S28912654A7K27GA00006MB002000LMT   0000329300Y
S28912662ACK27GA00004QS002000WLP   0000527000Y
S28912686X9K27G60000OV000200
S28912697ACK27GA00004RB002000WMT   0000540900Y
S28912708A9K27G60000ROS002000QQQQ  0000496100Y
S28912710ABK27GA0000YLB002000UTX   0000216300Y
S28912720ACK27GA00004SS002000WMT   0000580900Y
S28912738A1K27GA00009QB002000ABT   0000163100Y
S28912738ACK27GA00004TB002000WYE   0000127600Y
S28912760A2K27G600008MS002000BA    0001659800Y
S28912760ACK27GA00004US002000WYE   0000472500Y
S28912779A2K27G600008NS002000BBT   0001491900Y
S28912800A2K27G600008OS002000BP    0000760300Y
S28912812A2K27G600008PB002000BR    0000190800Y
S28912839X9K27G60000F5003200
S28912839A9K27G60000F5B003200QQQQ  0000495800Y
S28912948X8K27G600005D000100
S28912948A8K27G600005RB000100MVV   0000806600Y
S28913011AAK27GA00016ZS002500SPY   0001426100Y
S28913347A1K27GA00009RS002000AMGN  0000482600Y
S28913373X5K27GA000076002000
S28913400XAK27GA000167002000
S28913401A5K27GA000077S002000FNM   0001469200Y
S28913405X7K27GA00006M002000
S28913411X3K27G60000AR002000
S28913413A2K27G600008QB002000BMY   0000060900Y
S28913419XAK27GA00015P002000
S28913452A5K27GA000078B002000GM    0000178600Y
S28913452AAK27GA000170B002000SHLD  0000766400Y
S28913461XCK27GA00004T002000
S28913500A3K27G60000AWS002000CMCSK 0000272400Y
S28913502XBK27GA0000YL002000
S28913526X1K27GA00009Q002000
S28913528A7K27GA00006NB002000LMT   0000333100Y
S28913542X2K27G600008M002000
S28913549X2K27G600008N002000
S28913556ABK27GA0000YMB002000UTX   0000219100Y
S28913728ABK27GA0000YNS002000UTX   0001614800Y
S28913730ABK27GA0000YOS002000UTX   0001615600Y
S28913732A1K27GA00009SB002000A     0000346200Y
S28913745ACK27GA00004VB002000WYE   0000128000Y
S28913750A1K27GA00009TS002000A     0000371400Y
S28913757A1K27GA00009UB002000AFL   0000201900Y
S28913771A1K27GA00009VS002000AFL   0001604900Y
S28913771A1K27GA00009WB002000ABT   0000165500Y
S28913796A1K27GA00009XS002000ABT   0000567200Y
S28913798A2K27G600008RB002000BBT   0000098400Y
S28913813A2K27G600008SB002000BDX   0000772500Y
S28913830A1K27GA00009YB002000ABX   0000393800Y
S28913850A1K27GA00009ZS002000ABX   0000425700Y
S28913860A1K27GA0000A0B002000ACE   0000587200Y
S28914200AAK27GA000171S002000SPY   0001426700Y
S28914246AAK27GA000172B002000SPY   0001424900Y
S28914362X5K27GA000077002000
S28914375X7K27GA00006N002000
S28914375AAK27GA000173B002000SPLS  0000062400Y
S28914395XBK27GA0000YM002000
S28914405XBK27GA0000YN002000
S28914426XBK27GA0000YO002000
S28914432X1K27GA00009W002000
S28914457A3K27G60000AXB002000CTSH  0000089300Y
S28914458A5K27GA000079S002000FNM   0001463700Y
S28914460XAK27GA00016L001000
S28914460AAK27GA000174S001000SPY   0001426300Y
S28914462AAK27GA000175S001000SPY   0001426300Y
S28914466XCK27GA00004V002000
S28914470AAK27GA000176S002000SPY   0001426200Y
S28914475AAK27GA000177S002000SPY   0001426500Y
S28914483AAK27GA000178B002000SPY   0001425400Y
S28914484X1K27GA00009U002000
S28914484AAK27GA000179B002000SNDK  0000238600Y
S28914484AAK27GA00017AB002000SPY   0001425100Y
S28914493AAK27GA00017BB001000SPY   0001425600Y
S28914499XAK27GA00017B001000
S28914505X1K27GA00009V002000
S28914520ACK27GA00004WB002000WYE   0000130000Y
S28914526A7K27GA00006OB002000LMT   0000335300Y
S28914532A1K27GA0000A1S002000ACE   0000640600Y
S28914551A1K27GA0000A2B002000ACF   0000120500Y
S28914554ABK27GA0000YPB002000UTX   0000220300Y
S28914571A1K27GA0000A3B002000ACN   0000357400Y
S28914593A1K27GA0000A4S002000ACN   0000407900Y
S28914602A1K27GA0000A5B002000ABT   0000166200Y
S28914604A1K27GA0000A6B002000AFL   0000204600Y
S28914616A2K27G600008TS002000BA    0001653600Y
S28914622A1K27GA0000A7S002000AFL   0001600500Y
S28914626A2K27G600008US002000BBT   0001482700Y
S28914640A1K27GA0000A8B002000ALL   0000484200Y
S28914655A2K27G600008VS002000BR    0000248200Y
S28914659A1K27GA0000A9S002000ALL   0000524800Y
S28914673A2K27G600008WB002000BSX   0000118600Y
S28914695A2K27G600008XS002000BSX   0000153200Y
S28914715A2K27G600008YB002000CA    0000227900Y
S28915162XAK27GA00016R000100
S28915162AAK27GA00017CB000100SPY   0001425000Y
S28915344X1K27GA00007P002000
S28915403X7K27GA00006O002000
S28915404X2K27G600008Q002000
S28915408XBK27GA0000YP002000
S28915422X5K27GA000079002000
S28915424X1K27GA0000A5002000
S28915441A7K27GA00006PB002000LMT   0000339100Y
S28915462X2K27G600008T002000
S28915470X2K27G600008R002000
S28915473ABK27GA0000YQB002000UTX   0000223100Y
S28915479X2K27G600008U002000
S28915488A5K27GA00007AS002000FNM   0001459700Y
S28915494ABK27GA0000YRS002000UTX   0001607800Y
S28915507XCK27GA00004W002000
S28915521ABK27GA0000YSS002000UTX   0001608600Y
S28915523A1K27GA0000AAB002000ABT   0000168600Y
S28915540X1K27GA0000A6002000
S28915564X1K27GA0000A7002000
S28915572ACK27GA00004XB002000WYE   0000130400Y
S28915598A1K27GA0000ABB002000ANF   0000723200Y
S28915598A1K27GA0000ACB002000AFL   0000205600Y
S28915615A1K27GA0000ADS002000AFL   0001597700Y
S28915617A1K27GA0000AES002000ANF   0000772300Y
S28915641A1K27GA0000AFB002000ANN   0000259600Y
S28915646A2K27G600008ZS002000CA    0000254000Y
S28915670A1K27GA0000AGS002000ANN   0000302700Y
S28915708A1K27GA0000AHB002000AOC   0000443100Y
S28915720A1K27GA0000AIS002000AOC   0000498900Y
S28916350X1K27GA00008U002000
S28916353A1K27GA0000AJB002000APOL  0000412300Y
S28916378A2K27G6000090B002000BMY   0000062700Y
S28916378X5K27GA00007A002000
S28916413XBK27GA0000XX002000
S28916419XBK27GA0000YS002000
S28916441A5K27GA00007BS002000FNM   0001454200Y
S28916440XCK27GA00004X002000
S28916450X1K27GA0000AC002000
S28916456X1K27GA0000AD002000
S28916461X7K27GA00006P002000
S28916474XBK27GA0000XU002000
S28916478XBK27GA0000YQ002000
S28916479X2K27G600008L002000
S28916488XBK27GA0000YR002000
S28916495X1K27GA0000AA002000
S28916497A7K27GA00006QB002000LMT   0000341300Y
S28916506ABK27GA0000YTB002000UTX   0000224300Y
S28916508ACK27GA00004YB002000WYE   0000132400Y
S28916523A1K27GA0000AKB002000AFL   0000208300Y
S28916526A1K27GA0000ALB002000ABT   0000169300Y
S28916538A1K27GA0000AMS002000AFL   0001593300Y
S28916553A1K27GA0000ANB002000APC   0000765400Y
S28916568A1K27GA0000AOS002000APC   0000792900Y
S28916579A1K27GA0000APB002000ARO   0000299300Y
S28916589A1K27GA0000AQS002000ARO   0000369000Y
S28916599A2K27G6000091B002000AVP   0000358800Y
S28916642A2K27G6000092S002000BA    0001647500Y
S28916647A2K27G6000093B002000BBT   0000101200Y
S28916659A2K27G6000094S002000BBT   0001473600Y
S28916662A2K27G6000095B002000CAG   0000066300Y
S28916672A2K27G6000096S002000CAG   0001439400Y
S28916716XAK27GA00016O001000
S28916716AAK27GA00017DS002000SPY   0001426100Y
S28916716XAK27GA00016H003000
S28916716AAK27GA00017ES003000SPY   0001426000Y
S28916716AAK27GA00017FS003000SPY   0001426000Y
S28916716XAK27GA00016P003000
S28916716XAK27GA0000FD000500
S28916716AAK27GA0000FDB000500SPY   0001425400Y
S28916716XAK27GA0000O6000500
S28916716AAK27GA0000O6S000500SPY   0001426000Y
S28916716XAK27GA00016I003000
S28916717XAK27GA00016Q003000
S28916717XAK27GA0000E4001000
S28916717AAK27GA0000E4B001000SPY   0001425400Y
S28916717XAK27GA0000F2000500
S28916717AAK27GA0000F2B000500SPY   0001425400Y
S28916717AAK27GA00017GB002000SPY   0001424600Y
S28916717AAK27GA00017HS002000SPY   0001427000Y
S28916717AAK27GA00017IB002000SPY   0001424400Y
S28916717AAK27GA00017JB001000SPY   0001425500Y
S28916718XAK27GA00016D005000
S28916718AAK27GA00017KB003000SPY   0001425000Y
S28916718AAK27GA00017LB003000SPY   0001425000Y
S28916719AAK27GA00017MS005000SPY   0001426200Y
S28916719XAK27GA00016Y002500
S28916719XBK27GA0000Y6001000
S28916719XAK27GA00016X000500
S28916720AAK27GA00017NS000500SPY   0001426000Y
S28916720AAK27GA00017OS002500SPY   0001426000Y
S28916720XAK27GA00016Z002500
S28916733X9K27G60000G3002000
S28916733A9K27G60000G3S002000QQQQ  0000495900Y
S28916734X9K27G60000RN002000
S28916751X9K27G60000RK002000
S28916754A6K27GA0000BKS002000IWM   0000737200Y
S28916758XBK27GA0000XP001000
S28916760ABK27GA0000YUB001000SSO   0000764600Y
S28916776X6K27GA000027000500
S28916776A6K27GA000027B000500IWM   0000736400Y
S28916785XBK27GA0000YK000100
S28916785XBK27GA0000YJ000100
S28916786ABK27GA0000YVS000100TWM   0000702000Y
S28916802X6K27GA0000BJ002000
S28916816A8K27G600005SB000500MZZ   0000491400Y
S28916816A8K27G600005TS000100MVV   0000809600Y
S28916920AAK27GA00017PB000500SPY   0001425400Y
S28917361XAK27GA000170002000
S28917361A1K27GA0000ARS002000APOL  0000531900Y
S28917364X3K27G60000AX002000
S28917364X7K27GA00006Q002000
S28917398X5K27GA00007B002000
S28917402XBK27GA0000YT002000
S28917425XCK27GA00004Y002000
S28917446X1K27GA0000AL002000
S28917455X1K27GA0000AK002000
S28917474X1K27GA0000AM002000
S28917480X2K27G6000092002000
S28917486X2K27G6000094002000
S28917495X2K27G6000096002000
S28917495A7K27GA00006RB002000LMT   0000345100Y
S28917504A5K27GA00007CS002000FNM   0001450200Y
S28917512ABK27GA0000YWS002000TGT   0000622400Y
S28917524ABK27GA0000YXS002000TGT   0000623200Y
S28917531ABK27GA0000YYB002000UTX   0000227100Y
S28917533ABK27GA0000YZS002000UTX   0001601700Y
S28917554ABK27GA0000Z0S002000UTX   0001600900Y
S28917559ACK27GA00004ZB002000WYE   0000132800Y
S28917575A1K27GA0000ASB002000AFL   0000209300Y
S28917584A1K27GA0000ATB002000ABT   0000171600Y
S28917584A1K27GA0000AUS002000AFL   0001590600Y
S28917602A2K27G6000097S002000AVP   0000414400Y
S28917621A2K27G6000098B002000AXP   0000416800Y
S28917630A2K27G6000099B002000AXP   0000416000Y
S28917642A2K27G600009AS002000AXP   0000500000Y
S28917661A2K27G600009BB002000AZN   0000421600Y
S28917665A2K27G600009CB002000CAH   0000543500Y
S28917691A2K27G600009DS002000AZN   0000474700Y
S28917710A2K27G600009EB002000BA    0000855000Y
S28917745XAK27GA0000F2000500
S28917745AAK27GA0000F2B000500SPY   0001425800Y
S28917746XAK27GA00017E003000
S28917746XAK27GA00017F003000
S28917746XAK27GA00017K003000
S28917746XAK27GA00017L003000
S28917746XAK27GA00017D002000
S28917746AAK27GA00017QB003000SPY   0001425600Y
S28917746AAK27GA00017RB003000SPY   0001425600Y
S28917746XAK27GA000164001000
S28917746AAK27GA00017SB002000SPY   0001425600Y
S28917746XAK27GA0000E4001000
S28917746AAK27GA0000E4B001000SPY   0001425800Y
S28917746AAK27GA00017TS002000SPY   0001427200Y
S28917747XBK27GA0000YU001000
S28917747ABK27GA0000Z1B001000SSO   0000764700Y
S28917748AAK27GA00017US002000SPY   0001426200Y
S28917748AAK27GA00017VS003000SPY   0001426600Y
S28917748AAK27GA00017WS003000SPY   0001426600Y
S28917749ABK27GA0000Z2B001000SSO   0000764500Y
S28917749AAK27GA00017XS005000SPY   0001426100Y
S28917749XAK27GA00017M005000
S28917749XAK27GA00017O002500
S28917750AAK27GA00017YB002500SPY   0001425600Y
S28917751XAK27GA00017N000500
S28917751AAK27GA00017ZB000500SPY   0001425600Y
S28917751XAK27GA00017P000500
S28917754X6K27GA000027000500
S28917754A6K27GA000027B000500IWM   0000736800Y
S28917755A6K27GA0000BLB002000IWM   0000736700Y
S28917758ABK27GA0000Z3B000100UWM   0000542800Y
S28917758XBK27GA0000YV000100
S28917758ABK27GA0000Z4S000100TWM   0000701800Y
S28917758X6K27GA000027000500
S28917758A6K27GA000027B000500IWM   0000736400Y
S28917761XBK27GA0000Z3000100
S28917761XBK27GA0000Z4000100
S28917763ABK27GA0000Z5S000100TWM   0000702000Y
S28917762X6K27GA000027000500
S28917762A6K27GA000027B000500IWM   0000736800Y
S28917765ABK27GA0000Z6B000100UWM   0000542800Y
S28917765XBK27GA0000Z5000100
S28917765ABK27GA0000Z7S000100TWM   0000701800Y
S28917766XAK27GA0000E4001000
S28917766AAK27GA0000E4B001000SPY   0001425400Y
S28917766XAK27GA0000F2000500
S28917766AAK27GA0000F2B000500SPY   0001425400Y
S28917766X4K27GA0000DX000200
S28917766A4K27GA0000DXB000200DIA   0001298600Y
S28917767XAK27GA00017S002000
S28917768XBK27GA0000Z2001000
S28917768X4K27GA0000IW000100
S28917769X3K27G60000AU000100
S28917769XAK27GA00017W003000
S28917769XBK27GA0000Z1001000
S28917769XAK27GA00017Y002500
S28917769XAK27GA00017V003000
S28917769AAK27GA000180S003000SPY   0001426000Y
S28917770AAK27GA000181S003000SPY   0001426000Y
S28917771ABK27GA0000Z8B001000SSO   0000764600Y
S28917773X6K27GA000027000500
S28917773A6K27GA000027B000500IWM   0000736400Y
S28917776XAK27GA00017Z000500
S28917777X6K27GA000027000500
S28917777A6K27GA000027B000500IWM   0000736800Y
S28917779XAK27GA00017U001000
S28917779X6K27GA000027000500
S28917779A6K27GA000027B000500IWM   0000736400Y
S28917783X6K27GA000027000500
S28917783A6K27GA000027B000500IWM   0000736800Y
S28917785XBK27GA0000Z6000100
S28917785XBK27GA0000Z7000100
S28917785X6K27GA000027000500
S28917785A6K27GA000027B000500IWM   0000736400Y
S28917787ABK27GA0000Z9S000100TWM   0000701800Y
S28917787ABK27GA0000ZAB000100UWM   0000542800Y
S28917787X6K27GA000027000500
S28917787A6K27GA000027B000500IWM   0000736800Y
S28917788XBK27GA0000ZA000100
S28917788XBK27GA0000Z9000100
S28917790ABK27GA0000ZBB000100UWM   0000542800Y
S28917790ABK27GA0000ZCS000100TWM   0000701800Y
S28917793X6K27GA000027000500
S28917793A6K27GA000027B000500IWM   0000736400Y
S28917796XBK27GA0000ZC000100
S28917796XBK27GA0000ZB000100
S28917798ABK27GA0000ZDS000100TWM   0000702000Y
S28917798X6K27GA000027000500
S28917798A6K27GA000027B000500IWM   0000736800Y
S28917800AAK27GA000182B001000SPY   0001425400Y
S28917800ABK27GA0000ZEB000100UWM   0000542800Y
S28917800XBK27GA0000ZD000100
S28917800ABK27GA0000ZFS000100TWM   0000701800Y
S28917800XAK27GA00017J001000
S28917802AAK27GA000183B001000SPY   0001425400Y
S28917803X6K27GA000027000500
S28917803A6K27GA000027B000500IWM   0000736400Y
S28917804X6K27GA000027000500
S28917804A6K27GA000027B000500IWM   0000736800Y
S28917806XBK27GA0000ZE000100
S28917806XBK27GA0000ZF000100
S28917808ABK27GA0000ZGS000100TWM   0000701800Y
S28917808ABK27GA0000ZHB000100UWM   0000542800Y
S28917810XAK27GA00017U001000
S28917811X4K27GA0000DX000200
S28917811A4K27GA0000DXB000200DIA   0001298900Y
S28917813A4K27GA0000IXS000100DXD   0000500000Y
S28917814A3K27G60000AYB000100DDM   0000801300Y
S28917813X6K27GA000027000500
S28917813A6K27GA000027B000500IWM   0000736400Y
S28917823X6K27GA000027000500
S28917823A6K27GA000027B000500IWM   0000736800Y
S28917824XBK27GA0000ZH000100
S28917824XBK27GA0000ZG000100
S28917825A6K27GA0000BMB000100IWM   0000736300Y
S28917826ABK27GA0000ZIS000100TWM   0000702000Y
S28917825X6K27GA0000BM000100
S28917833X6K27GA000027000500
S28917833A6K27GA000027B000500IWM   0000736400Y
S28917835ABK27GA0000ZJS000100TWM   0000701800Y
S28917835ABK27GA0000ZKB000100UWM   0000542800Y
S28917835XBK27GA0000ZI000100
S28917838X6K27GA000027000500
S28917838A6K27GA000027B000500IWM   0000736800Y
S28917843X6K27GA000027000500
S28917843A6K27GA000027B000500IWM   0000736400Y
S28917854XBK27GA0000ZK000100
S28917855XBK27GA0000ZJ000100
S28917855X6K27GA000027000500
S28917855A6K27GA000027B000500IWM   0000736800Y
S28917855A6K27GA0000BNB000100IWM   0000736300Y
S28917855X6K27GA0000BN000100
S28917857ABK27GA0000ZLS000100TWM   0000702000Y
S28917863X6K27GA000027000500
S28917863A6K27GA000027B000500IWM   0000736400Y
S28917864ABK27GA0000ZMB000100UWM   0000542800Y
S28917865XBK27GA0000ZL000100
S28917865ABK27GA0000ZNS000100TWM   0000701800Y
S28917873X6K27GA000027000500
S28917873A6K27GA000027B000500IWM   0000736800Y
S28917875XBK27GA0000ZM000100
S28917875XBK27GA0000ZN000100
S28917877ABK27GA0000ZOS000100TWM   0000702000Y
S28917883X6K27GA000027000500
S28917883A6K27GA000027B000500IWM   0000736400Y
S28917885ABK27GA0000ZPB000100UWM   0000542800Y
S28917885XBK27GA0000ZO000100
S28917885ABK27GA0000ZQS000100TWM   0000701800Y
S28917887XAK27GA000180003000
S28917887XAK27GA000181003000
S28917887XAK27GA0000F2000500
S28917887AAK27GA0000F2B000500SPY   0001425800Y
S28917888AAK27GA000184B001000SPY   0001425600Y
S28917888XAK27GA000183001000
S28917889XAK27GA0000E4001000
S28917889AAK27GA0000E4B001000SPY   0001425800Y
S28917889AAK27GA000185S003000SPY   0001426600Y
S28917890ABK27GA0000ZRB001000SSO   0000764700Y
S28917890XBK27GA0000Z8001000
S28917891AAK27GA000186S003000SPY   0001426600Y
S28917891ABK27GA0000ZSB001000SSO   0000764500Y
S28917893X6K27GA000027000500
S28917893A6K27GA000027B000500IWM   0000736800Y
S28917894XBK27GA0000ZP000100
S28917894XBK27GA0000ZQ000100
S28917896ABK27GA0000ZTS000100TWM   0000702000Y
S28917901X6K27GA000027000500
S28917901A6K27GA000027B000500IWM   0000736400Y
S28917902X6K27GA000027000500
S28917902A6K27GA000027B000500IWM   0000736800Y
S28917910X6K27GA000027000500
S28917910A6K27GA000027B000500IWM   0000736400Y
S28917914X6K27GA000027000500
S28917914A6K27GA000027B000500IWM   0000736800Y
S28917919X6K27GA0000BK002000
S28917924ABK27GA0000ZUB000100UWM   0000542800Y
S28917925ABK27GA0000ZVS000100TWM   0000701800Y
S28917925XBK27GA0000ZT000100
S28917953AAK27GA000187B000500SPY   0001425600Y
S28918103X9K27G60000G3002000
S28918103A9K27G60000G3S002000QQQQ  0000496400Y
S28918177AAK27GA000188B002500SPY   0001425600Y
S28918341X3K27G60000AV002000
S28918346X6K27GA0000BA002000
S28918361A9K27G60000RPS001000QID   0000381800Y
S28918361X9K27G60000PG001000
S28918361A9K27G60000RQB001000QLD   0000889500Y
S28918362A9K27G60000RRS000100QID   0000382100Y
S28918362X9K27G60000RQ001000
S28918363A9K27G60000RSB001000QLD   0000889600Y
S28918365A9K27G60000RTB001000QQQQ  0000495500Y
S28918365A9K27G60000RUB001000QQQQ  0000495400Y
S28918374X9K27G60000RT001000
S28918374X9K27G60000RU001000
S28918409XAK27GA000173002000
S28918413X5K27GA00007C002000
S28918416X2K27G6000090002000
S28918432AAK27GA000189B002000SHLD  0000769300Y
S28918444X7K27GA00006R002000
S28918445XBK27GA0000YZ002000
S28918451XBK27GA0000YY002000
S28918458XCK27GA00004Z002000
S28918471XBK27GA0000Z0002000
S28918476X1K27GA0000AT002000
S28918481X1K27GA0000AS002000
S28918494X1K27GA0000AU002000
S28918496A5K27GA00007DS002000FNM   0001444600Y
S28918497A3K27G60000AZB002000CTSH  0000092800Y
S28918510X1K27GA000093002000
S28918542X2K27G6000093002000
S28918551X2K27G6000095002000
S28918558ACK27GA000050B002000WYE   0000134800Y
S28918567A7K27GA00006SB002000LMT   0000347300Y
S28918576A1K27GA0000AVB002000AFL   0000212000Y
S28918585ABK27GA0000ZWB002000UTX   0000228300Y
S28918596A1K27GA0000AWB002000ABT   0000172300Y
S28918605A1K27GA0000AXS002000AFL   0001586200Y
S28918635A2K27G600009FS002000BA    0001640500Y
S28918652A2K27G600009GS002000BA    0001641300Y
S28918655A2K27G600009HB002000BAX   0000587800Y
S28918660AAK27GA00018AS002500SPY   0001426100Y
S28918662A2K27G600009IS002000BBT   0001464400Y
S28918675A2K27G600009JS002000BAX   0000638000Y
S28918676A2K27G600009KS002000CAG   0001429600Y
S28918693A2K27G600009LB002000BBT   0000103900Y
S28918698A2K27G600009MS002000CAH   0000571300Y
S28918710A2K27G600009NS002000BBT   0001463600Y
S28918715A2K27G600009OB002000CAT   0000819000Y
S28919108XAK27GA000128002000
S28919349A3K27G60000B0B002000CELG  0000495300Y
S28919381X5K27GA00007D002000
S28919398X7K27GA00006S002000
S28919406XCK27GA000050002000
S28919416A6K27GA0000BOS002000IMCL  0000513100Y
S28919417XBK27GA0000ZW002000
S28919419X1K27GA0000AV002000
S28919432X1K27GA0000AX002000
S28919432X1K27GA0000AW002000
S28919433XAK27GA00012N001000
S28919437AAK27GA00018BB000800SPY   0001419800Y
S28919442X2K27G600009G002000
S28919464X2K27G600009I002000
S28919469X2K27G600008S002000
S28919470X2K27G600009F002000
S28919474X2K27G600009K002000
S28919473AAK27GA00018CB002000SPLS  0000065600Y
S28919480A5K27GA00007ES002000FNM   0001440700Y
S28919491X2K27G600009N002000
S28919521A2K27G600009PB002000BMY   0000064500Y
S28919541ABK27GA0000ZXS002000UTX   0001594800Y
S28919541A7K27GA00006TB002000LMT   0000351100Y
S28919554ACK27GA000051B002000WYE   0000135200Y
S28919560ABK27GA0000ZYB002000UTX   0000231100Y
S28919569A1K27GA0000AYB002000AFL   0000213000Y
S28919577A1K27GA0000AZS002000AFL   0001583400Y
S28919588A1K27GA0000B0B002000ARO   0000298700Y
S28919606ABK27GA0000ZZS002000UTX   0001594000Y
S28919624A1K27GA0000B1B002000ABT   0000174700Y
S28919629XAK27GA0000E4001000
S28919629AAK27GA0000E4B001000SPY   0001425400Y
S28919629XAK27GA000186003000
S28919629XAK27GA000185003000
S28919629XAK27GA0000F2000500
S28919629AAK27GA0000F2B000500SPY   0001425400Y
S28919630XAK27GA000184001000
S28919630AAK27GA00018DS002000SPY   0001426100Y
S28919630XAK27GA00017Q003000
S28919630XAK27GA00017R003000
S28919630AAK27GA00018ES003000SPY   0001426000Y
S28919630AAK27GA00018FS003000SPY   0001426000Y
S28919632AAK27GA00018GB001000SPY   0001425500Y
S28919632XBK27GA0000ZS001000
S28919633A2K27G600009QB002000BBT   0000104100Y
S28919632AAK27GA00018HB003000SPY   0001425000Y
S28919632AAK27GA00018IB003000SPY   0001425000Y
S28919633XAK27GA00017X005000
S28919633XAK27GA000188002500
S28919633AAK27GA00018JS005000SPY   0001426200Y
S28919633AAK27GA00018KS002500SPY   0001426000Y
S28919634XAK27GA00018A002500
S28919634XAK27GA000187000500
S28919634AAK27GA00018LS000500SPY   0001426000Y
S28919639XBK27GA0000ZR001000
S28919640A2K27G600009RB002000BBY   0000424000Y
S28919641ABK27GA000100B001000SSO   0000764600Y
S28919649A2K27G600009SB002000CAG   0000068300Y
S28919658A2K27G600009TS002000BBY   0000457500Y
S28919659X9K27G60000G3002000
S28919659A9K27G60000G3S002000QQQQ  0000496000Y
S28919662X6K27GA000027000500
S28919662A6K27GA000027B000500IWM   0000736400Y
S28919663A6K27GA0000BPS002000IWM   0000737200Y
S28919667X9K27G60000RS001000
S28919669A9K27G60000RVB001000QLD   0000889500Y
S28919669A9K27G60000RWB001000QQQQ  0000495500Y
S28919669A9K27G60000RXB001000QQQQ  0000495400Y
S28919674X9K27G60000RW001000
S28919674X9K27G60000RX001000
S28919673X6K27GA000027000500
S28919673A6K27GA000027B000500IWM   0000736800Y
S28919674XBK27GA0000ZU000100
S28919675XBK27GA0000ZV000100
S28919676ABK27GA000101B000100UWM   0000542800Y
S28919676ABK27GA000102S000100TWM   0000701800Y
S28919680A2K27G600009UB002000BDX   0000774500Y
S28919683X6K27GA000027000500
S28919683A6K27GA000027B000500IWM   0000736400Y
S28919690X6K27GA000027000500
S28919690A6K27GA000027B000500IWM   0000736800Y
S28919693X6K27GA000027000500
S28919693A6K27GA000027B000500IWM   0000736400Y
S28919695X6K27GA000027000500
S28919695A6K27GA000027B000500IWM   0000736800Y
S28919704X6K27GA000027000500
S28919704A6K27GA000027B000500IWM   0000736400Y
S28919706A2K27G600009VS002000BDX   0000899900Y
S28919713X6K27GA000027000500
S28919713A6K27GA000027B000500IWM   0000736800Y
S28919715XBK27GA000101000100
S28919715XBK27GA000102000100
S28919715X6K27GA000027000500
S28919715A6K27GA000027B000500IWM   0000736400Y
S28919717ABK27GA000103B000100UWM   0000542800Y
S28919717ABK27GA000104S000100TWM   0000701800Y
S28919718A2K27G600009WB002000BHI   0000843500Y
S28919723X6K27GA000027000500
S28919723A6K27GA000027B000500IWM   0000736800Y
S28919727A2K27G600009XS002000BHI   0000873900Y
S28919734X6K27GA000027000500
S28919734A6K27GA000027B000500IWM   0000736400Y
S28919753X6K27GA000027000500
S28919753A6K27GA000027B000500IWM   0000736800Y
S28919763X6K27GA000027000500
S28919763A6K27GA000027B000500IWM   0000736400Y
S28919773X6K27GA000027000500
S28919773A6K27GA000027B000500IWM   0000736800Y
S28919784XBK27GA000103000100
S28919784XBK27GA000104000100
S28919783X6K27GA000027000500
S28919783A6K27GA000027B000500IWM   0000736400Y
S28919786ABK27GA000105S000100TWM   0000702000Y
S28919794ABK27GA000106B000100UWM   0000542800Y
S28919794XBK27GA000105000100
S28919795ABK27GA000107S000100TWM   0000701800Y
S28919793X6K27GA000027000500
S28919793A6K27GA000027B000500IWM   0000736800Y
S28919804XBK27GA000106000100
S28919804XBK27GA000107000100
S28919803X6K27GA000027000500
S28919803A6K27GA000027B000500IWM   0000736400Y
S28919806ABK27GA000108S000100TWM   0000702000Y
S28919814ABK27GA000109B000100UWM   0000542800Y
S28919815ABK27GA00010AS000100TWM   0000701800Y
S28919815XBK27GA000108000100
S28919824XBK27GA000109000100
S28919824XBK27GA00010A000100
S28919826ABK27GA00010BS000100TWM   0000702000Y
S28919858AAK27GA00018MB000500SPY   0001425400Y
S28920153X6K27GA000027000500
S28920154A6K27GA0000BQB000500IWM   0000736300Y
S28920163X6K27GA0000BQ000500
S28920163A6K27GA0000BQB000500IWM   0000736400Y
S28920173X6K27GA0000BQ000500
S28920173A6K27GA0000BQB000500IWM   0000736800Y
S28920176ABK27GA00010CB000100UWM   0000542800Y
S28920176XBK27GA00010B000100
S28920176ABK27GA00010DS000100TWM   0000701800Y
S28920183X6K27GA0000BQ000500
S28920183A6K27GA0000BQB000500IWM   0000736400Y
S28920186XBK27GA00010C000100
S28920186XBK27GA00010D000100
S28920186A6K27GA0000BRB000100IWM   0000736300Y
S28920188ABK27GA00010ES000100TWM   0000702000Y
S28920186X6K27GA0000BR000100
S28920187X6K27GA0000BQ000500
S28920187A6K27GA0000BQB000500IWM   0000736800Y
S28920190ABK27GA00010FB000100UWM   0000542800Y
S28920189X6K27GA0000BQ000500
S28920189A6K27GA0000BQB000500IWM   0000736400Y
S28920191ABK27GA00010GS000100TWM   0000701800Y
S28920191XBK27GA00010E000100
S28920193XBK27GA00010G000100
S28920193XBK27GA00010F000100
S28920194ABK27GA00010HS000100TWM   0000702000Y
S28920193A6K27GA0000BSB000100IWM   0000736300Y
S28920193X6K27GA0000BS000100
S28920193X6K27GA0000BQ000500
S28920193A6K27GA0000BQB000500IWM   0000736800Y
S28920197ABK27GA00010IB000100UWM   0000542800Y
S28920197XBK27GA00010H000100
S28920197ABK27GA00010JS000100TWM   0000701800Y
S28920196X6K27GA0000BQ000500
S28920196A6K27GA0000BQB000500IWM   0000736400Y
S28920199XBK27GA00010I000100
S28920199XBK27GA00010J000100
S28920199A6K27GA0000BTB000100IWM   0000736300Y
S28920201ABK27GA00010KS000100TWM   0000702000Y
S28920199X6K27GA0000BT000100
S28920203X6K27GA0000BQ000500
S28920203A6K27GA0000BQB000500IWM   0000736800Y
S28920207ABK27GA00010LB000100UWM   0000542800Y
S28920207ABK27GA00010MS000100TWM   0000701800Y
S28920207XBK27GA00010K000100
S28920213X6K27GA0000BQ000500
S28920213A6K27GA0000BQB000500IWM   0000736400Y
S28920217XBK27GA00010L000100
S28920217XBK27GA00010M000100
S28920219ABK27GA00010NS000100TWM   0000702000Y
S28920223X6K27GA0000BQ000500
S28920223A6K27GA0000BQB000500IWM   0000736800Y
S28920227ABK27GA00010OB000100UWM   0000542800Y
S28920227ABK27GA00010PS000100TWM   0000701800Y
S28920227XBK27GA00010N000100
S28920234X6K27GA0000BQ000500
S28920234A6K27GA0000BQB000500IWM   0000736400Y
S28920237XBK27GA00010P000100
S28920237XBK27GA00010O000100
S28920239ABK27GA00010QS000100TWM   0000702000Y
S28920243X6K27GA0000BQ000500
S28920243A6K27GA0000BQB000500IWM   0000736800Y
S28920247ABK27GA00010RB000100UWM   0000542800Y
S28920247XBK27GA00010Q000100
S28920247ABK27GA00010SS000100TWM   0000701800Y
S28920255X6K27GA0000BQ000500
S28920255A6K27GA0000BQB000500IWM   0000736400Y
S28920259XBK27GA00010R000100
S28920259XBK27GA00010S000100
S28920261ABK27GA00010TS000100TWM   0000702000Y
S28920263X6K27GA0000BQ000500
S28920263A6K27GA0000BQB000500IWM   0000736800Y
S28920267ABK27GA00010UB000100UWM   0000542800Y
S28920267ABK27GA00010VS000100TWM   0000701800Y
S28920267XBK27GA00010T000100
S28920273X6K27GA0000BQ000500
S28920273A6K27GA0000BQB000500IWM   0000736400Y
S28920276XBK27GA00010U000100
S28920276XBK27GA00010V000100
S28920278ABK27GA00010WS000100TWM   0000702000Y
S28920277X6K27GA0000BQ000500
S28920277A6K27GA0000BQB000500IWM   0000736800Y
S28920279X6K27GA0000BQ000500
S28920279A6K27GA0000BQB000500IWM   0000736400Y
S28920283X6K27GA0000BQ000500
S28920283A6K27GA0000BQB000500IWM   0000736800Y
S28920293X6K27GA0000BQ000500
S28920293A6K27GA0000BQB000500IWM   0000736400Y
S28920303X6K27GA0000BQ000500
S28920303A6K27GA0000BQB000500IWM   0000736800Y
S28920305X6K27GA0000BQ000500
S28920305A6K27GA0000BQB000500IWM   0000736400Y
S28920313X6K27GA0000BQ000500
S28920313A6K27GA0000BQB000500IWM   0000736800Y
S28920323X6K27GA0000BQ000500
S28920323A6K27GA0000BQB000500IWM   0000736400Y
S28920343X6K27GA0000B8002000
S28920347X7K27GA00005O002000
S28920384X5K27GA00007E002000
S28920387XBK27GA0000ZX002000
S28920393XCK27GA000051002000
S28920398XCK27GA00004D002000
S28920403X1K27GA0000AY002000
S28920407X1K27GA0000AZ002000
S28920429A7K27GA00006UB002000LMT   0000353300Y
S28920436ABK27GA00010XB002000UTX   0000232300Y
S28920441A1K27GA0000B2B002000ABT   0000175400Y
S28920455A2K27G600009YS002000BA    0001635100Y
S28920466A2K27G600009ZS002000BBT   0001455200Y
S28920473A2K27G60000A0B002000BDX   0000773900Y
S28920483A2K27G60000A1S002000CAG   0001419900Y
S28920490A2K27G60000A2S002000CAT   0000868300Y
S28920507X7K27GA00006T002000
S28920511A3K27G60000B1B002000CCE   0000192600Y
S28920526XBK27GA0000ZY002000
S28920537XBK27GA0000ZZ002000
S28920549X1K27GA0000B1002000
S28920551A3K27G60000B2S002000CCE   0000241000Y
S28920559A5K27GA00007FS002000FNM   0001435100Y
S28920572A3K27G60000B3B002000CCL   0000380300Y
S28920581X2K27G600009L002000
S28920594ACK27GA000052B002000WYE   0000137300Y
S28920616A1K27GA0000B3B002000AFL   0000215700Y
S28920629A1K27GA0000B4S002000AFL   0001579000Y
S28920639A2K27G60000A3S002000BA    0001634300Y
S28920648A2K27G60000A4S002000BBT   0001454400Y
S28920657X6K27GA0000BQ000500
S28920657A6K27GA0000BQB000500IWM   0000736800Y
S28920658X6K27GA0000BP002000
S28920660ABK27GA00010YB000100UWM   0000542800Y
S28920660XBK27GA00010W000100
S28920660ABK27GA00010ZS000100TWM   0000701800Y
S28920664A2K27G60000A5B002000BJS   0000301100Y
S28920663X6K27GA0000BQ000500
S28920663A6K27GA0000BQB000500IWM   0000736400Y
S28920673A2K27G60000A6S002000BJS   0000327300Y
S28920673X6K27GA0000BQ000500
S28920673A6K27GA0000BQB000500IWM   0000736800Y
S28920674XBK27GA00010Y000100
S28920674XBK27GA00010Z000100
S28920676ABK27GA000110B000100UWM   0000542800Y
S28920675A6K27GA0000BUB000100IWM   0000736300Y
S28920675X6K27GA0000BU000100
S28920676ABK27GA000111S000100TWM   0000701800Y
S28920676X6K27GA0000BQ000500
S28920676A6K27GA0000BQB000500IWM   0000736400Y
S28920682A2K27G60000A7B002000BK    0000429300Y
S28920683X6K27GA0000BQ000500
S28920683A6K27GA0000BQB000500IWM   0000736800Y
S28920685XBK27GA000110000100
S28920685XBK27GA000111000100
S28920687ABK27GA000112B000100UWM   0000542800Y
S28920685A6K27GA0000BVB000100IWM   0000736300Y
S28920687ABK27GA000113S000100TWM   0000701800Y
S28920686X6K27GA0000BV000100
S28920692A2K27G60000A8S002000BK    0000476300Y
S28920693X6K27GA0000BQ000500
S28920693A6K27GA0000BQB000500IWM   0000736400Y
S28920697A6K27GA0000BWS002000IWM   0000737200Y
S28920704XBK27GA000112000100
S28920704XBK27GA000113000100
S28920705A6K27GA0000BXB000100IWM   0000736300Y
S28920706ABK27GA000114S000100TWM   0000702000Y
S28920705X6K27GA0000BX000100
S28921172XAK27GA00018D002000
S28921172AAK27GA00018NB002000SPY   0001425600Y
S28921172XAK27GA000182001000
S28921172XAK27GA00018F003000
S28921172XAK27GA00018H003000
S28921173XAK27GA0000F2000500
S28921173AAK27GA0000F2B000500SPY   0001425800Y
S28921173XAK27GA00018I003000
S28921173AAK27GA00018OB003000SPY   0001425600Y
S28921173XAK27GA0000E4001000
S28921173AAK27GA0000E4B001000SPY   0001425800Y
S28921173XAK27GA00018E003000
S28921173AAK27GA00018PB003000SPY   0001425600Y
S28921174AAK27GA00018QS002000SPY   0001426200Y
S28921174ABK27GA000115B001000SSO   0000764700Y
S28921174XBK27GA000100001000
S28921176AAK27GA00018RS003000SPY   0001426600Y
S28921176AAK27GA00018SS003000SPY   0001426600Y
S28921176AAK27GA00018TS005000SPY   0001426100Y
S28921176XAK27GA00018J005000
S28921177ABK27GA000116B001000SSO   0000764500Y
S28921177XAK27GA00018K002500
S28921177XAK27GA00018L000500
S28921177AAK27GA00018UB002500SPY   0001425600Y
S28921178AAK27GA00018VB000500SPY   0001425600Y
S28921178XAK27GA00018M000500
S28921181X6K27GA0000BQ000500
S28921181A6K27GA0000BQB000500IWM   0000736800Y
S28921181X6K27GA0000BW002000
S28921183X6K27GA0000BQ000500
S28921183A6K27GA0000BQB000500IWM   0000736400Y
S28921184X9K27G60000G3002000
S28921184A9K27G60000G3S002000QQQQ  0000496400Y
S28921184ABK27GA000117B000100UWM   0000542800Y
S28921184XBK27GA000114000100
S28921184ABK27GA000118S000100TWM   0000701800Y
S28921186XBK27GA000118000100
S28921186XBK27GA000117000100
S28921188ABK27GA000119S000100TWM   0000702000Y
S28921187X6K27GA0000BQ000500
S28921187A6K27GA0000BQB000500IWM   0000736800Y
S28921190ABK27GA00011AB000100UWM   0000542800Y
S28921190XBK27GA000119000100
S28921190ABK27GA00011BS000100TWM   0000701800Y
S28921189X6K27GA0000BQ000500
S28921189A6K27GA0000BQB000500IWM   0000736400Y
S28921192X9K27G60000RV001000
S28921192A9K27G60000RYB001000QLD   0000889600Y
S28921192XBK27GA00011A000100
S28921192XBK27GA00011B000100
S28921194ABK27GA00011CB000100UWM   0000542800Y
S28921195ABK27GA00011DS000100TWM   0000701800Y
S28921193X6K27GA0000BQ000500
S28921193A6K27GA0000BQB000500IWM   0000736800Y
S28921195A9K27G60000RZB001000QQQQ  0000495500Y
S28921195A9K27G60000S0B001000QQQQ  0000495400Y
S28921198X6K27GA0000BQ000500
S28921198A6K27GA0000BQB000500IWM   0000736400Y
S28921199XAK27GA00018Q001000
S28921202XAK27GA0000E4001000
S28921202AAK27GA0000E4B001000SPY   0001425400Y
S28921202XAK27GA0000F2000500
S28921202AAK27GA0000F2B000500SPY   0001425400Y
S28921202X4K27GA0000DX000200
S28921202A4K27GA0000DXB000200DIA   0001298600Y
S28921203XAK27GA00018N002000
S28921204X9K27G60000S0001000
S28921204X9K27G60000RZ001000
S28921204XAK27GA00018R003000
S28921204XAK27GA00018S003000
S28921204XAK27GA00018U002500
S28921204AAK27GA00018WS003000SPY   0001426000Y
S28921205XBK27GA000116001000
S28921205X3K27G60000AY000100
S28921204AAK27GA00018XS003000SPY   0001426000Y
S28921204X4K27GA0000IX000100
S28921203X6K27GA0000BQ000500
S28921203A6K27GA0000BQB000500IWM   0000736800Y
S28921206XAK27GA00018V000500
S28921209XBK27GA000115001000
S28921211ABK27GA00011EB001000SSO   0000764600Y
S28921213X6K27GA0000BQ000500
S28921213A6K27GA0000BQB000500IWM   0000736400Y
S28921217XAK27GA00018Q001000
S28921216X6K27GA0000BQ000500
S28921216A6K27GA0000BQB000500IWM   0000736800Y
S28921218XBK27GA00011C000100
S28921219XBK27GA00011D000100
S28921220ABK27GA00011FB000100UWM   0000542800Y
S28921220ABK27GA00011GS000100TWM   0000701800Y
S28921220X6K27GA0000BQ000500
S28921220A6K27GA0000BQB000500IWM   0000736400Y
S28921223X6K27GA0000BQ000500
S28921223A6K27GA0000BQB000500IWM   0000736800Y
S28921232XAK27GA00018G001000
S28921232AAK27GA00018YB001000SPY   0001425400Y
S28921234X6K27GA0000BQ000500
S28921234A6K27GA0000BQB000500IWM   0000736400Y
S28921236AAK27GA00018ZB001000SPY   0001425400Y
S28921242X6K27GA0000BQ000500
S28921242A6K27GA0000BQB000500IWM   0000736800Y
S28921243XBK27GA00011F000100
S28921243XBK27GA00011G000100
S28921245ABK27GA00011HB000100UWM   0000542800Y
S28921245ABK27GA00011IS000100TWM   0000701800Y
S28921245X6K27GA00009Q002000
S28921245A6K27GA0000BYS002000IWM   0000737800Y
S28921246X6K27GA0000BQ000500
S28921246A6K27GA0000BQB000500IWM   0000736400Y
S28921249X9K27G60000RY001000
S28921251A9K27G60000S1B001000QLD   0000889500Y
S28921251A9K27G60000S2B001000QQQQ  0000495400Y
S28921251A9K27G60000S3B001000QQQQ  0000495500Y
S28921251X6K27GA0000BQ000500
S28921251A6K27GA0000BQB000500IWM   0000736800Y
S28921253X9K27G60000G3002000
S28921253A9K27G60000G3S002000QQQQ  0000496000Y
S28921254X9K27G60000S3001000
S28921254X9K27G60000S2001000
S28921253X6K27GA0000BQ000500
S28921253A6K27GA0000BQB000500IWM   0000736400Y
S28921254XAK27GA00018Z001000
S28921261X6K27GA0000BQ000500
S28921261A6K27GA0000BQB000500IWM   0000736800Y
S28921263AAK27GA000190B001000SPY   0001425400Y
S28921263X6K27GA0000BQ000500
S28921263A6K27GA0000BQB000500IWM   0000736400Y
S28921264XBK27GA00011H000100
S28921264XBK27GA00011I000100
S28921266ABK27GA00011JS000100TWM   0000702000Y
S28921265X6K27GA0000BQ000500
S28921265A6K27GA0000BQB000500IWM   0000736800Y
S28921273X6K27GA0000BQ000500
S28921273A6K27GA0000BQB000500IWM   0000736400Y
S28921283X6K27GA0000BQ000500
S28921283A6K27GA0000BQB000500IWM   0000736800Y
S28921284ABK27GA00011KB000100UWM   0000542800Y
S28921284ABK27GA00011LS000100TWM   0000701800Y
S28921284XBK27GA00011J000100
S28921293X6K27GA0000BQ000500
S28921293A6K27GA0000BQB000500IWM   0000736400Y
S28921294XBK27GA00011K000100
S28921294XBK27GA00011L000100
S28921296ABK27GA00011MS000100TWM   0000702000Y
S28921314ABK27GA00011NB000100UWM   0000542800Y
S28921314XBK27GA00011M000100
S28921314ABK27GA00011OS000100TWM   0000701800Y
